Workbook

Sheet Datos pesos
B1: 1 | C1: 2 | D1: 3 | E1: 4 | F1: 5 | G1: 6 | H1: 7 | I1: 8 | J1: 9 | K1: 10 | L1: 11 | M1: 12 | N1: 13 | O1: 14 | P1: 15 | Q1: 16
B2: 45292 | C2: 45323 | D2: 45382 | E2: 45383 | F2: 45443 | G2: 45444 | H2: 45504 | I2: 45505 | J2: 45565 | K2: 45566 | L2: 45597 | M2: 45992 | N2: 45688 | O2: 45689 | P2: 45747 | Q2: 45748
A4: AGC | B4: 53881034 | C4: 20963937 | D4: 44692243 | E4: 38082942 | F4: 61682741 | G4: 36939440 | H4: 42664677 | I4: 28340416 | J4: 38131286 | K4: 32030555 | L4: 17470562 | M4: 55781137 | N4: 22956087 | O4: 25600892 | P4: 53528822 | Q4: 25216930
A5: Sailing | B5: 20403150 | C5: 19557884 | D5: 20027511 | E5: 36083086 | F5: 41916511 | G5: 26930564 | H5: 21563684 | I5: 26415950 | J5: 41050992 | K5: 35406312 | L5: 73513466 | M5: 67499258 | N5: 108650789 | O5: 72287909 | P5: 68071789 | Q5: 110837988
A6: Revenues | B6: 74284183 | C6: 40521821 | D6: 64719754 | E6: 74166027 | F6: 1.0359925e+08 | G6: 63870004 | H6: 64228361 | I6: 54756366 | J6: 79182278 | K6: 67436867 | L6: 90984028 | M6: 1.2328039e+08 | N6: 1.3160688e+08 | O6: 97888801 | P6: 1.2160061e+08 | Q6: 1.3605492e+08
A7: COGS AGC | B7: - | C7: - | E7: - | F7: - | G7: - | H7: - | I7: - | J7: - | K7: - | L7: - | M7: - | N7: - | O7: - | P7: - | Q7: -
A8: COGS Sailing | B8: -4562769 | C8: -3568071 | D8: -2978255 | E8: -4766775 | F8: -5659831 | G8: -1887826 | H8: -4126436 | I8: -4153176 | J8: -7890378 | K8: -3880908 | L8: -6631218 | M8: -5765951 | N8: -3318515 | O8: -3293817 | P8: -4774721 | Q8: 0
A9: COGS total | B9: -4562768.9 | C9: -3568070.9 | D9: -2978254.7 | E9: -4766774.8 | F9: -5659831.4 | G9: -1887825.7 | H9: -4126435.6 | I9: -4153176 | J9: -7890377.7 | K9: -3880908.5 | L9: -6631218 | M9: -5765951 | N9: -3318515.3 | O9: -3293817.1 | P9: -4774721.1 | Q9: -4418874.8
A10: Gross income | B10: 69721414 | C10: 36953750 | D10: 61741500 | E10: 69399253 | F10: 97939420 | G10: 61982178 | H10: 60101926 | I10: 50603190 | J10: 71291900 | K10: 63555959 | L10: 84352810 | M10: 1.1751444e+08 | N10: 1.2828836e+08 | O10: 94594984 | P10: 1.1682589e+08 | Q10: 1.3163604e+08
A11: Operating costs AGC | B11: 0 | C11: 0 | D11: 0 | E11: 0 | F11: 0 | G11: 0 | H11: 0 | I11: 0 | J11: 0 | K11: 0 | L11: 0 | M11: 0 | N11: 0 | O11: -6418000 | P11: -10460000 | Q11: -8781074
A12: Operating costs Sailing | B12: =B13 -> -23528050 | C12: =C13 -> -28351341 | D12: =D13 -> -39642168 | E12: =E13 -> -40094929 | F12: =F13 -> -45718436 | G12: =G13 -> -50658841 | H12: =H13 -> -47721368 | I12: =I13 -> -44982080 | ... N12: =N13 -> -1.1836569e+08 | O12: -100091106 | P12: -117012562 | Q12: -99911035
A13: Operatings costs less D&A | B13: -23528050 | C13: -28351341 | D13: -39642168 | E13: -40094929 | F13: -45718436 | G13: -50658841 | H13: -47721368 | I13: -44982080 | J13: -70781240 | K13: -1.1402285e+08 | L13: -1.0759983e+08 | M13: -1.2367715e+08 | N13: -1.1836569e+08 | O13: -1.0650911e+08 | P13: -1.2747256e+08 | Q13: -1.0869211e+08
A14: EBITDA | B14: 46193365 | C14: 8602408.2 | D14: 22099332 | E14: 29304323 | F14: 52220984 | G14: 11323338 | H14: 12380558 | I14: 5621110.3 | J14: 510659.37 | K14: -50466894 | L14: -23247024 | M14: -6162702.4 | N14: 9922671.4 | O14: -11914121 | P14: -10646671 | Q14: 22943935
A15: D&A | B15: -22322.92 | C15: -22322.92 | D15: -29249.587 | E15: -29249.587 | F15: -29249.587 | G15: -29249.587 | H15: -29249.587 | I15: -29249.587 | J15: -44249.587 | K15: -52582.92 | L15: -64249.587 | M15: -68999.587 | N15: -76916.253 | O15: -76916.253 | P15: -91082.92 | Q15: -91082.92
A16: Operating Income | B16: =B15+B14 -> 46171042 | C16: =C15+C14 -> 8580085.3 | D16: =D15+D14 -> 22070082 | E16: =E15+E14 -> 29275074 | F16: =F15+F14 -> 52191734 | G16: =G15+G14 -> 11294088 | H16: =H15+H14 -> 12351308 | I16: =I15+I14 -> 5591860.7 | ... Q16: =Q15+Q14 -> 22852852
A17: Financial results from AGC | B17: 5823772 | C17: -2843350 | D17: -310395 | E17: 1251089 | F17: 5400421 | G17: 1040798 | H17: -952237 | I17: -2524808 | J17: -352967 | K17: 1705635 | L17: 4960986 | M17: -20050020 | N17: -140965 | O17: -2514069 | P17: -18263159 | Q17: 24585568
A18: Financial results from Sailing | B18: 162098229 | C18: -64754666 | D18: 96870395 | E18: 82198492 | F18: 111022562 | G18: -32124514 | H18: -60598360 | I18: 112233928 | J18: -7962475 | K18: 27705321 | L18: 18777995 | M18: 142323223 | N18: 192192921 | O18: -249804761 | P18: -1849641 | Q18: -86076522
A19: Financial results total | B19: 1.67922e+08 | C19: -67598017 | D19: 96560001 | E19: 83449580 | F19: 1.1642298e+08 | G19: -31083715 | H19: -61550597 | I19: 1.0970912e+08 | J19: -8315442.6 | K19: 29410956 | L19: 23738981 | M19: 1.222732e+08 | N19: 1.9205196e+08 | O19: -2.5231883e+08 | P19: -20112800 | Q19: -61490955
A20: Pretax Income | B20: 2.1409304e+08 | C20: -59017931 | D20: 1.1863008e+08 | E20: 1.1272465e+08 | F20: 1.6861472e+08 | G20: -19789627 | H20: -49199289 | I20: 1.1530098e+08 | J20: -7849032.8 | K20: -21108521 | L20: 427707.42 | M20: 1.160415e+08 | N20: 2.0189771e+08 | O20: -2.6430987e+08 | P20: -30850554 | Q20: -38638103
A21: Income tax | B21: 0 | C21: 0 | D21: 0 | E21: 0 | F21: 0 | G21: 0 | H21: 0 | I21: 0 | J21: 0 | K21: 0 | L21: 0 | M21: 0 | N21: -4120995.4 | O21: 3708100.4 | P21: -377761.69 | Q21: 790656.75
A22: Net income | B22: 2.1409304e+08 | C22: -59017931 | D22: 1.1863008e+08 | E22: 1.1272465e+08 | F22: 1.6861472e+08 | G22: -19789627 | H22: -49199289 | I22: 1.1530098e+08 | J22: -7849032.8 | K22: -21108521 | L22: 427707.42 | M22: 1.160415e+08 | N22: 1.9777672e+08 | O22: -2.6060177e+08 | P22: -31228315 | Q22: -37847446
A25: Current Assets
A26: Cash | B26: 696746348 | C26: 679286384 | D26: 492899799 | E26: 680215868 | F26: 510151456 | G26: 584124853 | H26: 548840262 | I26: 499609742 | J26: 1110225795 | K26: 426829134 | L26: 495888756 | M26: 436326755 | N26: 357160028 | O26: 887567908 | P26: 627517013 | Q26: 447741539
A27: Short-Term Investments | B27: 879440834 | C27: 847774337 | D27: 965091034 | E27: 1003126928 | F27: 1316620219 | G27: 680241904 | H27: 1330779610 | I27: 1432687607 | J27: 989241208 | K27: 1404842137 | L27: 1404842137 | M27: 1936406570 | N27: 950975301 | O27: 2735737638 | P27: 2560467595 | Q27: 2026376944
A28: Operational credtis | B28: 175557820 | C28: 166978963 | D28: 163597789 | E28: 466246129 | F28: -254990642 | G28: 390098075 | H28: -161307282 | I28: -43799416 | J28: 8778256 | K28: -404918060 | L28: -404918060 | M28: -571631552 | N28: 729696147 | O28: -1235255802 | P28: -1157278992 | Q28: -926059025
A29: Other credits | B29: 16417357 | C29: 14121768 | D29: 13831814 | E29: 11823211 | F29: 10116473 | G29: 24562266 | H29: 28485968 | I29: 33444537 | J29: 45562936 | K29: 50627124 | L29: 50627124 | M29: 51941466 | N29: 59558262 | O29: 77986568 | P29: 95350193 | Q29: 97012532
A30: Total Current Assets | B30: 1768162360 | C30: 1708161452 | D30: 1635420437 | E30: 2161412136 | F30: 1581897506 | G30: 1679027098 | H30: 1746798559 | I30: 1921942470 | J30: 2153808194 | K30: 1477380336 | L30: 1546439958 | M30: 1853043238 | N30: 2097389737 | O30: 2466036312 | P30: 2126055808 | Q30: 1645071990
A31: Goodwill/Intangibles
A32: Bienes de uso | B32: 0 | C32: 0 | D32: 0 | E32: 0 | F32: 0 | G32: 0 | H32: 0 | I32: 0 | J32: 0 | K32: 0 | L32: 0 | M32: 0 | N32: 0 | O32: 0 | P32: - | Q32: 60714375
A33: Total del activo no corriente | B33: 9507645 | C33: 25874825 | D33: 26676775 | E33: 26647526 | F33: 26618276 | G33: 26589026 | H33: 26559777 | I33: 26530527 | J33: 28286278 | K33: 29233695 | L33: 29233695 | M33: 30569445 | N33: 31070446 | O33: 31943529 | P33: 59196541 | Q33: -
A34: TOTAL DE ACTIVO | B34: 1777670005 | C34: 1734036277 | D34: 1662097213 | E34: 2188059662 | F34: 1608515782 | G34: 1705616125 | H34: 1773358336 | I34: 1948472998 | J34: 2182094472 | K34: 1506614030 | L34: 1575673653 | M34: 1883612683 | N34: 2128460183 | O34: 2497979842 | P34: 2185252349 | Q34: 1705786365
A37: Liabilities
A38: Operational debt | B38: -1088814594 | C38: -1135570722 | D38: -957627051 | E38: -1386491729 | F38: -714556547 | G38: -873548532 | H38: -1008742249 | I38: -1080318100 | J38: -1322898253 | K38: -637809841 | L38: -735980515 | M38: -1016714794 | N38: -1171757218 | O38: -1333846112 | P38: -1246617770 | Q38: -810081059
A39: Commercial debt | B39: -5811224 | C39: -5136582 | D39: -4660346 | E39: -5299930 | F39: -6765780 | G39: -6227080 | H39: -6435841 | I39: -6530439 | J39: -8169281 | K39: -6363497 | L39: -8040174 | M39: -30197982 | N39: -13207957 | O39: -14542102 | P39: -10152107 | Q39: -14951839
A40: Fiscal debt | B40: -2556121 | C40: -3944682 | D40: -6131420 | E40: -7971689 | F40: -10144684 | G40: -5041079 | H40: -6310715 | I40: -7490147 | J40: -10136936 | K40: -8830697 | L40: -12765009 | M40: -15169508 | N40: -6261185 | O40: -10374999 | P40: -15672781 | Q40: -36378720
A41: Social debt | B41: -2893922 | C41: -78181551 | D41: -78176726 | E41: -79069988 | F41: -19207729 | G41: -18448019 | H41: -18142406 | I41: -18406205 | J41: -19110930 | K41: -19141823 | L41: -19141823 | M41: -21352640 | N41: -21014562 | O41: -25233797 | P41: -51402741 | Q41: -52043560
A42: Total current liabilities | B42: -1100075862 | C42: -1222833538 | D42: -1046595542 | E42: -1478833337 | F42: -750674740 | G42: -903264710 | H42: -1039631210 | I42: -1112744891 | J42: -1360315399 | K42: -672145859 | L42: -775927521 | M42: -1083434924 | N42: -1212240923 | O42: -1383997010 | P42: -1323845399 | Q42: -913455177
A43: WC | B43: 668086498 | C43: 485327915 | D43: 588824895 | E43: 682578799 | F43: 831222766 | G43: 775762388 | H43: 707167348 | I43: 809197579 | J43: 793492795 | K43: 805234477 | L43: 770512436 | M43: 769608314 | N43: 885148815 | O43: 1082039302 | P43: 802210409 | Q43: 731616814
A44: PATRIMONIO NETO
A45: Equity | B45: -677594145 | C45: -511202741 | D45: -615501672 | E45: -709226327 | F45: -857841043 | G45: -802351416 | H45: -733727127 | I45: -835728107 | J45: -821779074 | K45: -834468173 | L45: -799746133 | M45: -800177761 | N45: -916219262 | O45: -1113982832 | P45: -861406950 | Q45: -792331191
...

Sheet Datos USD
B1: 1 | C1: 2 | D1: 3 | E1: 4 | F1: 5 | G1: 6 | H1: 7 | I1: 8 | J1: 9 | K1: 10 | L1: 11 | M1: 12 | N1: 13 | O1: 14 | P1: 15 | Q1: 16
B2: 45292 | C2: 45323 | D2: 45382 | E2: 45383 | F2: 45443 | G2: 45444 | H2: 45504 | I2: 45505 | J2: 45565 | K2: 45566 | L2: 45597 | M2: 45992 | N2: 45688 | O2: 45689 | P2: 45747 | Q2: 45748
B3: 1176 | C3: 1109 | D3: 1000 | E3: 1014.09 | F3: 1117.41 | G3: 1284.41 | H3: 1347.4 | I3: 1295.36 | J3: 1228.64 | K3: 1161.01 | L3: 1106.51 | M3: 1105.82 | N3: 1164.47 | O3: 1198.36 | P3: 1264.71 | Q3: 1250.1
A4: AGC | B4: ='Datos pesos'!B4/'Datos USD'!B$3 -> 45817.205 | C4: ='Datos pesos'!C4/'Datos USD'!C$3 -> 18903.459 | D4: ='Datos pesos'!D4/'Datos USD'!D$3 -> 44692.243 | E4: ='Datos pesos'!E4/'Datos USD'!E$3 -> 37553.808 | F4: ='Datos pesos'!F4/'Datos USD'!F$3 -> 55201.529 | G4: ='Datos pesos'!G4/'Datos USD'!G$3 -> 28759.851 | H4: ='Datos pesos'!H4/'Datos USD'!H$3 -> 31664.448 | I4: ='Datos pesos'!I4/'Datos USD'!I$3 -> 21878.409 | ... Q4: ='Datos pesos'!Q4/'Datos USD'!Q$3 -> 20171.93
A5: Sailing | B5: ='Datos pesos'!B5/'Datos USD'!B$3 -> 17349.617 | C5: ='Datos pesos'!C5/'Datos USD'!C$3 -> 17635.603 | D5: ='Datos pesos'!D5/'Datos USD'!D$3 -> 20027.511 | E5: ='Datos pesos'!E5/'Datos USD'!E$3 -> 35581.739 | F5: ='Datos pesos'!F5/'Datos USD'!F$3 -> 37512.203 | G5: ='Datos pesos'!G5/'Datos USD'!G$3 -> 20967.264 | H5: ='Datos pesos'!H5/'Datos USD'!H$3 -> 16003.922 | I5: ='Datos pesos'!I5/'Datos USD'!I$3 -> 20392.748 | ... Q5: ='Datos pesos'!Q5/'Datos USD'!Q$3 -> 88663.297
A6: Revenues | B6: ='Datos pesos'!B6/'Datos USD'!B$3 -> 63166.822 | C6: ='Datos pesos'!C6/'Datos USD'!C$3 -> 36539.063 | D6: ='Datos pesos'!D6/'Datos USD'!D$3 -> 64719.754 | E6: ='Datos pesos'!E6/'Datos USD'!E$3 -> 73135.547 | F6: ='Datos pesos'!F6/'Datos USD'!F$3 -> 92713.732 | G6: ='Datos pesos'!G6/'Datos USD'!G$3 -> 49727.115 | H6: ='Datos pesos'!H6/'Datos USD'!H$3 -> 47668.37 | I6: ='Datos pesos'!I6/'Datos USD'!I$3 -> 42271.157 | ... Q6: ='Datos pesos'!Q6/'Datos USD'!Q$3 -> 108835.23
A7: COGS AGC | B7: 0 | C7: 0 | D7: 0 | E7: 0 | F7: 0 | G7: 0 | H7: 0 | I7: 0 | J7: 0 | K7: 0 | L7: 0 | M7: 0 | N7: 0 | O7: 0 | P7: 0 | Q7: 0
A8: COGS Sailing | B8: ='Datos pesos'!B8/'Datos USD'!B$3 -> -3879.9056 | C8: ='Datos pesos'!C8/'Datos USD'!C$3 -> -3217.3769 | D8: ='Datos pesos'!D8/'Datos USD'!D$3 -> -2978.255 | E8: ='Datos pesos'!E8/'Datos USD'!E$3 -> -4700.5443 | F8: ='Datos pesos'!F8/'Datos USD'!F$3 -> -5065.1337 | G8: ='Datos pesos'!G8/'Datos USD'!G$3 -> -1469.8001 | H8: ='Datos pesos'!H8/'Datos USD'!H$3 -> -3062.5174 | I8: ='Datos pesos'!I8/'Datos USD'!I$3 -> -3206.1944 | ... Q8: ='Datos pesos'!Q8/'Datos USD'!Q$3 -> 0
A9: COGS total | B9: ='Datos pesos'!B9/'Datos USD'!B$3 -> -3879.9055 | C9: ='Datos pesos'!C9/'Datos USD'!C$3 -> -3217.3768 | D9: ='Datos pesos'!D9/'Datos USD'!D$3 -> -2978.2547 | E9: ='Datos pesos'!E9/'Datos USD'!E$3 -> -4700.5441 | F9: ='Datos pesos'!F9/'Datos USD'!F$3 -> -5065.1341 | G9: ='Datos pesos'!G9/'Datos USD'!G$3 -> -1469.7999 | H9: ='Datos pesos'!H9/'Datos USD'!H$3 -> -3062.5172 | I9: ='Datos pesos'!I9/'Datos USD'!I$3 -> -3206.1944 | ... Q9: ='Datos pesos'!Q9/'Datos USD'!Q$3 -> -3534.8171
A10: Gross income | B10: ='Datos pesos'!B10/'Datos USD'!B$3 -> 59286.917 | C10: ='Datos pesos'!C10/'Datos USD'!C$3 -> 33321.686 | D10: ='Datos pesos'!D10/'Datos USD'!D$3 -> 61741.5 | E10: ='Datos pesos'!E10/'Datos USD'!E$3 -> 68435.003 | F10: ='Datos pesos'!F10/'Datos USD'!F$3 -> 87648.598 | G10: ='Datos pesos'!G10/'Datos USD'!G$3 -> 48257.315 | H10: ='Datos pesos'!H10/'Datos USD'!H$3 -> 44605.852 | I10: ='Datos pesos'!I10/'Datos USD'!I$3 -> 39064.963 | ... Q10: ='Datos pesos'!Q10/'Datos USD'!Q$3 -> 105300.41
A11: Operating costs AGC | B11: ='Datos pesos'!B11/'Datos USD'!B$3 -> 0 | C11: ='Datos pesos'!C11/'Datos USD'!C$3 -> 0 | D11: ='Datos pesos'!D11/'Datos USD'!D$3 -> 0 | E11: ='Datos pesos'!E11/'Datos USD'!E$3 -> 0 | F11: ='Datos pesos'!F11/'Datos USD'!F$3 -> 0 | G11: ='Datos pesos'!G11/'Datos USD'!G$3 -> 0 | H11: ='Datos pesos'!H11/'Datos USD'!H$3 -> 0 | I11: ='Datos pesos'!I11/'Datos USD'!I$3 -> 0 | ... Q11: ='Datos pesos'!Q11/'Datos USD'!Q$3 -> -7024.2973
A12: Operating costs Sailing | B12: ='Datos pesos'!B12/'Datos USD'!B$3 -> -20006.845 | C12: ='Datos pesos'!C12/'Datos USD'!C$3 -> -25564.78 | D12: ='Datos pesos'!D12/'Datos USD'!D$3 -> -39642.168 | E12: ='Datos pesos'!E12/'Datos USD'!E$3 -> -39537.841 | F12: ='Datos pesos'!F12/'Datos USD'!F$3 -> -40914.648 | G12: ='Datos pesos'!G12/'Datos USD'!G$3 -> -39441.332 | H12: ='Datos pesos'!H12/'Datos USD'!H$3 -> -35417.373 | I12: ='Datos pesos'!I12/'Datos USD'!I$3 -> -34725.544 | ... Q12: ='Datos pesos'!Q12/'Datos USD'!Q$3 -> -79922.434
A13: Operatings costs less D&A | B13: ='Datos pesos'!B13/'Datos USD'!B$3 -> -20006.845 | C13: ='Datos pesos'!C13/'Datos USD'!C$3 -> -25564.78 | D13: ='Datos pesos'!D13/'Datos USD'!D$3 -> -39642.168 | E13: ='Datos pesos'!E13/'Datos USD'!E$3 -> -39537.841 | F13: ='Datos pesos'!F13/'Datos USD'!F$3 -> -40914.648 | G13: ='Datos pesos'!G13/'Datos USD'!G$3 -> -39441.332 | H13: ='Datos pesos'!H13/'Datos USD'!H$3 -> -35417.373 | I13: ='Datos pesos'!I13/'Datos USD'!I$3 -> -34725.544 | ... Q13: ='Datos pesos'!Q13/'Datos USD'!Q$3 -> -86946.731
A14: EBITDA | B14: ='Datos pesos'!B14/'Datos USD'!B$3 -> 39280.072 | C14: ='Datos pesos'!C14/'Datos USD'!C$3 -> 7756.9055 | D14: ='Datos pesos'!D14/'Datos USD'!D$3 -> 22099.332 | E14: ='Datos pesos'!E14/'Datos USD'!E$3 -> 28897.162 | F14: ='Datos pesos'!F14/'Datos USD'!F$3 -> 46733.95 | G14: ='Datos pesos'!G14/'Datos USD'!G$3 -> 8815.9836 | H14: ='Datos pesos'!H14/'Datos USD'!H$3 -> 9188.4797 | I14: ='Datos pesos'!I14/'Datos USD'!I$3 -> 4339.4194 | ... Q14: ='Datos pesos'!Q14/'Datos USD'!Q$3 -> 18353.679
A15: D&A | B15: ='Datos pesos'!B15/'Datos USD'!B$3 -> -18.982075 | C15: ='Datos pesos'!C15/'Datos USD'!C$3 -> -20.128873 | D15: ='Datos pesos'!D15/'Datos USD'!D$3 -> -29.249587 | E15: ='Datos pesos'!E15/'Datos USD'!E$3 -> -28.843186 | F15: ='Datos pesos'!F15/'Datos USD'!F$3 -> -26.176235 | G15: ='Datos pesos'!G15/'Datos USD'!G$3 -> -22.77278 | H15: ='Datos pesos'!H15/'Datos USD'!H$3 -> -21.708169 | I15: ='Datos pesos'!I15/'Datos USD'!I$3 -> -22.580276 | ... Q15: ='Datos pesos'!Q15/'Datos USD'!Q$3 -> -72.860507
A16: Operating Income | B16: ='Datos pesos'!B16/'Datos USD'!B$3 -> 39261.09 | C16: ='Datos pesos'!C16/'Datos USD'!C$3 -> 7736.7767 | D16: ='Datos pesos'!D16/'Datos USD'!D$3 -> 22070.082 | E16: ='Datos pesos'!E16/'Datos USD'!E$3 -> 28868.319 | F16: ='Datos pesos'!F16/'Datos USD'!F$3 -> 46707.774 | G16: ='Datos pesos'!G16/'Datos USD'!G$3 -> 8793.2108 | H16: ='Datos pesos'!H16/'Datos USD'!H$3 -> 9166.7715 | I16: ='Datos pesos'!I16/'Datos USD'!I$3 -> 4316.8391 | ... Q16: ='Datos pesos'!Q16/'Datos USD'!Q$3 -> 18280.819
A17: Financial results from AGC | B17: ='Datos pesos'!B17/'Datos USD'!B$3 -> 4952.1871 | C17: ='Datos pesos'!C17/'Datos USD'!C$3 -> -2563.8864 | D17: ='Datos pesos'!D17/'Datos USD'!D$3 -> -310.395 | E17: ='Datos pesos'!E17/'Datos USD'!E$3 -> 1233.7061 | F17: ='Datos pesos'!F17/'Datos USD'!F$3 -> 4832.9807 | G17: ='Datos pesos'!G17/'Datos USD'!G$3 -> 810.33159 | H17: ='Datos pesos'!H17/'Datos USD'!H$3 -> -706.72183 | I17: ='Datos pesos'!I17/'Datos USD'!I$3 -> -1949.1168 | ... Q17: ='Datos pesos'!Q17/'Datos USD'!Q$3 -> 19666.881
A18: Financial results from Sailing | B18: ='Datos pesos'!B18/'Datos USD'!B$3 -> 137838.63 | C18: ='Datos pesos'!C18/'Datos USD'!C$3 -> -58390.141 | D18: ='Datos pesos'!D18/'Datos USD'!D$3 -> 96870.395 | E18: ='Datos pesos'!E18/'Datos USD'!E$3 -> 81056.407 | F18: ='Datos pesos'!F18/'Datos USD'!F$3 -> 99357.051 | G18: ='Datos pesos'!G18/'Datos USD'!G$3 -> -25011.105 | H18: ='Datos pesos'!H18/'Datos USD'!H$3 -> -44974.291 | I18: ='Datos pesos'!I18/'Datos USD'!I$3 -> 86643.04 | ... Q18: ='Datos pesos'!Q18/'Datos USD'!Q$3 -> -68855.709
A19: Financial results total | B19: ='Datos pesos'!B19/'Datos USD'!B$3 -> 142790.82 | C19: ='Datos pesos'!C19/'Datos USD'!C$3 -> -60954.028 | D19: ='Datos pesos'!D19/'Datos USD'!D$3 -> 96560.001 | E19: ='Datos pesos'!E19/'Datos USD'!E$3 -> 82290.113 | F19: ='Datos pesos'!F19/'Datos USD'!F$3 -> 104190.03 | G19: ='Datos pesos'!G19/'Datos USD'!G$3 -> -24200.773 | H19: ='Datos pesos'!H19/'Datos USD'!H$3 -> -45681.013 | I19: ='Datos pesos'!I19/'Datos USD'!I$3 -> 84693.923 | ... Q19: ='Datos pesos'!Q19/'Datos USD'!Q$3 -> -49188.829
... A22: Net income | B22: ='Datos pesos'!B22/'Datos USD'!B$3 -> 182051.91 | C22: ='Datos pesos'!C22/'Datos USD'!C$3 -> -53217.251 | D22: ='Datos pesos'!D22/'Datos USD'!D$3 -> 118630.08 | E22: ='Datos pesos'!E22/'Datos USD'!E$3 -> 111158.43 | F22: ='Datos pesos'!F22/'Datos USD'!F$3 -> 150897.81 | G22: ='Datos pesos'!G22/'Datos USD'!G$3 -> -15407.563 | H22: ='Datos pesos'!H22/'Datos USD'!H$3 -> -36514.242 | I22: ='Datos pesos'!I22/'Datos USD'!I$3 -> 89010.762 | ... Q22: ='Datos pesos'!Q22/'Datos USD'!Q$3 -> -30275.535
B23: ='Datos pesos'!B23/'Datos USD'!B$3 -> 0 | C23: ='Datos pesos'!C23/'Datos USD'!C$3 -> 0 | D23: ='Datos pesos'!D23/'Datos USD'!D$3 -> 0 | E23: ='Datos pesos'!E23/'Datos USD'!E$3 -> 0 | F23: ='Datos pesos'!F23/'Datos USD'!F$3 -> 0 | G23: ='Datos pesos'!G23/'Datos USD'!G$3 -> 0 | H23: ='Datos pesos'!H23/'Datos USD'!H$3 -> 0 | I23: ='Datos pesos'!I23/'Datos USD'!I$3 -> 0 | ... Q23: ='Datos pesos'!Q23/'Datos USD'!Q$3 -> 0
B24: ='Datos pesos'!B24/'Datos USD'!B$3 -> 0 | C24: ='Datos pesos'!C24/'Datos USD'!C$3 -> 0 | D24: ='Datos pesos'!D24/'Datos USD'!D$3 -> 0 | E24: ='Datos pesos'!E24/'Datos USD'!E$3 -> 0 | F24: ='Datos pesos'!F24/'Datos USD'!F$3 -> 0 | G24: ='Datos pesos'!G24/'Datos USD'!G$3 -> 0 | H24: ='Datos pesos'!H24/'Datos USD'!H$3 -> 0 | I24: ='Datos pesos'!I24/'Datos USD'!I$3 -> 0 | ... Q24: ='Datos pesos'!Q24/'Datos USD'!Q$3 -> 0
A25: Current Assets | B25: ='Datos pesos'!B25/'Datos USD'!B$3 -> 0 | C25: ='Datos pesos'!C25/'Datos USD'!C$3 -> 0 | D25: ='Datos pesos'!D25/'Datos USD'!D$3 -> 0 | E25: ='Datos pesos'!E25/'Datos USD'!E$3 -> 0 | F25: ='Datos pesos'!F25/'Datos USD'!F$3 -> 0 | G25: ='Datos pesos'!G25/'Datos USD'!G$3 -> 0 | H25: ='Datos pesos'!H25/'Datos USD'!H$3 -> 0 | I25: ='Datos pesos'!I25/'Datos USD'!I$3 -> 0 | ... Q25: ='Datos pesos'!Q25/'Datos USD'!Q$3 -> 0
A26: Cash | B26: ='Datos pesos'!B26/'Datos USD'!B$3 -> 592471.38 | C26: ='Datos pesos'!C26/'Datos USD'!C$3 -> 612521.54 | D26: ='Datos pesos'!D26/'Datos USD'!D$3 -> 492899.8 | E26: ='Datos pesos'!E26/'Datos USD'!E$3 -> 670764.79 | F26: ='Datos pesos'!F26/'Datos USD'!F$3 -> 456548.14 | G26: ='Datos pesos'!G26/'Datos USD'!G$3 -> 454780.68 | H26: ='Datos pesos'!H26/'Datos USD'!H$3 -> 407332.84 | I26: ='Datos pesos'!I26/'Datos USD'!I$3 -> 385691.81 | ... Q26: ='Datos pesos'!Q26/'Datos USD'!Q$3 -> 358164.58
A27: Short-Term Investments | B27: ='Datos pesos'!B27/'Datos USD'!B$3 -> 747823.84 | C27: ='Datos pesos'!C27/'Datos USD'!C$3 -> 764449.36 | D27: ='Datos pesos'!D27/'Datos USD'!D$3 -> 965091.03 | E27: ='Datos pesos'!E27/'Datos USD'!E$3 -> 989189.25 | F27: ='Datos pesos'!F27/'Datos USD'!F$3 -> 1178278.5 | G27: ='Datos pesos'!G27/'Datos USD'!G$3 -> 529614.3 | H27: ='Datos pesos'!H27/'Datos USD'!H$3 -> 987664.84 | I27: ='Datos pesos'!I27/'Datos USD'!I$3 -> 1106015 | ... Q27: ='Datos pesos'!Q27/'Datos USD'!Q$3 -> 1620971.9
A28: Operational credtis | B28: ='Datos pesos'!B28/'Datos USD'!B$3 -> 149283.86 | C28: ='Datos pesos'!C28/'Datos USD'!C$3 -> 150567.14 | D28: ='Datos pesos'!D28/'Datos USD'!D$3 -> 163597.79 | E28: ='Datos pesos'!E28/'Datos USD'!E$3 -> 459768 | F28: ='Datos pesos'!F28/'Datos USD'!F$3 -> -228197.92 | G28: ='Datos pesos'!G28/'Datos USD'!G$3 -> 303717.72 | H28: ='Datos pesos'!H28/'Datos USD'!H$3 -> -119717.44 | I28: ='Datos pesos'!I28/'Datos USD'!I$3 -> -33812.543 | ... Q28: ='Datos pesos'!Q28/'Datos USD'!Q$3 -> -740787.96
A29: Other credits | B29: ='Datos pesos'!B29/'Datos USD'!B$3 -> 13960.338 | C29: ='Datos pesos'!C29/'Datos USD'!C$3 -> 12733.785 | D29: ='Datos pesos'!D29/'Datos USD'!D$3 -> 13831.814 | E29: ='Datos pesos'!E29/'Datos USD'!E$3 -> 11658.937 | F29: ='Datos pesos'!F29/'Datos USD'!F$3 -> 9053.5014 | G29: ='Datos pesos'!G29/'Datos USD'!G$3 -> 19123.384 | H29: ='Datos pesos'!H29/'Datos USD'!H$3 -> 21141.434 | I29: ='Datos pesos'!I29/'Datos USD'!I$3 -> 25818.72 | ... Q29: ='Datos pesos'!Q29/'Datos USD'!Q$3 -> 77603.817
A30: Total Current Assets | B30: ='Datos pesos'!B30/'Datos USD'!B$3 -> 1503539.4 | C30: ='Datos pesos'!C30/'Datos USD'!C$3 -> 1540271.8 | D30: ='Datos pesos'!D30/'Datos USD'!D$3 -> 1635420.4 | E30: ='Datos pesos'!E30/'Datos USD'!E$3 -> 2131381 | F30: ='Datos pesos'!F30/'Datos USD'!F$3 -> 1415682.3 | G30: ='Datos pesos'!G30/'Datos USD'!G$3 -> 1307236.1 | H30: ='Datos pesos'!H30/'Datos USD'!H$3 -> 1296421.7 | I30: ='Datos pesos'!I30/'Datos USD'!I$3 -> 1483713 | ... Q30: ='Datos pesos'!Q30/'Datos USD'!Q$3 -> 1315952.3
A31: Goodwill/Intangibles | B31: ='Datos pesos'!B31/'Datos USD'!B$3 -> 0 | C31: ='Datos pesos'!C31/'Datos USD'!C$3 -> 0 | D31: ='Datos pesos'!D31/'Datos USD'!D$3 -> 0 | E31: ='Datos pesos'!E31/'Datos USD'!E$3 -> 0 | F31: ='Datos pesos'!F31/'Datos USD'!F$3 -> 0 | G31: ='Datos pesos'!G31/'Datos USD'!G$3 -> 0 | H31: ='Datos pesos'!H31/'Datos USD'!H$3 -> 0 | I31: ='Datos pesos'!I31/'Datos USD'!I$3 -> 0 | ... Q31: ='Datos pesos'!Q31/'Datos USD'!Q$3 -> 0
A32: Bienes de uso | B32: ='Datos pesos'!B32/'Datos USD'!B$3 -> 0 | C32: ='Datos pesos'!C32/'Datos USD'!C$3 -> 0 | D32: ='Datos pesos'!D32/'Datos USD'!D$3 -> 0 | E32: ='Datos pesos'!E32/'Datos USD'!E$3 -> 0 | F32: ='Datos pesos'!F32/'Datos USD'!F$3 -> 0 | G32: ='Datos pesos'!G32/'Datos USD'!G$3 -> 0 | H32: ='Datos pesos'!H32/'Datos USD'!H$3 -> 0 | I32: ='Datos pesos'!I32/'Datos USD'!I$3 -> 0 | ... O32: ='Datos pesos'!O32/'Datos USD'!O$3 -> 0 | P32: 0 | Q32: ='Datos pesos'!Q32/'Datos USD'!Q$3 -> 48567.615
A33: Total del activo no corriente | B33: ='Datos pesos'!B33/'Datos USD'!B$3 -> 8084.7321 | C33: ='Datos pesos'!C33/'Datos USD'!C$3 -> 23331.673 | D33: ='Datos pesos'!D33/'Datos USD'!D$3 -> 26676.775 | E33: ='Datos pesos'!E33/'Datos USD'!E$3 -> 26277.279 | F33: ='Datos pesos'!F33/'Datos USD'!F$3 -> 23821.405 | G33: ='Datos pesos'!G33/'Datos USD'!G$3 -> 20701.354 | H33: ='Datos pesos'!H33/'Datos USD'!H$3 -> 19711.872 | I33: ='Datos pesos'!I33/'Datos USD'!I$3 -> 20481.2 | ... Q33: ='Datos pesos'!Q33/'Datos USD'!Q$3 -> #VALUE!
A34: TOTAL DE ACTIVO | B34: ='Datos pesos'!B34/'Datos USD'!B$3 -> 1511624.2 | C34: ='Datos pesos'!C34/'Datos USD'!C$3 -> 1563603.5 | D34: ='Datos pesos'!D34/'Datos USD'!D$3 -> 1662097.2 | E34: ='Datos pesos'!E34/'Datos USD'!E$3 -> 2157658.3 | F34: ='Datos pesos'!F34/'Datos USD'!F$3 -> 1439503.7 | G34: ='Datos pesos'!G34/'Datos USD'!G$3 -> 1327937.4 | H34: ='Datos pesos'!H34/'Datos USD'!H$3 -> 1316133.5 | I34: ='Datos pesos'!I34/'Datos USD'!I$3 -> 1504194.2 | ... Q34: ='Datos pesos'!Q34/'Datos USD'!Q$3 -> 1364519.9
B35: ='Datos pesos'!B35/'Datos USD'!B$3 -> 0 | C35: ='Datos pesos'!C35/'Datos USD'!C$3 -> 0 | D35: ='Datos pesos'!D35/'Datos USD'!D$3 -> 0 | E35: ='Datos pesos'!E35/'Datos USD'!E$3 -> 0 | F35: ='Datos pesos'!F35/'Datos USD'!F$3 -> 0 | G35: ='Datos pesos'!G35/'Datos USD'!G$3 -> 0 | H35: ='Datos pesos'!H35/'Datos USD'!H$3 -> 0 | I35: ='Datos pesos'!I35/'Datos USD'!I$3 -> 0 | ... Q35: ='Datos pesos'!Q35/'Datos USD'!Q$3 -> 0
B36: ='Datos pesos'!B36/'Datos USD'!B$3 -> 0 | C36: ='Datos pesos'!C36/'Datos USD'!C$3 -> 0 | D36: ='Datos pesos'!D36/'Datos USD'!D$3 -> 0 | E36: ='Datos pesos'!E36/'Datos USD'!E$3 -> 0 | F36: ='Datos pesos'!F36/'Datos USD'!F$3 -> 0 | G36: ='Datos pesos'!G36/'Datos USD'!G$3 -> 0 | H36: ='Datos pesos'!H36/'Datos USD'!H$3 -> 0 | I36: ='Datos pesos'!I36/'Datos USD'!I$3 -> 0 | ... Q36: ='Datos pesos'!Q36/'Datos USD'!Q$3 -> 0
A37: Liabilities | B37: ='Datos pesos'!B37/'Datos USD'!B$3 -> 0 | C37: ='Datos pesos'!C37/'Datos USD'!C$3 -> 0 | D37: ='Datos pesos'!D37/'Datos USD'!D$3 -> 0 | E37: ='Datos pesos'!E37/'Datos USD'!E$3 -> 0 | F37: ='Datos pesos'!F37/'Datos USD'!F$3 -> 0 | G37: ='Datos pesos'!G37/'Datos USD'!G$3 -> 0 | H37: ='Datos pesos'!H37/'Datos USD'!H$3 -> 0 | I37: ='Datos pesos'!I37/'Datos USD'!I$3 -> 0 | ... Q37: ='Datos pesos'!Q37/'Datos USD'!Q$3 -> 0
A38: Operational debt | B38: ='Datos pesos'!B38/'Datos USD'!B$3 -> -925862.75 | C38: ='Datos pesos'!C38/'Datos USD'!C$3 -> -1023959.2 | D38: ='Datos pesos'!D38/'Datos USD'!D$3 -> -957627.05 | E38: ='Datos pesos'!E38/'Datos USD'!E$3 -> -1367227.5 | F38: ='Datos pesos'!F38/'Datos USD'!F$3 -> -639475.7 | G38: ='Datos pesos'!G38/'Datos USD'!G$3 -> -680116.58 | H38: ='Datos pesos'!H38/'Datos USD'!H$3 -> -748658.34 | I38: ='Datos pesos'!I38/'Datos USD'!I$3 -> -833990.63 | ... Q38: ='Datos pesos'!Q38/'Datos USD'!Q$3 -> -648013.01
A39: Commercial debt | B39: ='Datos pesos'!B39/'Datos USD'!B$3 -> -4941.517 | C39: ='Datos pesos'!C39/'Datos USD'!C$3 -> -4631.7241 | D39: ='Datos pesos'!D39/'Datos USD'!D$3 -> -4660.346 | E39: ='Datos pesos'!E39/'Datos USD'!E$3 -> -5226.2916 | F39: ='Datos pesos'!F39/'Datos USD'!F$3 -> -6054.8769 | G39: ='Datos pesos'!G39/'Datos USD'!G$3 -> -4848.2027 | H39: ='Datos pesos'!H39/'Datos USD'!H$3 -> -4776.4888 | I39: ='Datos pesos'!I39/'Datos USD'!I$3 -> -5041.4086 | ... Q39: ='Datos pesos'!Q39/'Datos USD'!Q$3 -> -11960.514
A40: Fiscal debt | B40: ='Datos pesos'!B40/'Datos USD'!B$3 -> -2173.5723 | C40: ='Datos pesos'!C40/'Datos USD'!C$3 -> -3556.972 | D40: ='Datos pesos'!D40/'Datos USD'!D$3 -> -6131.42 | E40: ='Datos pesos'!E40/'Datos USD'!E$3 -> -7860.9285 | F40: ='Datos pesos'!F40/'Datos USD'!F$3 -> -9078.7482 | G40: ='Datos pesos'!G40/'Datos USD'!G$3 -> -3924.8207 | H40: ='Datos pesos'!H40/'Datos USD'!H$3 -> -4683.624 | I40: ='Datos pesos'!I40/'Datos USD'!I$3 -> -5782.2899 | ... Q40: ='Datos pesos'!Q40/'Datos USD'!Q$3 -> -29100.648
A41: Social debt | B41: ='Datos pesos'!B41/'Datos USD'!B$3 -> -2460.818 | C41: ='Datos pesos'!C41/'Datos USD'!C$3 -> -70497.341 | D41: ='Datos pesos'!D41/'Datos USD'!D$3 -> -78176.726 | E41: ='Datos pesos'!E41/'Datos USD'!E$3 -> -77971.371 | F41: ='Datos pesos'!F41/'Datos USD'!F$3 -> -17189.509 | G41: ='Datos pesos'!G41/'Datos USD'!G$3 -> -14363.03 | H41: ='Datos pesos'!H41/'Datos USD'!H$3 -> -13464.751 | I41: ='Datos pesos'!I41/'Datos USD'!I$3 -> -14209.336 | ... Q41: ='Datos pesos'!Q41/'Datos USD'!Q$3 -> -41631.517
A42: Total current liabilities | B42: ='Datos pesos'!B42/'Datos USD'!B$3 -> -935438.66 | C42: ='Datos pesos'!C42/'Datos USD'!C$3 -> -1102645.2 | D42: ='Datos pesos'!D42/'Datos USD'!D$3 -> -1046595.5 | E42: ='Datos pesos'!E42/'Datos USD'!E$3 -> -1458286.1 | F42: ='Datos pesos'!F42/'Datos USD'!F$3 -> -671798.84 | G42: ='Datos pesos'!G42/'Datos USD'!G$3 -> -703252.63 | H42: ='Datos pesos'!H42/'Datos USD'!H$3 -> -771583.2 | I42: ='Datos pesos'!I42/'Datos USD'!I$3 -> -859023.66 | ... Q42: ='Datos pesos'!Q42/'Datos USD'!Q$3 -> -730705.69
...

Sheet Model USD
A1: Maturity | B1: -0.01
A2: Discount | B2: 0.15
A3: ROIC | B3: 0.13
A4: NPV | B4: =NPV($B$2,R26:ET26) -> 2194737.1
C7: Q124 | D7: Q224 | E7: Q324 | F7: Q424 | G7: Q125 | H7: Q225 | I7: Q325 | J7: Q425 | K7: Q126 | L7: Q226 | M7: Q326 | N7: Q426 | Q7: 2024 | R7: 2025 | S7: 2026 | T7: =S7+1 -> 2027 | U7: =T7+1 -> 2028 | V7: =U7+1 -> 2029 | W7: =V7+1 -> 2030 | X7: =W7+1 -> 2031 | Y7: =X7+1 -> 2032 | Z7: =Y7+1 -> 2033 | AA7: =Z7+1 -> 2034 | ... ET7: =ES7+1 -> 2157
B8: AGC | C8: =SUM('Datos USD'!B4:D4) -> 109412.91 | D8: =SUM('Datos USD'!E4:G4) -> 121515.19 | E8: =SUM('Datos USD'!H4:J4) -> 84578.218 | F8: =SUM('Datos USD'!K4:M4) -> 93820.648 | G8: =SUM('Datos USD'!N4:P4) -> 83402.015 | Q8: =SUM(C8:F8) -> 409326.96
B9: Sailing | C9: =SUM('Datos USD'!B5:D5) -> 55012.731 | D9: =SUM('Datos USD'!E5:G5) -> 94061.206 | E9: =SUM('Datos USD'!H5:J5) -> 69808.403 | F9: =SUM('Datos USD'!K5:M5) -> 157973.37 | G9: =SUM('Datos USD'!N5:P5) -> 207451.32 | Q9: =SUM(C9:F9) -> 376855.71
B10: Revenues | C10: =SUM('Datos USD'!B6:D6) -> 164425.64 | D10: =SUM('Datos USD'!E6:G6) -> 215576.39 | E10: =SUM('Datos USD'!H6:J6) -> 154386.62 | F10: =SUM('Datos USD'!K6:M6) -> 251794.02 | G10: =SUM('Datos USD'!N6:P6) -> 290853.34 | Q10: =SUM(C10:F10) -> 786182.67
B11: COGS AGC | C11: =SUM('Datos USD'!B7:D7) -> 0 | D11: =SUM('Datos USD'!E7:G7) -> 0 | E11: =SUM('Datos USD'!H7:J7) -> 0 | F11: =SUM('Datos USD'!K7:M7) -> 0 | G11: =SUM('Datos USD'!N7:P7) -> 0 | Q11: =SUM(C11:F11) -> 0
B12: COGS Sailing | C12: =SUM('Datos USD'!B8:D8) -> -10075.538 | D12: =SUM('Datos USD'!E8:G8) -> -11235.478 | E12: =SUM('Datos USD'!H8:J8) -> -12690.754 | F12: =SUM('Datos USD'!K8:M8) -> -14549.799 | G12: =SUM('Datos USD'!N8:P8) -> -9373.7596 | Q12: =SUM(C12:F12) -> -48551.568
B13: COGS total | C13: =SUM('Datos USD'!B9:D9) -> -10075.537 | D13: =SUM('Datos USD'!E9:G9) -> -11235.478 | E13: =SUM('Datos USD'!H9:J9) -> -12690.754 | F13: =SUM('Datos USD'!K9:M9) -> -14549.799 | G13: =SUM('Datos USD'!N9:P9) -> -9373.76 | Q13: =SUM(C13:F13) -> -48551.568
B14: Gross income | C14: =SUM('Datos USD'!B10:D10) -> 154350.1 | D14: =SUM('Datos USD'!E10:G10) -> 204340.92 | E14: =SUM('Datos USD'!H10:J10) -> 141695.87 | F14: =SUM('Datos USD'!K10:M10) -> 237244.22 | G14: =SUM('Datos USD'!N10:P10) -> 281479.58 | Q14: =SUM(C14:F14) -> 737631.11
B15: Operating costs AGC | C15: =SUM('Datos USD'!B11:D11) -> 0 | D15: =SUM('Datos USD'!E11:G11) -> 0 | E15: =SUM('Datos USD'!H11:J11) -> 0 | F15: =SUM('Datos USD'!K11:M11) -> 0 | G15: =SUM('Datos USD'!N11:P11) -> -13626.323 | Q15: =SUM(C15:F15) -> 0
B16: Operating costs Sailing | C16: =SUM('Datos USD'!B12:D12) -> -85213.793 | D16: =SUM('Datos USD'!E12:G12) -> -119893.82 | E16: =SUM('Datos USD'!H12:J12) -> -127752.34 | F16: =SUM('Datos USD'!K12:M12) -> -307294.61 | G16: =SUM('Datos USD'!N12:P12) -> -277692.36 | Q16: =SUM(C16:F16) -> -640154.56
B17: Operatings costs less D&A | C17: =SUM('Datos USD'!B13:D13) -> -85213.793 | D17: =SUM('Datos USD'!E13:G13) -> -119893.82 | E17: =SUM('Datos USD'!H13:J13) -> -127752.34 | F17: =SUM('Datos USD'!K13:M13) -> -307294.61 | G17: =SUM('Datos USD'!N13:P13) -> -291318.68 | Q17: =SUM(C17:F17) -> -640154.56
B18: EBITDA | C18: =SUM('Datos USD'!B14:D14) -> 69136.309 | D18: =SUM('Datos USD'!E14:G14) -> 84447.096 | E18: =SUM('Datos USD'!H14:J14) -> 13943.529 | F18: =SUM('Datos USD'!K14:M14) -> -70050.388 | G18: =SUM('Datos USD'!N14:P14) -> -9839.1016 | Q18: =SUM(C18:F18) -> 97476.547 | R18: 97476.547 | S18: 97476.547 | T18: 97476.547 | U18: 97476.547 | V18: 97476.547 | W18: 97476.547 | X18: 97476.547 | Y18: 97476.547 | Z18: 97476.547 | AA18: 97476.547 | AB18: 97476.547 | AC18: 96501.781 | AD18: 95536.763 | AE18: 94581.396 | AF18: 93635.582 | AG18: 92699.226 | AH18: 91772.234 | AI18: 90854.511 | AJ18: 89945.966 | AK18: 89046.507 | AL18: 88156.041 | AM18: 87274.481 | AN18: 86401.736 | AO18: 85537.719 | AP18: 84682.342 | AQ18: 83835.518 | AR18: 82997.163 | AS18: 82167.191 | AT18: 81345.52 | AU18: 80532.064 | AV18: 79726.744 | AW18: 78929.476 | AX18: 78140.181 | AY18: 77358.78 | AZ18: 76585.192 | BA18: 75819.34 | BB18: 75061.147 | BC18: 74310.535 | BD18: 73567.43 | BE18: 72831.755 | BF18: 72103.438 | BG18: 71382.404 | BH18: 70668.579 | BI18: 69961.894 | BJ18: 69262.275 | BK18: 68569.652 | BL18: 67883.955 | BM18: 67205.116 | BN18: 66533.065 | BO18: 65867.734 | BP18: 65209.057 | BQ18: 64556.966 | BR18: 63911.397 | BS18: 63272.283 | BT18: 62639.56 | BU18: 62013.164 | BV18: 61393.033 | BW18: 60779.102 | BX18: 60171.311 | BY18: 59569.598 | BZ18: 58973.902 | CA18: 58384.163 | CB18: 57800.321 | CC18: 57222.318 | CD18: 56650.095 | CE18: 56083.594 | CF18: 55522.758 | CG18: 54967.531 | CH18: 54417.855 | CI18: 53873.677 | CJ18: 53334.94 | CK18: 52801.591 | CL18: 52273.575 | CM18: 51750.839 | CN18: 51233.33 | CO18: 50720.997 | CP18: 50213.787 | CQ18: 49711.649 | CR18: 49214.533 | CS18: 48722.388 | CT18: 48235.164 | CU18: 47752.812 | CV18: 47275.284 | CW18: 46802.531 | CX18: 46334.506 | CY18: 45871.161 | CZ18: 45412.449 | DA18: 44958.325 | DB18: 44508.741 | DC18: 44063.654 | DD18: 43623.017 | DE18: 43186.787 | DF18: 42754.919 | DG18: 42327.37 | DH18: 41904.096 | DI18: 41485.055 | DJ18: 41070.205 | DK18: 40659.503 | DL18: 40252.908 | DM18: 39850.379 | DN18: 39451.875 | DO18: 39057.356 | DP18: 38666.783 | DQ18: 38280.115 | DR18: 37897.314 | DS18: 37518.341 | DT18: 37143.157 | DU18: 36771.726 | DV18: 36404.008 | DW18: 36039.968 | DX18: 35679.569 | DY18: 35322.773 | DZ18: 34969.545 | EA18: 34619.85 | EB18: 34273.651 | EC18: 33930.915 | ED18: 33591.606 | EE18: 33255.689 | EF18: 32923.133 | EG18: 32593.901 | EH18: 32267.962 | EI18: 31945.283 | EJ18: 31625.83 | EK18: 31309.572 | EL18: 30996.476 | EM18: 30686.511 | EN18: 30379.646 | EO18: 30075.849 | EP18: 29775.091 | EQ18: 29477.34 | ER18: 29182.567 | ES18: 28890.741 | ET18: 28601.834
B19: D&A | C19: =SUM('Datos USD'!B15:D15) -> -68.360534 | D19: =SUM('Datos USD'!E15:G15) -> -77.792201 | E19: =SUM('Datos USD'!H15:J15) -> -80.30354 | F19: =SUM('Datos USD'!K15:M15) -> -165.75251 | G19: =SUM('Datos USD'!N15:P15) -> -202.256 | Q19: =SUM(C19:F19) -> -392.20878
B20: Operating Income | C20: =SUM('Datos USD'!B16:D16) -> 69067.949 | D20: =SUM('Datos USD'!E16:G16) -> 84369.304 | E20: =SUM('Datos USD'!H16:J16) -> 13863.225 | F20: =SUM('Datos USD'!K16:M16) -> -70216.14 | G20: =SUM('Datos USD'!N16:P16) -> -10041.358 | Q20: =SUM(C20:F20) -> 97084.338
B21: Financial results from AGC | C21: =SUM('Datos USD'!B17:D17) -> 2077.9057 | D21: =SUM('Datos USD'!E17:G17) -> 6877.0184 | E21: =SUM('Datos USD'!H17:J17) -> -2943.1214 | F21: =SUM('Datos USD'!K17:M17) -> -12178.81 | G21: =SUM('Datos USD'!N17:P17) -> -16659.57 | Q21: =SUM(C21:F21) -> -6167.0076
B22: Financial results from Sailing | C22: =SUM('Datos USD'!B18:D18) -> 176318.88 | D22: =SUM('Datos USD'!E18:G18) -> 155402.35 | E22: =SUM('Datos USD'!H18:J18) -> 35188.026 | F22: =SUM('Datos USD'!K18:M18) -> 169537.38 | G22: =SUM('Datos USD'!N18:P18) -> -44870.475 | Q22: =SUM(C22:F22) -> 536446.64 | R22: =Q28*$B$3 -> 117000 | S22: =R28*$B$3 -> 132210 | T22: =S28*$B$3 -> 149397.3 | U22: =T28*$B$3 -> 168818.95 | V22: =U28*$B$3 -> 190765.41 | W22: =V28*$B$3 -> 215564.92 | X22: =W28*$B$3 -> 243588.36 | Y22: =X28*$B$3 -> 275254.84 | ... AB22: =AA28*$B$3 -> 397164.38
B23: Financial results total | C23: =SUM('Datos USD'!B19:D19) -> 178396.79 | D23: =SUM('Datos USD'!E19:G19) -> 162279.37 | E23: =SUM('Datos USD'!H19:J19) -> 32244.904 | F23: =SUM('Datos USD'!K19:M19) -> 157358.57 | G23: =SUM('Datos USD'!N19:P19) -> -61530.045 | Q23: =SUM(C23:F23) -> 530279.63
B24: Pretax Income | C24: =SUM('Datos USD'!B20:D20) -> 247464.74 | D24: =SUM('Datos USD'!E20:G20) -> 246648.67 | E24: =SUM('Datos USD'!H20:J20) -> 46108.129 | F24: =SUM('Datos USD'!K20:M20) -> 87142.428 | G24: =SUM('Datos USD'!N20:P20) -> -71571.403 | Q24: =SUM(C24:F24) -> 627363.97
B25: Income tax | C25: =SUM('Datos USD'!B21:D21) -> 0 | D25: =SUM('Datos USD'!E21:G21) -> 0 | E25: =SUM('Datos USD'!H21:J21) -> 0 | F25: =SUM('Datos USD'!K21:M21) -> 0 | G25: =SUM('Datos USD'!N21:P21) -> -743.32691 | Q25: =SUM(C25:F25) -> 0
B26: Net income | C26: =SUM('Datos USD'!B22:D22) -> 247464.74 | D26: =SUM('Datos USD'!E22:G22) -> 246648.67 | E26: =SUM('Datos USD'!H22:J22) -> 46108.129 | F26: =SUM('Datos USD'!K22:M22) -> 87142.428 | G26: =SUM('Datos USD'!N22:P22) -> -72314.73 | Q26: =SUM(C26:F26) -> 627363.97 | R26: =SUM(R18:R22) -> 214476.55 | S26: =SUM(S18:S22) -> 229686.55 | T26: =SUM(T18:T22) -> 246873.85 | U26: =SUM(U18:U22) -> 266295.5 | V26: =SUM(V18:V22) -> 288241.96 | W26: =SUM(W18:W22) -> 313041.46 | X26: =SUM(X18:X22) -> 341064.9 | Y26: =SUM(Y18:Y22) -> 372731.39 | ... AB26: =SUM(AB18:AB22) -> 494640.93 | AC26: =AB26*(1+$B$1) -> 489694.52 | AD26: =AC26*(1+$B$1) -> 484797.58 | AE26: =AD26*(1+$B$1) -> 479949.6 | AF26: =AE26*(1+$B$1) -> 475150.1 | AG26: =AF26*(1+$B$1) -> 470398.6 | AH26: =AG26*(1+$B$1) -> 465694.62 | AI26: =AH26*(1+$B$1) -> 461037.67 | AJ26: =AI26*(1+$B$1) -> 456427.29 | ... ET26: =ES26*(1+$B$1) -> 145138.89
Q28: 900000 | R28: =Q28+R22 -> 1017000 | S28: =R28+S22 -> 1149210 | T28: =S28+T22 -> 1298607.3 | U28: =T28+U22 -> 1467426.2 | V28: =U28+V22 -> 1658191.7 | W28: =V28+W22 -> 1873756.6 | X28: =W28+X22 -> 2117344.9 | Y28: =X28+Y22 -> 2392599.8 | ... AB28: =AA28+AB22 -> 3452275
B29: Current Assets
B30: Cash | C30: ='Datos USD'!D26 -> 492899.8 | D30: ='Datos USD'!G26 -> 454780.68 | E30: ='Datos USD'!J26 -> 903621.72 | F30: ='Datos USD'!M26 -> 394573.04 | G30: ='Datos USD'!P26 -> 496174.63 | Q30: =G30 -> 496174.63
B31: Short-Term Investments | C31: ='Datos USD'!D27 -> 965091.03 | D31: ='Datos USD'!G27 -> 529614.3 | E31: ='Datos USD'!J27 -> 805151.39 | F31: ='Datos USD'!M27 -> 1751104.7 | G31: ='Datos USD'!P27 -> 2024549.2 | Q31: =G31 -> 2024549.2
B32: Operational credtis | C32: ='Datos USD'!D28 -> 163597.79 | D32: ='Datos USD'!G28 -> 303717.72 | E32: ='Datos USD'!J28 -> 7144.6933 | F32: ='Datos USD'!M28 -> -516930.02 | G32: ='Datos USD'!P28 -> -915054.83 | Q32: =G32 -> -915054.83
B33: Other credits | C33: ='Datos USD'!D29 -> 13831.814 | D33: ='Datos USD'!G29 -> 19123.384 | E33: ='Datos USD'!J29 -> 37084.041 | F33: ='Datos USD'!M29 -> 46970.995 | G33: ='Datos USD'!P29 -> 75392.93 | Q33: =G33 -> 75392.93
B34: Total Current Assets | C34: ='Datos USD'!D30 -> 1635420.4 | D34: ='Datos USD'!G30 -> 1307236.1 | E34: ='Datos USD'!J30 -> 1753001.9 | F34: ='Datos USD'!M30 -> 1675718.7 | G34: ='Datos USD'!P30 -> 1681061.9 | Q34: =G34 -> 1681061.9
B35: Goodwill/Intangibles | C35: ='Datos USD'!D31 -> 0 | D35: ='Datos USD'!G31 -> 0 | E35: ='Datos USD'!J31 -> 0 | F35: ='Datos USD'!M31 -> 0 | G35: ='Datos USD'!P31 -> 0 | Q35: =G35 -> 0
B36: Bienes de uso | C36: ='Datos USD'!D32 -> 0 | D36: ='Datos USD'!G32 -> 0 | E36: ='Datos USD'!J32 -> 0 | F36: ='Datos USD'!M32 -> 0 | G36: 0 | Q36: =G36 -> 0
B37: Total del activo no corriente | C37: ='Datos USD'!D33 -> 26676.775 | D37: ='Datos USD'!G33 -> 20701.354 | E37: ='Datos USD'!J33 -> 23022.43 | F37: ='Datos USD'!M33 -> 27644.142 | G37: ='Datos USD'!P33 -> 46806.415 | Q37: =G37 -> 46806.415
B38: TOTAL DE ACTIVO | C38: ='Datos USD'!D34 -> 1662097.2 | D38: ='Datos USD'!G34 -> 1327937.4 | E38: ='Datos USD'!J34 -> 1776024.3 | F38: ='Datos USD'!M34 -> 1703362.8 | G38: ='Datos USD'!P34 -> 1727868.3 | Q38: =G38 -> 1727868.3
C39: ='Datos USD'!D35 -> 0 | D39: ='Datos USD'!G35 -> 0 | E39: ='Datos USD'!J35 -> 0 | F39: ='Datos USD'!M35 -> 0 | G39: ='Datos USD'!P35 -> 0 | Q39: =G39 -> 0
C40: ='Datos USD'!D36 -> 0 | D40: ='Datos USD'!G36 -> 0 | E40: ='Datos USD'!J36 -> 0 | F40: ='Datos USD'!M36 -> 0 | G40: ='Datos USD'!P36 -> 0 | Q40: =G40 -> 0
B41: Liabilities | C41: ='Datos USD'!D37 -> 0 | D41: ='Datos USD'!G37 -> 0 | E41: ='Datos USD'!J37 -> 0 | F41: ='Datos USD'!M37 -> 0 | G41: ='Datos USD'!P37 -> 0 | Q41: =G41 -> 0
B42: Operational debt | C42: ='Datos USD'!D38 -> -957627.05 | D42: ='Datos USD'!G38 -> -680116.58 | E42: ='Datos USD'!J38 -> -1076717.6 | F42: ='Datos USD'!M38 -> -919421.6 | G42: ='Datos USD'!P38 -> -985694.56 | Q42: =G42 -> -985694.56
B43: Commercial debt | C43: ='Datos USD'!D39 -> -4660.346 | D43: ='Datos USD'!G39 -> -4848.2027 | E43: ='Datos USD'!J39 -> -6649.0437 | F43: ='Datos USD'!M39 -> -27308.226 | G43: ='Datos USD'!P39 -> -8027.2213 | Q43: =G43 -> -8027.2213
...
