Workbook

Sheet Main
A1: Indice | C1: Fecha de liq | D1: =TODAY()+3 -> 46068 | V1: MEP | W1: =I15 -> 1438.6
A2: Caución
A3: FX
A4: Favoritos | C4: Caución | D4: Moneda | E4: Plazo | F4: Tasa | G4: Bid | H4: Ask | I4: VWAP | K4: Ticker | L4: Variación | M4: Tasa | O4: LECAPS | P4: Ticker | Q4: TEM | R4: Vencimiento | S4: Variación | T4: TNA | U4: Días a vencimiento | V4: Bid | W4: Ask | X4: Bid Volume | Y4: Ask Volume | Z4: Total Volume | AA4: Tasa directa | AB4: MEP BE | AD4: Soberanos HD | AE4: Ticker | AF4: TIR | AG4: MD | AH4: Bid | AI4: Ask | AJ4: Bid Volume | AK4: Ask Volume | AL4: Total Volume | AM4: Variación | AO4: Empresa | AP4: Ticker | AQ4: TIR | AR4: MD | AS4: Vto | AT4: Bid Price | AU4: Ask Price | AV4: Bid Volume | AW4: Ask volume | AX4: Total volume | AY4: Variación | AZ4: Periodicidad | BA4: Lamina minima | BB4: Tipo
A5: LECAPs | D5: USD | E5: 1 | F5: =VLOOKUP(E5,Caucho!$E$2:$N$65,3,FALSE) -> 0.0101 | G5: =VLOOKUP(E5,Caucho!$E$2:$N$65,7,FALSE) -> 0.0097 | H5: =VLOOKUP(E5,Caucho!$E$2:$N$65,8,FALSE) -> 0.0101 | I5: =VLOOKUP(E5,Caucho!$E$2:$N$65,10,FALSE) -> 0.010170026 | K5: LECAPs | L5: =AVERAGE(Tabla11[Variación]) -> 0.0023285714 | M5: =AVERAGE(Tabla11[TEM]) -> 0.027271311 | AE5: AE38D | AF5: {=INDIRECT("'" & Tabla9[[#This Row],[Ticker]] & "'!K4")} -> 0.092724559 | AG5: {=INDIRECT("'" & Tabla9[[#This Row],[Ticker]] & "'!K3")} -> 4.9172261 | AH5: {=_xll.PrecioBD(Tabla9[[#This Row],[Ticker]],"24","BID","N")} -> 81.47 | AI5: {=_xll.PrecioBD(Tabla9[[#This Row],[Ticker]],"24","ASK","N")} -> 81.48 | AJ5: {=_xll.PrecioBD(Tabla9[[#This Row],[Ticker]],24,"QUANTITY BID","N")} -> 2193 | AK5: {=_xll.PrecioBD(Tabla9[[#This Row],[Ticker]],24,"QUANTITY ASK","N")} -> 994 | AL5: {=_xll.PrecioBD(Tabla9[[#This Row],[Ticker]],24,"VOLUME AMOUNT","N")} -> 1057046.4 | AM5: {=_xll.PrecioBD(Tabla9[[#This Row],[Ticker]],24,"IMBALANCE","N")} -> -0.0014 | AP5: RUCDD | AQ5: {=INDIRECT("'" & AP5 & "'!K4")} -> 0.088503292 | AR5: {=INDIRECT("'" & AP5 & "'!K3")} -> 3.3903709 | AS5: 47822 | AT5: {=_xll.PrecioBD(AP5,"24","BID","N")} -> 105.4 | AU5: {=_xll.PrecioBD(AP5,"24","ASK","N")} -> 105.7 | AV5: {=_xll.PrecioBD(AP5,24,"QUANTITY BID","N")} -> 1812 | AW5: {=_xll.PrecioBD(AP5,24,"QUANTITY ASK","N")} -> 1064 | AX5: {=_xll.PrecioBD(AP5,24,"VOLUME AMOUNT","N")} -> 18647.88 | AY5: {=_xll.PrecioBD(AP5,24,"IMBALANCE","N")} -> 0.0061 | AZ5: Semestral | BA5: 1 | BB5: Sinkable
A6: Soberanos HD | D6: USD | E6: 7 | F6: =VLOOKUP(E6,Caucho!$E$2:$N$65,3,FALSE) -> 0.015 | G6: =VLOOKUP(E6,Caucho!$E$2:$N$65,7,FALSE) -> 0.0125 | H6: =VLOOKUP(E6,Caucho!$E$2:$N$65,8,FALSE) -> 0.015 | I6: =VLOOKUP(E6,Caucho!$E$2:$N$65,10,FALSE) -> 0.016787804 | K6: Soberanos HD | L6: =AVERAGE(Tabla9[Variación]) -> 0.0017 | M6: =AVERAGE(Tabla9[TIR]) -> 0.080722115 | P6: S27F6 | Q6: {=INDIRECT("'" & P6 & "'!J6")} -> 0.031282205 | R6: {=INDIRECT("'" & P6& "'!B3")} -> 46080 | S6: {=_xll.PrecioBD(P6,24,"IMBALANCE","N")} -> 0.0002 | T6: {=INDIRECT("'" & Tabla11[[#This Row],[Ticker]]& "'!J5")} -> 0.37188975 | U6: =Tabla11[[#This Row],[Vencimiento]]-$D$1 -> 12 | V6: {=_xll.PrecioBD(Tabla11[[#This Row],[Ticker]],"24","BID","N")} -> 124.315 | W6: {=_xll.PrecioBD(Tabla11[[#This Row],[Ticker]],"24","ASK","N")} -> 124.32 | X6: {=_xll.PrecioBD(Tabla11[[#This Row],[Ticker]],24,"QUANTITY BID","N")} -> 31951733 | Y6: {=_xll.PrecioBD(Tabla11[[#This Row],[Ticker]],24,"QUANTITY ASK","N")} -> 11705293 | Z6: {=_xll.PrecioBD(Tabla11[[#This Row],[Ticker]],24,"VOLUME AMOUNT","N")} -> 9.2597273e+09 | AA6: =Tabla11[[#This Row],[TNA]]/365*Tabla11[[#This Row],[Días a vencimiento]] -> 0.012226512 | AB6: =$I$15*(1+Tabla11[[#This Row],[TNA]]/365*Tabla11[[#This Row],[Días a vencimiento]]) -> 1456.189 | AE6: AL35D | AF6: {=INDIRECT("'" & Tabla9[[#This Row],[Ticker]] & "'!K4")} -> 0.091228488 | AG6: {=INDIRECT("'" & Tabla9[[#This Row],[Ticker]] & "'!K3")} -> 5.6582089 | AH6: {=_xll.PrecioBD(Tabla9[[#This Row],[Ticker]],"24","BID","N")} -> 78.77 | AI6: {=_xll.PrecioBD(Tabla9[[#This Row],[Ticker]],"24","ASK","N")} -> 78.83 | AJ6: {=_xll.PrecioBD(Tabla9[[#This Row],[Ticker]],24,"QUANTITY BID","N")} -> 3062 | AK6: {=_xll.PrecioBD(Tabla9[[#This Row],[Ticker]],24,"QUANTITY ASK","N")} -> 1738 | AL6: {=_xll.PrecioBD(Tabla9[[#This Row],[Ticker]],24,"VOLUME AMOUNT","N")} -> 605208.73 | AM6: {=_xll.PrecioBD(Tabla9[[#This Row],[Ticker]],24,"IMBALANCE","N")} -> -0.0007 | AP6: DNC7D | AQ6: {=INDIRECT("'" & AP6 & "'!K4")} -> 0.085928509 | AR6: {=INDIRECT("'" & AP6 & "'!K3")} -> 2.9700447 | AS6: 47780 | AT6: {=_xll.PrecioBD(AP6,"24","BID","N")} -> 107 | AU6: {=_xll.PrecioBD(AP6,"24","ASK","N")} -> 107.15 | AV6: {=_xll.PrecioBD(AP6,24,"QUANTITY BID","N")} -> 7300 | AW6: {=_xll.PrecioBD(AP6,24,"QUANTITY ASK","N")} -> 2300 | AX6: {=_xll.PrecioBD(AP6,24,"VOLUME AMOUNT","N")} -> 94696 | AY6: {=_xll.PrecioBD(AP6,24,"IMBALANCE","N")} -> 0 | AZ6: Semestral | BA6: 1000 | BB6: Sinkable
A7: Ons NY | D7: USD | E7: 31 | F7: =VLOOKUP(E7,Caucho!$E$2:$N$65,3,FALSE) -> #N/A | G7: =VLOOKUP(E7,Caucho!$E$2:$N$65,7,FALSE) -> #N/A | H7: =VLOOKUP(E7,Caucho!$E$2:$N$65,8,FALSE) -> #N/A | I7: =VLOOKUP(E7,Caucho!$E$2:$N$65,10,FALSE) -> #N/A | K7: ONs | L7: =AVERAGE(Tabla1[Variación]) -> 0.000325 | M7: =AVERAGE(AQ2:AQ19) -> 0.074338263 | P7: S16M6 | Q7: {=INDIRECT("'" & P7 & "'!J6")} -> 0.029721472 | R7: {=INDIRECT("'" & P7& "'!B3")} -> 46097 | S7: {=_xll.PrecioBD(P7,24,"IMBALANCE","N")} -> 0.0012 | T7: {=INDIRECT("'" & Tabla11[[#This Row],[Ticker]]& "'!J5")} -> 0.35641332 | U7: =Tabla11[[#This Row],[Vencimiento]]-$D$1 -> 29 | V7: {=_xll.PrecioBD(Tabla11[[#This Row],[Ticker]],"24","BID","N")} -> 101.725 | W7: {=_xll.PrecioBD(Tabla11[[#This Row],[Ticker]],"24","ASK","N")} -> 101.74 | X7: {=_xll.PrecioBD(Tabla11[[#This Row],[Ticker]],24,"QUANTITY BID","N")} -> 100 | Y7: {=_xll.PrecioBD(Tabla11[[#This Row],[Ticker]],24,"QUANTITY ASK","N")} -> 27975415 | Z7: {=_xll.PrecioBD(Tabla11[[#This Row],[Ticker]],24,"VOLUME AMOUNT","N")} -> 2.344682e+10 | AA7: =Tabla11[[#This Row],[TNA]]/365*Tabla11[[#This Row],[Días a vencimiento]] -> 0.028317771 | AB7: =$I$15*(1+Tabla11[[#This Row],[TNA]]/365*Tabla11[[#This Row],[Días a vencimiento]]) -> 1479.3379 | AE7: AL41D | AF7: {=INDIRECT("'" & Tabla9[[#This Row],[Ticker]] & "'!K4")} -> 0.090390292 | AG7: {=INDIRECT("'" & Tabla9[[#This Row],[Ticker]] & "'!K3")} -> 6.2109542 | AH7: {=_xll.PrecioBD(Tabla9[[#This Row],[Ticker]],"24","BID","N")} -> 74.13 | AI7: {=_xll.PrecioBD(Tabla9[[#This Row],[Ticker]],"24","ASK","N")} -> 74.15 | AJ7: {=_xll.PrecioBD(Tabla9[[#This Row],[Ticker]],24,"QUANTITY BID","N")} -> 1680 | AK7: {=_xll.PrecioBD(Tabla9[[#This Row],[Ticker]],24,"QUANTITY ASK","N")} -> 7910 | AL7: {=_xll.PrecioBD(Tabla9[[#This Row],[Ticker]],24,"VOLUME AMOUNT","N")} -> 92177.52 | AM7: {=_xll.PrecioBD(Tabla9[[#This Row],[Ticker]],24,"IMBALANCE","N")} -> 0.0027 | AP7: TLCTD | AQ7: {=INDIRECT("'" & AP7 & "'!K4")} -> 0.076098976 | AR7: {=INDIRECT("'" & AP7 & "'!K3")} -> 6.4927935 | AS7: 49695 | AT7: {=_xll.PrecioBD(AP7,"24","BID","N")} -> 107.1 | AU7: {=_xll.PrecioBD(AP7,"24","ASK","N")} -> 107.45 | AV7: {=_xll.PrecioBD(AP7,24,"QUANTITY BID","N")} -> 14542 | AW7: {=_xll.PrecioBD(AP7,24,"QUANTITY ASK","N")} -> 1000 | AX7: {=_xll.PrecioBD(AP7,24,"VOLUME AMOUNT","N")} -> 93632.85 | AY7: {=_xll.PrecioBD(AP7,24,"IMBALANCE","N")} -> 0.0004 | BA7: 0 | BB7: 0
A8: CEDEARs | D8: ARS | E8: 1 | F8: =VLOOKUP(E8,Caucho!$E$66:$N$141,3,FALSE) -> 0.298 | G8: =VLOOKUP(E8,Caucho!$E$66:$N$141,7,FALSE) -> 0.298 | H8: =VLOOKUP(E8,Caucho!$E$66:$N$141,8,FALSE) -> 0.299 | I8: =VLOOKUP(E8,Caucho!$E$66:$N$141,10,FALSE) -> 0.27311917 | K8: VXX | L8: {=_xll.PrecioBD(K8,24,"IMBALANCE","N")} -> 0 | P8: S17A6 | Q8: {=INDIRECT("'" & P8 & "'!J6")} -> 0.029462418 | R8: {=INDIRECT("'" & P8& "'!B3")} -> 46129 | S8: {=_xll.PrecioBD(P8,24,"IMBALANCE","N")} -> 0.0011 | T8: {=INDIRECT("'" & Tabla11[[#This Row],[Ticker]]& "'!J5")} -> 0.35878603 | U8: =Tabla11[[#This Row],[Vencimiento]]-$D$1 -> 61 | V8: {=_xll.PrecioBD(Tabla11[[#This Row],[Ticker]],"24","BID","N")} -> 103.899 | W8: {=_xll.PrecioBD(Tabla11[[#This Row],[Ticker]],"24","ASK","N")} -> 103.9 | X8: {=_xll.PrecioBD(Tabla11[[#This Row],[Ticker]],24,"QUANTITY BID","N")} -> 384989 | Y8: {=_xll.PrecioBD(Tabla11[[#This Row],[Ticker]],24,"QUANTITY ASK","N")} -> 499610894 | Z8: {=_xll.PrecioBD(Tabla11[[#This Row],[Ticker]],24,"VOLUME AMOUNT","N")} -> 9.3694606e+10 | AA8: =Tabla11[[#This Row],[TNA]]/365*Tabla11[[#This Row],[Días a vencimiento]] -> 0.059961501 | AB8: =$I$15*(1+Tabla11[[#This Row],[TNA]]/365*Tabla11[[#This Row],[Días a vencimiento]]) -> 1524.8606 | AE8: GD41D | AF8: {=INDIRECT("'" & Tabla9[[#This Row],[Ticker]] & "'!K4")} -> 0.088145849 | AG8: {=INDIRECT("'" & Tabla9[[#This Row],[Ticker]] & "'!K3")} -> 6.2475791 | AH8: {=_xll.PrecioBD(Tabla9[[#This Row],[Ticker]],"24","BID","N")} -> 75.11 | AI8: {=_xll.PrecioBD(Tabla9[[#This Row],[Ticker]],"24","ASK","N")} -> 75.15 | AJ8: {=_xll.PrecioBD(Tabla9[[#This Row],[Ticker]],24,"QUANTITY BID","N")} -> 10 | AK8: {=_xll.PrecioBD(Tabla9[[#This Row],[Ticker]],24,"QUANTITY ASK","N")} -> 10 | AL8: {=_xll.PrecioBD(Tabla9[[#This Row],[Ticker]],24,"VOLUME AMOUNT","N")} -> 167503.41 | AM8: {=_xll.PrecioBD(Tabla9[[#This Row],[Ticker]],24,"IMBALANCE","N")} -> 0.0018 | AP8: TLCPD | AQ8: {=INDIRECT("'" & AP8 & "'!K4")} -> 0.077443376 | AR8: {=INDIRECT("'" & AP8 & "'!K3")} -> 4.9623155 | AS8: 48726 | AT8: {=_xll.PrecioBD(AP8,"24","BID","N")} -> 111.2 | AU8: {=_xll.PrecioBD(AP8,"24","ASK","N")} -> 111.3 | AV8: {=_xll.PrecioBD(AP8,24,"QUANTITY BID","N")} -> 53310 | AW8: {=_xll.PrecioBD(AP8,24,"QUANTITY ASK","N")} -> 71456 | AX8: {=_xll.PrecioBD(AP8,24,"VOLUME AMOUNT","N")} -> 182321.69 | AY8: {=_xll.PrecioBD(AP8,24,"IMBALANCE","N")} -> -0.0017 | AZ8: Semestral | BA8: 1 | BB8: Sinkable
A9: Panel Lider | D9: ARS | E9: 7 | F9: =VLOOKUP(E9,Caucho!$E$66:$N$141,3,FALSE) -> 0.31 | G9: =VLOOKUP(E9,Caucho!$E$66:$N$141,7,FALSE) -> 0.31 | H9: =VLOOKUP(E9,Caucho!$E$66:$N$141,8,FALSE) -> 0.32 | I9: =VLOOKUP(E9,Caucho!$E$66:$N$141,10,FALSE) -> 0.29870893 | K9: DIA | L9: {=_xll.PrecioBD(K9,24,"IMBALANCE","N")} -> -0.0059 | P9: S30A6 | Q9: {=INDIRECT("'" & P9 & "'!J6")} -> 0.027674298 | R9: {=INDIRECT("'" & P9& "'!B3")} -> 46142 | S9: {=_xll.PrecioBD(P9,24,"IMBALANCE","N")} -> 0.0033 | T9: {=INDIRECT("'" & Tabla11[[#This Row],[Ticker]]& "'!J5")} -> 0.33870213 | U9: =Tabla11[[#This Row],[Vencimiento]]-$D$1 -> 74 | V9: {=_xll.PrecioBD(Tabla11[[#This Row],[Ticker]],"24","BID","N")} -> 119.28 | W9: {=_xll.PrecioBD(Tabla11[[#This Row],[Ticker]],"24","ASK","N")} -> 119.298 | X9: {=_xll.PrecioBD(Tabla11[[#This Row],[Ticker]],24,"QUANTITY BID","N")} -> 5045581 | Y9: {=_xll.PrecioBD(Tabla11[[#This Row],[Ticker]],24,"QUANTITY ASK","N")} -> 50000000 | Z9: {=_xll.PrecioBD(Tabla11[[#This Row],[Ticker]],24,"VOLUME AMOUNT","N")} -> 7.636687e+08 | AA9: =Tabla11[[#This Row],[TNA]]/365*Tabla11[[#This Row],[Días a vencimiento]] -> 0.068668377 | AB9: =$I$15*(1+Tabla11[[#This Row],[TNA]]/365*Tabla11[[#This Row],[Días a vencimiento]]) -> 1537.3863 | AE9: AL30D | AF9: {=INDIRECT("'" & Tabla9[[#This Row],[Ticker]] & "'!K4")} -> 0.078818211 | AG9: {=INDIRECT("'" & Tabla9[[#This Row],[Ticker]] & "'!K3")} -> 2.1828813 | AH9: {=_xll.PrecioBD(Tabla9[[#This Row],[Ticker]],"24","BID","N")} -> 62.15 | AI9: {=_xll.PrecioBD(Tabla9[[#This Row],[Ticker]],"24","ASK","N")} -> 62.17 | AJ9: {=_xll.PrecioBD(Tabla9[[#This Row],[Ticker]],24,"QUANTITY BID","N")} -> 32567 | AK9: {=_xll.PrecioBD(Tabla9[[#This Row],[Ticker]],24,"QUANTITY ASK","N")} -> 181686 | AL9: {=_xll.PrecioBD(Tabla9[[#This Row],[Ticker]],24,"VOLUME AMOUNT","N")} -> 30904047 | AM9: {=_xll.PrecioBD(Tabla9[[#This Row],[Ticker]],24,"IMBALANCE","N")} -> 0.0014 | AP9: MGCRD | AQ9: {=INDIRECT("'" & AP9 & "'!K4")} -> 0.073805109 | AR9: {=INDIRECT("'" & AP9 & "'!K3")} -> 7.5792451 | AS9: 50360 | AT9: {=_xll.PrecioBD(AP9,"24","BID","N")} -> 105.8 | AU9: {=_xll.PrecioBD(AP9,"24","ASK","N")} -> 105.9 | AV9: {=_xll.PrecioBD(AP9,24,"QUANTITY BID","N")} -> 10000 | AW9: {=_xll.PrecioBD(AP9,24,"QUANTITY ASK","N")} -> 10000 | AX9: {=_xll.PrecioBD(AP9,24,"VOLUME AMOUNT","N")} -> 95320 | AY9: {=_xll.PrecioBD(AP9,24,"IMBALANCE","N")} -> 0 | AZ9: Semestral | BA9: 1 | BB9: Sinkable
A10: Panel General | D10: ARS | E10: 31 | F10: =VLOOKUP(E10,Caucho!$E$66:$N$141,3,FALSE) -> #N/A | G10: =VLOOKUP(E10,Caucho!$E$66:$N$141,7,FALSE) -> #N/A | H10: =VLOOKUP(E10,Caucho!$E$66:$N$141,8,FALSE) -> #N/A | I10: =VLOOKUP(E10,Caucho!$E$66:$N$141,10,FALSE) -> #N/A | K10: ILF | L10: {=_xll.PrecioBD(K10,24,"IMBALANCE","N")} -> -0.0054 | P10: S29Y6 | Q10: {=INDIRECT("'" & P10 & "'!J6")} -> 0.027605885 | R10: {=INDIRECT("'" & P10& "'!B3")} -> 46171 | S10: {=_xll.PrecioBD(P10,24,"IMBALANCE","N")} -> 0.0045 | T10: {=INDIRECT("'" & Tabla11[[#This Row],[Ticker]]& "'!J5")} -> 0.34232156 | U10: =Tabla11[[#This Row],[Vencimiento]]-$D$1 -> 103 | V10: {=_xll.PrecioBD(Tabla11[[#This Row],[Ticker]],"24","BID","N")} -> 120.534 | W10: {=_xll.PrecioBD(Tabla11[[#This Row],[Ticker]],"24","ASK","N")} -> 120.6 | X10: {=_xll.PrecioBD(Tabla11[[#This Row],[Ticker]],24,"QUANTITY BID","N")} -> 27325 | Y10: {=_xll.PrecioBD(Tabla11[[#This Row],[Ticker]],24,"QUANTITY ASK","N")} -> 2007190865 | Z10: {=_xll.PrecioBD(Tabla11[[#This Row],[Ticker]],24,"VOLUME AMOUNT","N")} -> 3.5023139e+09 | AA10: =Tabla11[[#This Row],[TNA]]/365*Tabla11[[#This Row],[Días a vencimiento]] -> 0.096600332 | AB10: =$I$15*(1+Tabla11[[#This Row],[TNA]]/365*Tabla11[[#This Row],[Días a vencimiento]]) -> 1577.5692 | AE10: GD35D | AF10: {=INDIRECT("'" & Tabla9[[#This Row],[Ticker]] & "'!K4")} -> 0.087667724 | AG10: {=INDIRECT("'" & Tabla9[[#This Row],[Ticker]] & "'!K3")} -> 5.6843481 | AH10: {=_xll.PrecioBD(Tabla9[[#This Row],[Ticker]],"24","BID","N")} -> 80.31 | AI10: {=_xll.PrecioBD(Tabla9[[#This Row],[Ticker]],"24","ASK","N")} -> 80.37 | AJ10: {=_xll.PrecioBD(Tabla9[[#This Row],[Ticker]],24,"QUANTITY BID","N")} -> 137 | AK10: {=_xll.PrecioBD(Tabla9[[#This Row],[Ticker]],24,"QUANTITY ASK","N")} -> 3508 | AL10: {=_xll.PrecioBD(Tabla9[[#This Row],[Ticker]],24,"VOLUME AMOUNT","N")} -> 830868.13 | AM10: {=_xll.PrecioBD(Tabla9[[#This Row],[Ticker]],24,"IMBALANCE","N")} -> 0.0002 | AP10: YM34D | AQ10: {=INDIRECT("'" & AP10 & "'!K4")} -> 0.072391567 | AR10: {=INDIRECT("'" & AP10 & "'!K3")} -> 5.2896143 | AS10: 48961 | AT10: {=_xll.PrecioBD(AP10,"24","BID","N")} -> 106.8 | AU10: {=_xll.PrecioBD(AP10,"24","ASK","N")} -> 106.85 | AV10: {=_xll.PrecioBD(AP10,24,"QUANTITY BID","N")} -> 259 | AW10: {=_xll.PrecioBD(AP10,24,"QUANTITY ASK","N")} -> 5249 | AX10: {=_xll.PrecioBD(AP10,24,"VOLUME AMOUNT","N")} -> 337639.59 | AY10: {=_xll.PrecioBD(AP10,24,"IMBALANCE","N")} -> 0.0009 | AZ10: Semestral | BA10: 100 | BB10: Sinkable
A11: Factor Alfa | K11: VEA | L11: {=_xll.PrecioBD(K11,24,"IMBALANCE","N")} -> -0.0068 | P11: T30J6 | Q11: {=INDIRECT("'" & P11 & "'!J6")} -> 0.02750658 | R11: {=INDIRECT("'" & P11& "'!B3")} -> 46203 | S11: {=_xll.PrecioBD(P11,24,"IMBALANCE","N")} -> 0.005 | T11: {=INDIRECT("'" & Tabla11[[#This Row],[Ticker]]& "'!J5")} -> 0.3460404 | U11: =Tabla11[[#This Row],[Vencimiento]]-$D$1 -> 135 | V11: {=_xll.PrecioBD(Tabla11[[#This Row],[Ticker]],"24","BID","N")} -> 128.4 | W11: {=_xll.PrecioBD(Tabla11[[#This Row],[Ticker]],"24","ASK","N")} -> 128.45 | X11: {=_xll.PrecioBD(Tabla11[[#This Row],[Ticker]],24,"QUANTITY BID","N")} -> 476694981 | Y11: {=_xll.PrecioBD(Tabla11[[#This Row],[Ticker]],24,"QUANTITY ASK","N")} -> 8857601 | Z11: {=_xll.PrecioBD(Tabla11[[#This Row],[Ticker]],24,"VOLUME AMOUNT","N")} -> 4.0167256e+09 | AA11: =Tabla11[[#This Row],[TNA]]/365*Tabla11[[#This Row],[Días a vencimiento]] -> 0.12798754 | AB11: =$I$15*(1+Tabla11[[#This Row],[TNA]]/365*Tabla11[[#This Row],[Días a vencimiento]]) -> 1622.7229 | AE11: GD38D | AF11: {=INDIRECT("'" & Tabla9[[#This Row],[Ticker]] & "'!K4")} -> 0.086429152 | AG11: {=INDIRECT("'" & Tabla9[[#This Row],[Ticker]] & "'!K3")} -> 4.9862373 | AH11: {=_xll.PrecioBD(Tabla9[[#This Row],[Ticker]],"24","BID","N")} -> 83.81 | AI11: {=_xll.PrecioBD(Tabla9[[#This Row],[Ticker]],"24","ASK","N")} -> 83.95 | AJ11: {=_xll.PrecioBD(Tabla9[[#This Row],[Ticker]],24,"QUANTITY BID","N")} -> 186 | AK11: {=_xll.PrecioBD(Tabla9[[#This Row],[Ticker]],24,"QUANTITY ASK","N")} -> 1924 | AL11: {=_xll.PrecioBD(Tabla9[[#This Row],[Ticker]],24,"VOLUME AMOUNT","N")} -> 60922.11 | AM11: {=_xll.PrecioBD(Tabla9[[#This Row],[Ticker]],24,"IMBALANCE","N")} -> -0.0001 | AP11: TSC4D | AQ11: {=INDIRECT("'" & AP11 & "'!K4")} -> 0.072250578 | AR11: {=INDIRECT("'" & AP11 & "'!K3")} -> 2.0743719 | AS11: 49633 | AT11: {=_xll.PrecioBD(AP11,"24","BID","N")} -> 106.3 | AU11: {=_xll.PrecioBD(AP11,"24","ASK","N")} -> 106.4 | AV11: {=_xll.PrecioBD(AP11,24,"QUANTITY BID","N")} -> 9000 | AW11: {=_xll.PrecioBD(AP11,24,"QUANTITY ASK","N")} -> 11000 | AX11: {=_xll.PrecioBD(AP11,24,"VOLUME AMOUNT","N")} -> 73414 | AY11: {=_xll.PrecioBD(AP11,24,"IMBALANCE","N")} -> -0.0028 | AZ11: Semestral | BA11: 100 | BB11: Sinkable
C12: {=_xll.TiposCambioBD()} -> TIPO CAMBIO | D12: VENCIMIENTO | E12: ESPECIE | F12: SIMBOLO | G12: COMPRA | H12: VENTA | I12: ULTIMO | K12: Factor Alfa | L12: =Tabla68[[#Totals],[Columna2]] -> -0.007959 | P12: S31L6 | Q12: {=INDIRECT("'" & P12 & "'!J6")} -> 0.027560332 | R12: {=INDIRECT("'" & P12& "'!B3")} -> 46234 | S12: {=_xll.PrecioBD(P12,24,"IMBALANCE","N")} -> 0.0044 | T12: {=INDIRECT("'" & Tabla11[[#This Row],[Ticker]]& "'!J5")} -> 0.35169518 | U12: =Tabla11[[#This Row],[Vencimiento]]-$D$1 -> 166 | V12: {=_xll.PrecioBD(Tabla11[[#This Row],[Ticker]],"24","BID","N")} -> 101.449 | W12: {=_xll.PrecioBD(Tabla11[[#This Row],[Ticker]],"24","ASK","N")} -> 101.45 | X12: {=_xll.PrecioBD(Tabla11[[#This Row],[Ticker]],24,"QUANTITY BID","N")} -> 2107027 | Y12: {=_xll.PrecioBD(Tabla11[[#This Row],[Ticker]],24,"QUANTITY ASK","N")} -> 79925697 | Z12: {=_xll.PrecioBD(Tabla11[[#This Row],[Ticker]],24,"VOLUME AMOUNT","N")} -> 5.3673613e+09 | AA12: =Tabla11[[#This Row],[TNA]]/365*Tabla11[[#This Row],[Días a vencimiento]] -> 0.15994904 | AB12: =$I$15*(1+Tabla11[[#This Row],[TNA]]/365*Tabla11[[#This Row],[Días a vencimiento]]) -> 1668.7027 | AE12: AL29D | AF12: {=INDIRECT("'" & Tabla9[[#This Row],[Ticker]] & "'!K4")} -> 0.069797418 | AG12: {=INDIRECT("'" & Tabla9[[#This Row],[Ticker]] & "'!K3")} -> 1.763296 | AH12: {=_xll.PrecioBD(Tabla9[[#This Row],[Ticker]],"24","BID","N")} -> 62.95 | AI12: {=_xll.PrecioBD(Tabla9[[#This Row],[Ticker]],"24","ASK","N")} -> 62.99 | AJ12: {=_xll.PrecioBD(Tabla9[[#This Row],[Ticker]],24,"QUANTITY BID","N")} -> 3186 | AK12: {=_xll.PrecioBD(Tabla9[[#This Row],[Ticker]],24,"QUANTITY ASK","N")} -> 23053 | AL12: {=_xll.PrecioBD(Tabla9[[#This Row],[Ticker]],24,"VOLUME AMOUNT","N")} -> 326258.52 | AM12: {=_xll.PrecioBD(Tabla9[[#This Row],[Ticker]],24,"IMBALANCE","N")} -> 0.0035 | AP12: IRCPD | AQ12: {=INDIRECT("'" & AP12 & "'!K4")} -> 0.072679135 | AR12: {=INDIRECT("'" & AP12 & "'!K3")} -> 5.8033839 | AS12: 49399 | AT12: {=_xll.PrecioBD(AP12,"24","BID","N")} -> 108.05 | AU12: {=_xll.PrecioBD(AP12,"24","ASK","N")} -> 108.2 | AV12: {=_xll.PrecioBD(AP12,24,"QUANTITY BID","N")} -> 4865 | AW12: {=_xll.PrecioBD(AP12,24,"QUANTITY ASK","N")} -> 3931 | AX12: {=_xll.PrecioBD(AP12,24,"VOLUME AMOUNT","N")} -> 88043.04 | AY12: {=_xll.PrecioBD(AP12,24,"IMBALANCE","N")} -> -0.0009 | AZ12: Semestral | BA12: 10000 | BB12: Bullet
K13: IEMG | L13: {=_xll.PrecioBD(K13,24,"IMBALANCE","N")} -> -0.0075 | P13: S31G6 | Q13: {=INDIRECT("'" & P13 & "'!J6")} -> 0.02832805 | R13: {=INDIRECT("'" & P13& "'!B3")} -> 46265 | S13: {=_xll.PrecioBD(P13,24,"IMBALANCE","N")} -> 0 | T13: {=INDIRECT("'" & Tabla11[[#This Row],[Ticker]]& "'!J5")} -> 0.36744879 | U13: =Tabla11[[#This Row],[Vencimiento]]-$D$1 -> 197 | V13: {=_xll.PrecioBD(Tabla11[[#This Row],[Ticker]],"24","BID","N")} -> 107.056 | W13: {=_xll.PrecioBD(Tabla11[[#This Row],[Ticker]],"24","ASK","N")} -> 107.25 | X13: {=_xll.PrecioBD(Tabla11[[#This Row],[Ticker]],24,"QUANTITY BID","N")} -> 3569286 | Y13: {=_xll.PrecioBD(Tabla11[[#This Row],[Ticker]],24,"QUANTITY ASK","N")} -> 4610951 | Z13: {=_xll.PrecioBD(Tabla11[[#This Row],[Ticker]],24,"VOLUME AMOUNT","N")} -> 43791501 | AA13: =Tabla11[[#This Row],[TNA]]/365*Tabla11[[#This Row],[Días a vencimiento]] -> 0.19832168 | AB13: =$I$15*(1+Tabla11[[#This Row],[TNA]]/365*Tabla11[[#This Row],[Días a vencimiento]]) -> 1723.9055 | AE13: GD30D | AF13: {=INDIRECT("'" & Tabla9[[#This Row],[Ticker]] & "'!K4")} -> 0.067136118 | AG13: {=INDIRECT("'" & Tabla9[[#This Row],[Ticker]] & "'!K3")} -> 2.2121439 | AH13: {=_xll.PrecioBD(Tabla9[[#This Row],[Ticker]],"24","BID","N")} -> 63.69 | AI13: {=_xll.PrecioBD(Tabla9[[#This Row],[Ticker]],"24","ASK","N")} -> 63.73 | AJ13: {=_xll.PrecioBD(Tabla9[[#This Row],[Ticker]],24,"QUANTITY BID","N")} -> 7690 | AK13: {=_xll.PrecioBD(Tabla9[[#This Row],[Ticker]],24,"QUANTITY ASK","N")} -> 20079 | AL13: {=_xll.PrecioBD(Tabla9[[#This Row],[Ticker]],24,"VOLUME AMOUNT","N")} -> 440541.78 | AM13: {=_xll.PrecioBD(Tabla9[[#This Row],[Ticker]],24,"IMBALANCE","N")} -> 0.0028 | AP13: MGCOD | AQ13: {=INDIRECT("'" & AP13 & "'!K4")} -> 0.071567294 | AR13: {=INDIRECT("'" & AP13 & "'!K3")} -> 6.3016378 | AS13: 49294 | AT13: {=_xll.PrecioBD(AP13,"24","BID","N")} -> 106.25 | AU13: {=_xll.PrecioBD(AP13,"24","ASK","N")} -> 106.75 | AV13: {=_xll.PrecioBD(AP13,24,"QUANTITY BID","N")} -> 10000 | AW13: {=_xll.PrecioBD(AP13,24,"QUANTITY ASK","N")} -> 10000 | AX13: {=_xll.PrecioBD(AP13,24,"VOLUME AMOUNT","N")} -> 510315 | AY13: {=_xll.PrecioBD(AP13,24,"IMBALANCE","N")} -> -0.0004 | AZ13: Semestral | BA13: 1000 | BB13: Bullet
D14: 2026-02-09 | E14: GD30/GD30C | F14: GD30/GD30C (CI) | G14: 1477.9 | H14: 1480 | I14: 1478.8 | K14: XLE | L14: {=_xll.PrecioBD(K14,24,"IMBALANCE","N")} -> -0.0078 | P14: S30O6 | Q14: {=INDIRECT("'" & P14 & "'!J6")} -> 0.026089853 | R14: {=INDIRECT("'" & P14& "'!B3")} -> 46325 | S14: {=_xll.PrecioBD(P14,24,"IMBALANCE","N")} -> 0.0048 | T14: {=INDIRECT("'" & Tabla11[[#This Row],[Ticker]]& "'!J5")} -> 0.34527031 | U14: =Tabla11[[#This Row],[Vencimiento]]-$D$1 -> 257 | V14: {=_xll.PrecioBD(Tabla11[[#This Row],[Ticker]],"24","BID","N")} -> 108.558 | W14: {=_xll.PrecioBD(Tabla11[[#This Row],[Ticker]],"24","ASK","N")} -> 108.824 | X14: {=_xll.PrecioBD(Tabla11[[#This Row],[Ticker]],24,"QUANTITY BID","N")} -> 324899 | Y14: {=_xll.PrecioBD(Tabla11[[#This Row],[Ticker]],24,"QUANTITY ASK","N")} -> 5000000 | Z14: {=_xll.PrecioBD(Tabla11[[#This Row],[Ticker]],24,"VOLUME AMOUNT","N")} -> 24525398 | AA14: =Tabla11[[#This Row],[TNA]]/365*Tabla11[[#This Row],[Días a vencimiento]] -> 0.24310814 | AB14: =$I$15*(1+Tabla11[[#This Row],[TNA]]/365*Tabla11[[#This Row],[Días a vencimiento]]) -> 1788.3353 | AE14: GD29D | AF14: {=INDIRECT("'" & Tabla9[[#This Row],[Ticker]] & "'!K4")} -> 0.05488334 | AG14: {=INDIRECT("'" & Tabla9[[#This Row],[Ticker]] & "'!K3")} -> 1.7893463 | AH14: {=_xll.PrecioBD(Tabla9[[#This Row],[Ticker]],"24","BID","N")} -> 64.51 | AI14: {=_xll.PrecioBD(Tabla9[[#This Row],[Ticker]],"24","ASK","N")} -> 64.63 | AJ14: {=_xll.PrecioBD(Tabla9[[#This Row],[Ticker]],24,"QUANTITY BID","N")} -> 468 | AK14: {=_xll.PrecioBD(Tabla9[[#This Row],[Ticker]],24,"QUANTITY ASK","N")} -> 3934 | AL14: {=_xll.PrecioBD(Tabla9[[#This Row],[Ticker]],24,"VOLUME AMOUNT","N")} -> 36642.35 | AM14: {=_xll.PrecioBD(Tabla9[[#This Row],[Ticker]],24,"IMBALANCE","N")} -> 0.0068 | AP14: VSCVD | AQ14: {=INDIRECT("'" & AP14 & "'!K4")} -> 0.071171436 | AR14: {=INDIRECT("'" & AP14 & "'!K3")} -> 4.8284439 | AS14: 48740 | AT14: {=_xll.PrecioBD(AP14,"24","BID","N")} -> 108.85 | AU14: {=_xll.PrecioBD(AP14,"24","ASK","N")} -> 109.1 | AV14: {=_xll.PrecioBD(AP14,24,"QUANTITY BID","N")} -> 2000 | AW14: {=_xll.PrecioBD(AP14,24,"QUANTITY ASK","N")} -> 31000 | AX14: {=_xll.PrecioBD(AP14,24,"VOLUME AMOUNT","N")} -> 311679 | AY14: {=_xll.PrecioBD(AP14,24,"IMBALANCE","N")} -> 0.0022 | AZ14: Semestral | BA14: 1000 | BB14: Bullet
D15: 2026-02-09 | E15: GD30/GD30D | F15: GD30/GD30D (CI) | G15: 1437.2 | H15: 1440 | I15: 1438.6 | K15: MEP | L15: =$D$20 -> -0.009377494 | P15: S30N6 | Q15: {=INDIRECT("'" & P15 & "'!J6")} -> 0.026730211 | R15: {=INDIRECT("'" & P15& "'!B3")} -> 46356 | S15: {=_xll.PrecioBD(P15,24,"IMBALANCE","N")} -> 0.0028 | T15: {=INDIRECT("'" & Tabla11[[#This Row],[Ticker]]& "'!J5")} -> 0.3595906 | U15: =Tabla11[[#This Row],[Vencimiento]]-$D$1 -> 288 | V15: {=_xll.PrecioBD(Tabla11[[#This Row],[Ticker]],"24","BID","N")} -> 101.27 | W15: {=_xll.PrecioBD(Tabla11[[#This Row],[Ticker]],"24","ASK","N")} -> 101.314 | X15: {=_xll.PrecioBD(Tabla11[[#This Row],[Ticker]],24,"QUANTITY BID","N")} -> 5000000 | Y15: {=_xll.PrecioBD(Tabla11[[#This Row],[Ticker]],24,"QUANTITY ASK","N")} -> 5000000 | Z15: {=_xll.PrecioBD(Tabla11[[#This Row],[Ticker]],24,"VOLUME AMOUNT","N")} -> 3.5053028e+08 | AA15: =Tabla11[[#This Row],[TNA]]/365*Tabla11[[#This Row],[Días a vencimiento]] -> 0.28373176 | AB15: =$I$15*(1+Tabla11[[#This Row],[TNA]]/365*Tabla11[[#This Row],[Días a vencimiento]]) -> 1846.7765 | AP15: PLC5D | AQ15: {=INDIRECT("'" & AP15 & "'!K4")} -> 0.069972578 | AR15: {=INDIRECT("'" & AP15 & "'!K3")} -> 4.186849 | AS15: 47987 | AT15: {=_xll.PrecioBD(AP15,"24","BID","N")} -> 107.25 | AU15: {=_xll.PrecioBD(AP15,"24","ASK","N")} -> 107.35 | AV15: {=_xll.PrecioBD(AP15,24,"QUANTITY BID","N")} -> 20000 | AW15: {=_xll.PrecioBD(AP15,24,"QUANTITY ASK","N")} -> 20000 | AX15: {=_xll.PrecioBD(AP15,24,"VOLUME AMOUNT","N")} -> 121221 | AY15: {=_xll.PrecioBD(AP15,24,"IMBALANCE","N")} -> 0.0004 | AZ15: Semestral | BA15: 1 | BB15: Sinkable
D16: 2026-02-09 | E16: MAE | F16: Dolar Mayorista Bancos - Argentina | G16: 1423 | H16: 1432 | I16: 1432 | K16: SPY | L16: {=_xll.PrecioBD(K16,24,"IMBALANCE","N")} -> -0.0107 | P16: T15E7 | Q16: {=INDIRECT("'" & P16 & "'!J6")} -> 0.027068654 | R16: {=INDIRECT("'" & P16& "'!B3")} -> 46402 | S16: {=_xll.PrecioBD(P16,24,"IMBALANCE","N")} -> 0.002 | T16: {=INDIRECT("'" & Tabla11[[#This Row],[Ticker]]& "'!J5")} -> 0.37245733 | U16: =Tabla11[[#This Row],[Vencimiento]]-$D$1 -> 334 | V16: {=_xll.PrecioBD(Tabla11[[#This Row],[Ticker]],"24","BID","N")} -> 120.1 | W16: {=_xll.PrecioBD(Tabla11[[#This Row],[Ticker]],"24","ASK","N")} -> 120.15 | X16: {=_xll.PrecioBD(Tabla11[[#This Row],[Ticker]],24,"QUANTITY BID","N")} -> 50769775 | Y16: {=_xll.PrecioBD(Tabla11[[#This Row],[Ticker]],24,"QUANTITY ASK","N")} -> 15000000 | Z16: {=_xll.PrecioBD(Tabla11[[#This Row],[Ticker]],24,"VOLUME AMOUNT","N")} -> 6.8889e+09 | AA16: =Tabla11[[#This Row],[TNA]]/365*Tabla11[[#This Row],[Días a vencimiento]] -> 0.34082397 | AB16: =$I$15*(1+Tabla11[[#This Row],[TNA]]/365*Tabla11[[#This Row],[Días a vencimiento]]) -> 1928.9093 | AE16: Spread | AF16: Delta | AP16: PLC4D | AQ16: {=INDIRECT("'" & AP16 & "'!K4")} -> 0.073068348 | AR16: {=INDIRECT("'" & AP16 & "'!K3")} -> 4.7958835 | AS16: 48364 | AT16: {=_xll.PrecioBD(AP16,"24","BID","N")} -> 108.1 | AU16: {=_xll.PrecioBD(AP16,"24","ASK","N")} -> 108.35 | AV16: {=_xll.PrecioBD(AP16,24,"QUANTITY BID","N")} -> 4000 | AW16: {=_xll.PrecioBD(AP16,24,"QUANTITY ASK","N")} -> 48000 | AX16: {=_xll.PrecioBD(AP16,24,"VOLUME AMOUNT","N")} -> 121382.5 | AY16: {=_xll.PrecioBD(AP16,24,"IMBALANCE","N")} -> 0 | AZ16: Semestral | BA16: 0 | BB16: 0
D17: 2026-02-09 | E17: USB | F17: Dolar Banco Nacion Billete - Argentina | G17: 1395 | H17: 1445 | I17: 1445 | K17: IBIT | L17: {=_xll.PrecioBD(K17,24,"IMBALANCE","N")} -> -0.0114 | P17: T30A7 | Q17: {=INDIRECT("'" & P17 & "'!J6")} -> 0.027111167 | R17: {=INDIRECT("'" & P17& "'!B3")} -> 46507 | S17: {=_xll.PrecioBD(P17,24,"IMBALANCE","N")} -> 0 | T17: {=INDIRECT("'" & Tabla11[[#This Row],[Ticker]]& "'!J5")} -> 0.39177649 | U17: =Tabla11[[#This Row],[Vencimiento]]-$D$1 -> 439 | V17: {=_xll.PrecioBD(Tabla11[[#This Row],[Ticker]],"24","BID","N")} -> 108.65 | W17: {=_xll.PrecioBD(Tabla11[[#This Row],[Ticker]],"24","ASK","N")} -> 108.7 | X17: {=_xll.PrecioBD(Tabla11[[#This Row],[Ticker]],24,"QUANTITY BID","N")} -> 142099074 | Y17: {=_xll.PrecioBD(Tabla11[[#This Row],[Ticker]],24,"QUANTITY ASK","N")} -> 141132 | Z17: {=_xll.PrecioBD(Tabla11[[#This Row],[Ticker]],24,"VOLUME AMOUNT","N")} -> 9.7208279e+08 | AA17: =Tabla11[[#This Row],[TNA]]/365*Tabla11[[#This Row],[Días a vencimiento]] -> 0.47120515 | AB17: =$I$15*(1+Tabla11[[#This Row],[TNA]]/365*Tabla11[[#This Row],[Días a vencimiento]]) -> 2116.4757 | AE17: AL29/GD29 | AF17: {=_xll.PrecioBD("GD29D",24,"ASK","N")/_xll.PrecioBD("AL29D",24,"ASK","N")-1} -> 0.026035879 | AP17: VSCTD | AQ17: {=INDIRECT("'" & AP17 & "'!K4")} -> 0.070167872 | AR17: {=INDIRECT("'" & AP17 & "'!K3")} -> 6.3325003 | AS17: 49653 | AT17: {=_xll.PrecioBD(AP17,"24","BID","N")} -> 106 | AU17: {=_xll.PrecioBD(AP17,"24","ASK","N")} -> 106.05 | AV17: {=_xll.PrecioBD(AP17,24,"QUANTITY BID","N")} -> 30000 | AW17: {=_xll.PrecioBD(AP17,24,"QUANTITY ASK","N")} -> 75000 | AX17: {=_xll.PrecioBD(AP17,24,"VOLUME AMOUNT","N")} -> 31830 | AY17: {=_xll.PrecioBD(AP17,24,"IMBALANCE","N")} -> -0.0004 | AZ17: Semestral | BA17: 10000 | BB17: Bullet
D18: 2026-02-09 | E18: USD | F18: Dolar x Peso Argentino BNA | G18: 1423 | H18: 1432 | I18: 1432 | K18: URA | L18: {=_xll.PrecioBD(K18,24,"IMBALANCE","N")} -> -0.0145 | P18: T31Y7 | Q18: {=INDIRECT("'" & P18 & "'!J6")} -> 0.025395019 | R18: {=INDIRECT("'" & P18& "'!B3")} -> 46538 | S18: {=_xll.PrecioBD(P18,24,"IMBALANCE","N")} -> 0.0024 | T18: {=INDIRECT("'" & Tabla11[[#This Row],[Ticker]]& "'!J5")} -> 0.36756352 | U18: =Tabla11[[#This Row],[Vencimiento]]-$D$1 -> 470 | V18: {=_xll.PrecioBD(Tabla11[[#This Row],[Ticker]],"24","BID","N")} -> 102.95 | W18: {=_xll.PrecioBD(Tabla11[[#This Row],[Ticker]],"24","ASK","N")} -> 103 | X18: {=_xll.PrecioBD(Tabla11[[#This Row],[Ticker]],24,"QUANTITY BID","N")} -> 401063 | Y18: {=_xll.PrecioBD(Tabla11[[#This Row],[Ticker]],24,"QUANTITY ASK","N")} -> 610108 | Z18: {=_xll.PrecioBD(Tabla11[[#This Row],[Ticker]],24,"VOLUME AMOUNT","N")} -> 2.4139405e+08 | AA18: =Tabla11[[#This Row],[TNA]]/365*Tabla11[[#This Row],[Días a vencimiento]] -> 0.47330097 | AB18: =$I$15*(1+Tabla11[[#This Row],[TNA]]/365*Tabla11[[#This Row],[Días a vencimiento]]) -> 2119.4907 | AE18: AL30/GD30 | AF18: {=_xll.PrecioBD("GD30D",24,"ASK","N")/_xll.PrecioBD("AL30D",24,"ASK","N")-1} -> 0.025092488 | AP18: YMCXD | AQ18: {=INDIRECT("'" & AP18 & "'!K4")} -> 0.070133516 | AR18: {=INDIRECT("'" & AP18 & "'!K3")} -> 3.8873354 | AS18: 48102 | AT18: {=_xll.PrecioBD(AP18,"24","BID","N")} -> 111.35 | AU18: {=_xll.PrecioBD(AP18,"24","ASK","N")} -> 111.45 | AV18: {=_xll.PrecioBD(AP18,24,"QUANTITY BID","N")} -> 1048 | AW18: {=_xll.PrecioBD(AP18,24,"QUANTITY ASK","N")} -> 11028 | AX18: {=_xll.PrecioBD(AP18,24,"VOLUME AMOUNT","N")} -> 278428.4 | AY18: {=_xll.PrecioBD(AP18,24,"IMBALANCE","N")} -> -0.0022 | AZ18: Semestral | BA18: 1 | BB18: Sinkable
D19: MEP | E19: CCL | F19: MEP/Oficial | K19: GLD | L19: {=_xll.PrecioBD(K19,24,"IMBALANCE","N")} -> -0.0115 | P19: T30J7 | Q19: {=INDIRECT("'" & P19 & "'!J6")} -> 0.020262212 | R19: {=INDIRECT("'" & P19& "'!B3")} -> 46568 | S19: {=_xll.PrecioBD(P19,24,"IMBALANCE","N")} -> 0.0009 | T19: {=INDIRECT("'" & Tabla11[[#This Row],[Ticker]]& "'!J5")} -> 0.28515079 | U19: =Tabla11[[#This Row],[Vencimiento]]-$D$1 -> 500 | V19: {=_xll.PrecioBD(Tabla11[[#This Row],[Ticker]],"24","BID","N")} -> 103.4 | W19: {=_xll.PrecioBD(Tabla11[[#This Row],[Ticker]],"24","ASK","N")} -> 104.45 | X19: {=_xll.PrecioBD(Tabla11[[#This Row],[Ticker]],24,"QUANTITY BID","N")} -> 84662 | Y19: {=_xll.PrecioBD(Tabla11[[#This Row],[Ticker]],24,"QUANTITY ASK","N")} -> 948843 | Z19: {=_xll.PrecioBD(Tabla11[[#This Row],[Ticker]],24,"VOLUME AMOUNT","N")} -> 2.6572571e+08 | AA19: =Tabla11[[#This Row],[TNA]]/365*Tabla11[[#This Row],[Días a vencimiento]] -> 0.39061752 | AB19: =$I$15*(1+Tabla11[[#This Row],[TNA]]/365*Tabla11[[#This Row],[Días a vencimiento]]) -> 2000.5423 | AE19: AL35/GD35 | AF19: {=_xll.PrecioBD("GD35D",24,"ASK","N")/_xll.PrecioBD("AL35D",24,"ASK","N")-1} -> 0.01953571 | AP19: YFCJD | AQ19: {=INDIRECT("'" & AP19 & "'!K4")} -> 0.069892356 | AR19: {=INDIRECT("'" & AP19 & "'!K3")} -> 4.4359847 | AS19: 48503 | AT19: {=_xll.PrecioBD(AP19,"24","BID","N")} -> 106.9 | AU19: {=_xll.PrecioBD(AP19,"24","ASK","N")} -> 107.25 | AV19: {=_xll.PrecioBD(AP19,24,"QUANTITY BID","N")} -> 1000 | AW19: {=_xll.PrecioBD(AP19,24,"QUANTITY ASK","N")} -> 5000 | AX19: {=_xll.PrecioBD(AP19,24,"VOLUME AMOUNT","N")} -> 14959.5 | AY19: {=_xll.PrecioBD(AP19,24,"IMBALANCE","N")} -> 0 | AZ19: Semestral | BA19: 1000 | BB19: Sinkable
D20: {=(1+_xll.PrecioBD("AL30","CI","IMBALANCE","N"))/(1+_xll.PrecioBD("AL30D","CI","IMBALANCE","N"))-1} -> -0.009377494 | E20: {=(1+_xll.PrecioBD("AL30","CI","IMBALANCE","N"))/(1+_xll.PrecioBD("AL30C","CI","IMBALANCE","N"))-1} -> -0.0073970412 | F20: =I15/I18-1 -> 0.0046089215 | K20: IWM | L20: {=_xll.PrecioBD(K20,24,"IMBALANCE","N")} -> -0.0153 | AE20: AE38/GD38 | AF20: {=_xll.PrecioBD("GD38D",24,"ASK","N")/_xll.PrecioBD("AE38D",24,"ASK","N")-1} -> 0.030314188 | AP20: GN49D | AQ20: {=INDIRECT("'" & AP20 & "'!K4")} -> 0.070659539 | AR20: {=INDIRECT("'" & AP20 & "'!K3")} -> 5.1788799 | AS20: 48915 | AT20: {=_xll.PrecioBD(AP20,"24","BID","N")} -> 104.9 | AU20: {=_xll.PrecioBD(AP20,"24","ASK","N")} -> 105.9 | AV20: {=_xll.PrecioBD(AP20,24,"QUANTITY BID","N")} -> 1000 | AW20: {=_xll.PrecioBD(AP20,24,"QUANTITY ASK","N")} -> 15000 | AX20: {=_xll.PrecioBD(AP20,24,"VOLUME AMOUNT","N")} -> 37930.5 | AY20: {=_xll.PrecioBD(AP20,24,"IMBALANCE","N")} -> 0.0057 | AZ20: Semestral | BA20: 1000 | BB20: Bullet
K21: COPX | L21: {=_xll.PrecioBD(K21,24,"IMBALANCE","N")} -> -0.0151 | P21: MEP | Q21: =W1 -> 1438.6 | AE21: AL41/GD41 | AF21: {=_xll.PrecioBD("GD41D",24,"ASK","N")/_xll.PrecioBD("AL41D",24,"ASK","N")-1} -> 0.013486177 | AP21: TLCMD | AQ21: {=INDIRECT("'" & AP21 & "'!K4")} -> 0.068281874 | AR21: {=INDIRECT("'" & AP21 & "'!K3")} -> 3.6058106 | AS21: 48047 | AT21: {=_xll.PrecioBD(AP21,"24","BID","N")} -> 111.05 | AU21: {=_xll.PrecioBD(AP21,"24","ASK","N")} -> 111.2 | AV21: {=_xll.PrecioBD(AP21,24,"QUANTITY BID","N")} -> 7000 | AW21: {=_xll.PrecioBD(AP21,24,"QUANTITY ASK","N")} -> 12000 | AX21: {=_xll.PrecioBD(AP21,24,"VOLUME AMOUNT","N")} -> 194210 | AY21: {=_xll.PrecioBD(AP21,24,"IMBALANCE","N")} -> -0.0035 | AZ21: Semestral | BA21: 1000 | BB21: Sinkable
D22: Plazo fijo | E22: Caucho - PF | F22: Lecap - PF | K22: Merval | L22: ='Indices BYMA'!H5 -> -0.0226 | Q22: Rendimiento en USD para los diferentes MEP | AP22: YMCJD | AQ22: {=INDIRECT("'" & AP22 & "'!K4")} -> 0.066920939 | AR22: {=INDIRECT("'" & AP22 & "'!K3")} -> 4.9308554 | AS22: 48852 | AT22: {=_xll.PrecioBD(AP22,"24","BID","N")} -> 104.6 | AU22: {=_xll.PrecioBD(AP22,"24","ASK","N")} -> 104.75 | AV22: {=_xll.PrecioBD(AP22,24,"QUANTITY BID","N")} -> 1083 | AW22: {=_xll.PrecioBD(AP22,24,"QUANTITY ASK","N")} -> 986 | AX22: {=_xll.PrecioBD(AP22,24,"VOLUME AMOUNT","N")} -> 198024.03 | AY22: {=_xll.PrecioBD(AP22,24,"IMBALANCE","N")} -> 0.0028 | AZ22: Semestral | BA22: 10000 | BB22: Bullet
D23: 0.25 | E23: =G8-D23 -> 0.048 | F23: =AVERAGE(T6:T19)-D23 -> 0.10393616 | K23: USO | L23: {=_xll.PrecioBD(K23,24,"IMBALANCE","N")} -> -0.0226 | Q23: Ticker | R23: 1450 | S23: 1500 | T23: 1550 | U23: 1600 | V23: 1650 | W23: 1700 | X23: 1750 | Y23: 1800 | Z23: 1850 | AP23: TTCDD | AQ23: {=INDIRECT("'" & AP23 & "'!K4")} -> 0.06647186 | AR23: {=INDIRECT("'" & AP23 & "'!K3")} -> 3.86195 | AS23: 47791 | AT23: {=_xll.PrecioBD(AP23,"24","BID","N")} -> 106.3 | AU23: {=_xll.PrecioBD(AP23,"24","ASK","N")} -> 106.45 | AV23: {=_xll.PrecioBD(AP23,24,"QUANTITY BID","N")} -> 33000 | AW23: {=_xll.PrecioBD(AP23,24,"QUANTITY ASK","N")} -> 1000 | AX23: {=_xll.PrecioBD(AP23,24,"VOLUME AMOUNT","N")} -> 117155.5 | AY23: {=_xll.PrecioBD(AP23,24,"IMBALANCE","N")} -> -0.0004 | AZ23: Semestral | BA23: 1 | BB23: Sinkable
D24: https://www.bcra.gob.ar/plazos-fijos-online/ | K24: SLV | L24: {=_xll.PrecioBD(K24,24,"IMBALANCE","N")} -> -0.0281 | AP24: TSC3D | AQ24: {=INDIRECT("'" & AP24 & "'!K4")} -> 0.065198669 | AR24: {=INDIRECT("'" & AP24 & "'!K3")} -> 4.3559699 | AS24: 48053 | AT24: {=_xll.PrecioBD(AP24,"24","BID","N")} -> 109.4 | AU24: {=_xll.PrecioBD(AP24,"24","ASK","N")} -> 109.95 | AV24: {=_xll.PrecioBD(AP24,24,"QUANTITY BID","N")} -> 10000 | AW24: {=_xll.PrecioBD(AP24,24,"QUANTITY ASK","N")} -> 10000 | AX24: {=_xll.PrecioBD(AP24,24,"VOLUME AMOUNT","N")} -> 10920 | AY24: {=_xll.PrecioBD(AP24,24,"IMBALANCE","N")} -> -0.0022 | AZ24: Semestral | BA24: 1000 | BB24: Bullet
Q25: S27F6 | R25: =AB6/$R$23-1 -> 0.0042683005 | S25: =AB6/$S$23-1 -> -0.029207309 | T25: =AB6/$T$23-1 -> -0.060523203 | U25: =AB6/$U$23-1 -> -0.089881853 | V25: =AB6/$V$23-1 -> -0.11746119 | W25: =AB6/$W$23-1 -> -0.14341821 | X25: =AB6/$X$23-1 -> -0.16789198 | Y25: =AB6/$Y$23-1 -> -0.19100609 | Z25: =AB6/$Z$23-1 -> -0.21287079 | AP25: MGCMD | AQ25: {=INDIRECT("'" & AP25 & "'!K4")} -> 0.064246032 | AR25: {=INDIRECT("'" & AP25 & "'!K3")} -> 4.365162 | AS25: 48101 | AT25: {=_xll.PrecioBD(AP25,"24","BID","N")} -> 110.6 | AU25: {=_xll.PrecioBD(AP25,"24","ASK","N")} -> 111 | AV25: {=_xll.PrecioBD(AP25,24,"QUANTITY BID","N")} -> 10000 | AW25: {=_xll.PrecioBD(AP25,24,"QUANTITY ASK","N")} -> 10000 | AX25: {=_xll.PrecioBD(AP25,24,"VOLUME AMOUNT","N")} -> 0 | AY25: {=_xll.PrecioBD(AP25,24,"IMBALANCE","N")} -> 0 | AZ25: Semestral | BA25: 1000 | BB25: Sinkable
C26: CEDEARs | D26: Ticker | E26: Precio | F26: Total volume | G26: Variación | I26: Panel Lider | J26: Ticker | K26: Precio | L26: Total volume | M26: Variación | Q26: S16M6 | R26: =AB7/$R$23-1 -> 0.020233048 | S26: =AB7/$S$23-1 -> -0.01377472 | T26: =AB7/$T$23-1 -> -0.045588439 | U26: =AB7/$U$23-1 -> -0.0754138 | V26: =AB7/$V$23-1 -> -0.10343156 | W26: =AB7/$W$23-1 -> -0.12980122 | X26: =AB7/$X$23-1 -> -0.15466405 | Y26: =AB7/$Y$23-1 -> -0.1781456 | Z26: =AB7/$Z$23-1 -> -0.20035788 | AP26: TTCAD | AQ26: {=INDIRECT("'" & AP26 & "'!K4")} -> 0.063613895 | AR26: {=INDIRECT("'" & AP26 & "'!K3")} -> 4.7503804 | AS26: 48601 | AT26: {=_xll.PrecioBD(AP26,"24","BID","N")} -> 106 | AU26: {=_xll.PrecioBD(AP26,"24","ASK","N")} -> 107.1 | AV26: {=_xll.PrecioBD(AP26,24,"QUANTITY BID","N")} -> 10000 | AW26: {=_xll.PrecioBD(AP26,24,"QUANTITY ASK","N")} -> 16000 | AX26: {=_xll.PrecioBD(AP26,24,"VOLUME AMOUNT","N")} -> 0 | AY26: {=_xll.PrecioBD(AP26,24,"IMBALANCE","N")} -> 0 | AZ26: Semestral | BA26: 1000 | BB26: Sinkable
D27: MU | E27: {=_xll.PrecioBD(D27,24,"ASK","N")} -> 123650 | F27: {=_xll.PrecioBD(D27,24,"VOLUME AMOUNT","N")} -> 8568427575 | G27: {=_xll.PrecioBD(D27,24,"IMBALANCE","N")} -> 0.0189 | J27: TGNO4 | K27: {=_xll.PrecioBD(J27,24,"ASK","N")} -> 4545 | L27: {=_xll.PrecioBD(J27,24,"VOLUME AMOUNT","N")} -> 2.6566524e+08 | M27: {=_xll.PrecioBD(J27,24,"IMBALANCE","N")} -> 0.0022 | Q27: S17A6 | R27: =AB8/$R$23-1 -> 0.051627993 | S27: =AB8/$S$23-1 -> 0.016573727 | T27: =AB8/$T$23-1 -> -0.016218974 | U27: =AB8/$U$23-1 -> -0.046962131 | V27: =AB8/$V$23-1 -> -0.075842067 | W27: =AB8/$W$23-1 -> -0.10302318 | X27: =AB8/$X$23-1 -> -0.12865109 | Y27: =AB8/$Y$23-1 -> -0.15285523 | Z27: =AB8/$Z$23-1 -> -0.17575103 | AP27: PNXCD | AQ27: {=INDIRECT("'" & AP27 & "'!K4")} -> 0.062183937 | AR27: {=INDIRECT("'" & AP27 & "'!K3")} -> 4.134957 | AS27: 48334 | AT27: {=_xll.PrecioBD(AP27,"24","BID","N")} -> 112.35 | AU27: {=_xll.PrecioBD(AP27,"24","ASK","N")} -> 112.9 | AV27: {=_xll.PrecioBD(AP27,24,"QUANTITY BID","N")} -> 1000 | AW27: {=_xll.PrecioBD(AP27,24,"QUANTITY ASK","N")} -> 7000 | AX27: {=_xll.PrecioBD(AP27,24,"VOLUME AMOUNT","N")} -> 23591 | AY27: {=_xll.PrecioBD(AP27,24,"IMBALANCE","N")} -> 0.0057 | AZ27: Semestral | BA27: 1 | BB27: Sinkable
D28: MSFT | E28: {=_xll.PrecioBD(D28,24,"ASK","N")} -> 19630 | F28: {=_xll.PrecioBD(D28,24,"VOLUME AMOUNT","N")} -> 2172524600 | G28: {=_xll.PrecioBD(D28,24,"IMBALANCE","N")} -> -0.016 | J28: TXAR | K28: {=_xll.PrecioBD(J28,24,"ASK","N")} -> 700 | L28: {=_xll.PrecioBD(J28,24,"VOLUME AMOUNT","N")} -> 1.0039531e+08 | M28: {=_xll.PrecioBD(J28,24,"IMBALANCE","N")} -> -0.0007 | Q28: S30A6 | R28: =AB9/$R$23-1 -> 0.060266414 | S28: =AB9/$S$23-1 -> 0.0249242 | T28: =AB9/$T$23-1 -> -0.0081378706 | U28: =AB9/$U$23-1 -> -0.039133562 | V28: =AB9/$V$23-1 -> -0.068250727 | W28: =AB9/$W$23-1 -> -0.095655117 | X28: =AB9/$X$23-1 -> -0.12149354 | Y28: =AB9/$Y$23-1 -> -0.1458965 | Z28: =AB9/$Z$23-1 -> -0.16898038 | AP28: BACGD | AQ28: {=INDIRECT("'" & AP28 & "'!K4")} -> 0.058027127 | AR28: {=INDIRECT("'" & AP28 & "'!K3")} -> 2.9104947 | AS28: 47292 | AT28: {=_xll.PrecioBD(AP28,"24","BID","N")} -> 107.2 | AU28: {=_xll.PrecioBD(AP28,"24","ASK","N")} -> 108 | AV28: {=_xll.PrecioBD(AP28,24,"QUANTITY BID","N")} -> 6000 | AW28: {=_xll.PrecioBD(AP28,24,"QUANTITY ASK","N")} -> 11000 | AX28: {=_xll.PrecioBD(AP28,24,"VOLUME AMOUNT","N")} -> 20511.5 | AY28: {=_xll.PrecioBD(AP28,24,"IMBALANCE","N")} -> 0.0079 | AZ28: Semestral | BA28: 10000 | BB28: Bullet
D29: MELI | E29: {=_xll.PrecioBD(D29,24,"ASK","N")} -> 25300 | F29: {=_xll.PrecioBD(D29,24,"VOLUME AMOUNT","N")} -> 1713938220 | G29: {=_xll.PrecioBD(D29,24,"IMBALANCE","N")} -> 0.0148 | J29: ALUA | K29: {=_xll.PrecioBD(J29,24,"ASK","N")} -> 995 | L29: {=_xll.PrecioBD(J29,24,"VOLUME AMOUNT","N")} -> 1.870205e+08 | M29: {=_xll.PrecioBD(J29,24,"IMBALANCE","N")} -> -0.0015 | Q29: S29Y6 | R29: =AB10/$R$23-1 -> 0.087978766 | S29: =AB10/$S$23-1 -> 0.051712807 | T29: =AB10/$T$23-1 -> 0.017786587 | U29: =AB10/$U$23-1 -> -0.014019244 | V29: =AB10/$V$23-1 -> -0.043897448 | W29: =AB10/$W$23-1 -> -0.072018112 | X29: =AB10/$X$23-1 -> -0.09853188 | Y29: =AB10/$Y$23-1 -> -0.12357266 | Z29: =AB10/$Z$23-1 -> -0.14725989 | AP29: ARC1D | AQ29: {=INDIRECT("'" & AP29 & "'!K4")} -> 0.061365077 | AR29: {=INDIRECT("'" & AP29 & "'!K3")} -> 2.9687023 | AS29: 48061 | AT29: {=_xll.PrecioBD(AP29,"24","BID","N")} -> 106.15 | AU29: {=_xll.PrecioBD(AP29,"24","ASK","N")} -> 106.3 | AV29: {=_xll.PrecioBD(AP29,24,"QUANTITY BID","N")} -> 1000 | AW29: {=_xll.PrecioBD(AP29,24,"QUANTITY ASK","N")} -> 14000 | AX29: {=_xll.PrecioBD(AP29,24,"VOLUME AMOUNT","N")} -> 17005.5 | AY29: {=_xll.PrecioBD(AP29,24,"IMBALANCE","N")} -> 0.0037 | AZ29: Trimestral | BA29: 1000 | BB29: Sinkable
D30: VIST | E30: {=_xll.PrecioBD(D30,24,"ASK","N")} -> 27140 | F30: {=_xll.PrecioBD(D30,24,"VOLUME AMOUNT","N")} -> 1691423680 | G30: {=_xll.PrecioBD(D30,24,"IMBALANCE","N")} -> -0.0173 | J30: TRAN | K30: {=_xll.PrecioBD(J30,24,"ASK","N")} -> 4117.5 | L30: {=_xll.PrecioBD(J30,24,"VOLUME AMOUNT","N")} -> 245508190 | M30: {=_xll.PrecioBD(J30,24,"IMBALANCE","N")} -> -0.0042 | Q30: T30J6 | R30: =AB11/$R$23-1 -> 0.11911921 | S30: =AB11/$S$23-1 -> 0.081815235 | T30: =AB11/$T$23-1 -> 0.04691797 | U30: =AB11/$U$23-1 -> 0.014201783 | V30: =AB11/$V$23-1 -> -0.016531604 | W30: =AB11/$W$23-1 -> -0.045457145 | X30: =AB11/$X$23-1 -> -0.072729798 | Y30: =AB11/$Y$23-1 -> -0.098487304 | Z30: =AB11/$Z$23-1 -> -0.12285251 | AP30: BYCHD | AQ30: {=INDIRECT("'" & AP30 & "'!K4")} -> 0.05249463 | AR30: {=INDIRECT("'" & AP30 & "'!K3")} -> 2.3355305 | AS30: 47036 | AT30: {=_xll.PrecioBD(AP30,"24","BID","N")} -> 106.75 | AU30: {=_xll.PrecioBD(AP30,"24","ASK","N")} -> 109 | AV30: {=_xll.PrecioBD(AP30,24,"QUANTITY BID","N")} -> 20000 | AW30: {=_xll.PrecioBD(AP30,24,"QUANTITY ASK","N")} -> 2700 | AX30: {=_xll.PrecioBD(AP30,24,"VOLUME AMOUNT","N")} -> 0 | AY30: {=_xll.PrecioBD(AP30,24,"IMBALANCE","N")} -> 0 | AZ30: Semestral | BA30: 10000 | BB30: Bullet
D31: HUT | E31: {=_xll.PrecioBD(D31,24,"ASK","N")} -> 385900 | F31: {=_xll.PrecioBD(D31,24,"VOLUME AMOUNT","N")} -> 1174584275 | G31: {=_xll.PrecioBD(D31,24,"IMBALANCE","N")} -> -0.0183 | J31: IRSA | K31: {=_xll.PrecioBD(J31,24,"ASK","N")} -> 2325 | L31: {=_xll.PrecioBD(J31,24,"VOLUME AMOUNT","N")} -> 43247005 | M31: {=_xll.PrecioBD(J31,24,"IMBALANCE","N")} -> -0.0042 | Q31: S31L6 | R31: =AB12/$R$23-1 -> 0.15082942 | S31: =AB12/$S$23-1 -> 0.11246844 | T31: =AB12/$T$23-1 -> 0.076582361 | U31: =AB12/$U$23-1 -> 0.042939162 | V31: =AB12/$V$23-1 -> 0.011334945 | W31: =AB12/$W$23-1 -> -0.018410201 | X31: =AB12/$X$23-1 -> -0.046455623 | Y31: =AB12/$Y$23-1 -> -0.072942967 | Z31: =AB12/$Z$23-1 -> -0.097998563 | AP31: YMCID | AQ31: {=INDIRECT("'" & AP31 & "'!K4")} -> 0.050438944 | AR31: {=INDIRECT("'" & AP31 & "'!K3")} -> 1.7060416 | AS31: 47299 | AT31: {=_xll.PrecioBD(AP31,"24","BID","N")} -> 108 | AU31: {=_xll.PrecioBD(AP31,"24","ASK","N")} -> 108.15 | AV31: {=_xll.PrecioBD(AP31,24,"QUANTITY BID","N")} -> 37818 | AW31: {=_xll.PrecioBD(AP31,24,"QUANTITY ASK","N")} -> 932 | AX31: {=_xll.PrecioBD(AP31,24,"VOLUME AMOUNT","N")} -> 319465.78 | AY31: {=_xll.PrecioBD(AP31,24,"IMBALANCE","N")} -> -0.0023 | AZ31: Semestral | BA31: 1000 | BB31: Sinkable
D32: TSLA | E32: {=_xll.PrecioBD(D32,24,"ASK","N")} -> 41740 | F32: {=_xll.PrecioBD(D32,24,"VOLUME AMOUNT","N")} -> 1128756160 | G32: {=_xll.PrecioBD(D32,24,"IMBALANCE","N")} -> -0.008 | J32: BYMA | K32: {=_xll.PrecioBD(J32,24,"ASK","N")} -> 323 | L32: {=_xll.PrecioBD(J32,24,"VOLUME AMOUNT","N")} -> 3.2396257e+08 | M32: {=_xll.PrecioBD(J32,24,"IMBALANCE","N")} -> -0.0092 | Q32: S31G6 | R32: =AB13/$R$23-1 -> 0.18890037 | S32: =AB13/$S$23-1 -> 0.14927036 | T32: =AB13/$T$23-1 -> 0.11219712 | U32: =AB13/$U$23-1 -> 0.077440961 | V32: =AB13/$V$23-1 -> 0.044791235 | W32: =AB13/$W$23-1 -> 0.014062081 | X32: =AB13/$X$23-1 -> -0.014911122 | Y32: =AB13/$Y$23-1 -> -0.042274702 | Z32: =AB13/$Z$23-1 -> -0.068159169 | AP32: IRCFD | AQ32: {=INDIRECT("'" & AP32 & "'!K4")} -> 0.055855003 | AR32: {=INDIRECT("'" & AP32 & "'!K3")} -> 1.4147671 | AS32: 46926 | AT32: {=_xll.PrecioBD(AP32,"24","BID","N")} -> 68.62 | AU32: {=_xll.PrecioBD(AP32,"24","ASK","N")} -> 68.89 | AV32: {=_xll.PrecioBD(AP32,24,"QUANTITY BID","N")} -> 7216 | AW32: {=_xll.PrecioBD(AP32,24,"QUANTITY ASK","N")} -> 400 | AX32: {=_xll.PrecioBD(AP32,24,"VOLUME AMOUNT","N")} -> 22459.43 | AY32: {=_xll.PrecioBD(AP32,24,"IMBALANCE","N")} -> 0.0005 | AZ32: Semestral | BA32: 1000 | BB32: Bullet
D33: AMD | E33: {=_xll.PrecioBD(D33,24,"ASK","N")} -> 31120 | F33: {=_xll.PrecioBD(D33,24,"VOLUME AMOUNT","N")} -> 1014853820 | G33: {=_xll.PrecioBD(D33,24,"IMBALANCE","N")} -> -0.0101 | J33: TECO2 | K33: {=_xll.PrecioBD(J33,24,"ASK","N")} -> 3380 | L33: {=_xll.PrecioBD(J33,24,"VOLUME AMOUNT","N")} -> 5.8328943e+08 | M33: {=_xll.PrecioBD(J33,24,"IMBALANCE","N")} -> -0.0102 | Q33: S30O6 | R33: =AB14/$R$23-1 -> 0.23333472 | S33: =AB14/$S$23-1 -> 0.19222356 | T33: =AB14/$T$23-1 -> 0.15376473 | U33: =AB14/$U$23-1 -> 0.11770959 | V33: =AB14/$V$23-1 -> 0.083839598 | W33: =AB14/$W$23-1 -> 0.051961963 | X33: =AB14/$X$23-1 -> 0.021905907 | Y33: =AB14/$Y$23-1 -> -0.0064803684 | Z33: =AB14/$Z$23-1 -> -0.03333225 | AP33: CAC5D | AQ33: {=INDIRECT("'" & AP33 & "'!K4")} -> 0.059898403 | AR33: {=INDIRECT("'" & AP33 & "'!K3")} -> 1.141965 | AS33: 46990 | AT33: {=_xll.PrecioBD(AP33,"24","BID","N")} -> 80.61 | AU33: {=_xll.PrecioBD(AP33,"24","ASK","N")} -> 81.28 | AV33: {=_xll.PrecioBD(AP33,24,"QUANTITY BID","N")} -> 1351 | AW33: {=_xll.PrecioBD(AP33,24,"QUANTITY ASK","N")} -> 916 | AX33: {=_xll.PrecioBD(AP33,24,"VOLUME AMOUNT","N")} -> 32006.09 | AY33: {=_xll.PrecioBD(AP33,24,"IMBALANCE","N")} -> -0.01 | AZ33: Semestral | BA33: 1000 | BB33: Sinkable
D34: COIN | E34: {=_xll.PrecioBD(D34,24,"ASK","N")} -> 7910 | F34: {=_xll.PrecioBD(D34,24,"VOLUME AMOUNT","N")} -> 1010921675 | G34: {=_xll.PrecioBD(D34,24,"IMBALANCE","N")} -> -0.0561 | J34: VALO | K34: {=_xll.PrecioBD(J34,24,"ASK","N")} -> 582 | L34: {=_xll.PrecioBD(J34,24,"VOLUME AMOUNT","N")} -> 1.6812574e+09 | M34: {=_xll.PrecioBD(J34,24,"IMBALANCE","N")} -> -0.0127 | Q34: S30N6 | R34: =AB15/$R$23-1 -> 0.27363896 | S34: =AB15/$S$23-1 -> 0.23118432 | T34: =AB15/$T$23-1 -> 0.1914687 | U34: =AB15/$U$23-1 -> 0.1542353 | V34: =AB15/$V$23-1 -> 0.11925848 | W34: =AB15/$W$23-1 -> 0.086339109 | X34: =AB15/$X$23-1 -> 0.055300849 | Y34: =AB15/$Y$23-1 -> 0.025986936 | Z34: =AB15/$Z$23-1 -> -0.0017424404 | AP34: MTCGD | AQ34: {=INDIRECT("'" & AP34 & "'!K4")} -> 0.02873399 | AR34: {=INDIRECT("'" & AP34 & "'!K3")} -> 0.36070615 | AS34: 46203 | AT34: {=_xll.PrecioBD(AP34,"24","BID","N")} -> 104.3 | AU34: {=_xll.PrecioBD(AP34,"24","ASK","N")} -> 104.4 | AV34: {=_xll.PrecioBD(AP34,24,"QUANTITY BID","N")} -> 580 | AW34: {=_xll.PrecioBD(AP34,24,"QUANTITY ASK","N")} -> 2268 | AX34: {=_xll.PrecioBD(AP34,24,"VOLUME AMOUNT","N")} -> 17231.61 | AY34: {=_xll.PrecioBD(AP34,24,"IMBALANCE","N")} -> 0.0009 | AZ34: Trimestral | BA34: 2000 | BB34: Bullet
D35: SPY | E35: {=_xll.PrecioBD(D35,24,"ASK","N")} -> 50675 | F35: {=_xll.PrecioBD(D35,24,"VOLUME AMOUNT","N")} -> 1044567400 | G35: {=_xll.PrecioBD(D35,24,"IMBALANCE","N")} -> -0.0107 | J35: METR | K35: {=_xll.PrecioBD(J35,24,"ASK","N")} -> 2339 | L35: {=_xll.PrecioBD(J35,24,"VOLUME AMOUNT","N")} -> 325618803 | M35: {=_xll.PrecioBD(J35,24,"IMBALANCE","N")} -> -0.0131 | Q35: T15E7 | R35: =AB16/$R$23-1 -> 0.3302823 | S35: =AB16/$S$23-1 -> 0.28593955 | T35: =AB16/$T$23-1 -> 0.24445763 | U35: =AB16/$U$23-1 -> 0.20556833 | V35: =AB16/$V$23-1 -> 0.16903596 | W35: =AB16/$W$23-1 -> 0.13465255 | X35: =AB16/$X$23-1 -> 0.1022339 | Y35: =AB16/$Y$23-1 -> 0.071616295 | Z35: =AB16/$Z$23-1 -> 0.042653692 | AP35: YCAMD | AQ35: {=INDIRECT("'" & AP35 & "'!K4")} -> 0 | AR35: {=INDIRECT("'" & AP35 & "'!K3")} -> 0 | AS35: 46589 | AT35: {=_xll.PrecioBD(AP35,"24","BID","N")} -> 0 | AU35: {=_xll.PrecioBD(AP35,"24","ASK","N")} -> 105.3 | AV35: {=_xll.PrecioBD(AP35,24,"QUANTITY BID","N")} -> 0 | AW35: {=_xll.PrecioBD(AP35,24,"QUANTITY ASK","N")} -> 26000 | AX35: {=_xll.PrecioBD(AP35,24,"VOLUME AMOUNT","N")} -> 0 | AY35: {=_xll.PrecioBD(AP35,24,"IMBALANCE","N")} -> 0 | AZ35: Semestral | BA35: 1 | BB35: Sinkable
D36: JMIA | E36: {=_xll.PrecioBD(D36,24,"ASK","N")} -> 14290 | F36: {=_xll.PrecioBD(D36,24,"VOLUME AMOUNT","N")} -> 902736040 | G36: {=_xll.PrecioBD(D36,24,"IMBALANCE","N")} -> -0.0082 | J36: YPFD | K36: {=_xll.PrecioBD(J36,24,"ASK","N")} -> 56800 | L36: {=_xll.PrecioBD(J36,24,"VOLUME AMOUNT","N")} -> 4231933225 | M36: {=_xll.PrecioBD(J36,24,"IMBALANCE","N")} -> -0.0177 | Q36: T30A7 | R36: =AB17/$R$23-1 -> 0.45963841 | S36: =AB17/$S$23-1 -> 0.4109838 | T36: =AB17/$T$23-1 -> 0.36546819 | U36: =AB17/$U$23-1 -> 0.32279731 | V36: =AB17/$V$23-1 -> 0.28271254 | W36: =AB17/$W$23-1 -> 0.2449857 | X36: =AB17/$X$23-1 -> 0.20941468 | Y36: =AB17/$Y$23-1 -> 0.17581983 | Z36: =AB17/$Z$23-1 -> 0.14404092 | AP36: PNDCD | AQ36: {=INDIRECT("'" & AP36 & "'!K4")} -> 0.0024431378 | AR36: {=INDIRECT("'" & AP36 & "'!K3")} -> 0.68797658 | AS36: 46507 | AT36: {=_xll.PrecioBD(AP36,"24","BID","N")} -> 64 | AU36: {=_xll.PrecioBD(AP36,"24","ASK","N")} -> 65.37 | AV36: {=_xll.PrecioBD(AP36,24,"QUANTITY BID","N")} -> 3000 | AW36: {=_xll.PrecioBD(AP36,24,"QUANTITY ASK","N")} -> 5000 | AX36: {=_xll.PrecioBD(AP36,24,"VOLUME AMOUNT","N")} -> 0 | AY36: {=_xll.PrecioBD(AP36,24,"IMBALANCE","N")} -> 0 | AZ36: Semestral | BA36: 1 | BB36: Sinkable
D37: IBIT | E37: {=_xll.PrecioBD(D37,24,"ASK","N")} -> 5610 | F37: {=_xll.PrecioBD(D37,24,"VOLUME AMOUNT","N")} -> 796716555 | G37: {=_xll.PrecioBD(D37,24,"IMBALANCE","N")} -> -0.0114 | J37: CRES | K37: {=_xll.PrecioBD(J37,24,"ASK","N")} -> 1846 | L37: {=_xll.PrecioBD(J37,24,"VOLUME AMOUNT","N")} -> 109461415 | M37: {=_xll.PrecioBD(J37,24,"IMBALANCE","N")} -> -0.0196 | Q37: T31Y7 | R37: =AB18/$R$23-1 -> 0.46171775 | S37: =AB18/$S$23-1 -> 0.41299383 | T37: =AB18/$T$23-1 -> 0.36741338 | U37: =AB18/$U$23-1 -> 0.32468171 | V37: =AB18/$V$23-1 -> 0.28453984 | W37: =AB18/$W$23-1 -> 0.24675926 | X37: =AB18/$X$23-1 -> 0.21113757 | Y37: =AB18/$Y$23-1 -> 0.17749486 | Z37: =AB18/$Z$23-1 -> 0.14567067
D38: AAPL | E38: {=_xll.PrecioBD(D38,24,"ASK","N")} -> 19870 | F38: {=_xll.PrecioBD(D38,24,"VOLUME AMOUNT","N")} -> 765856910 | G38: {=_xll.PrecioBD(D38,24,"IMBALANCE","N")} -> -0.0264 | J38: BMA | K38: {=_xll.PrecioBD(J38,24,"ASK","N")} -> 13590 | L38: {=_xll.PrecioBD(J38,24,"VOLUME AMOUNT","N")} -> 1174789710 | M38: {=_xll.PrecioBD(J38,24,"IMBALANCE","N")} -> -0.0251 | Q38: T30J7 | R38: =AB19/$R$23-1 -> 0.37968437 | S38: =AB19/$S$23-1 -> 0.33369489 | T38: =AB19/$T$23-1 -> 0.29067247 | U38: =AB19/$U$23-1 -> 0.25033896 | V38: =AB19/$V$23-1 -> 0.2124499 | W38: =AB19/$W$23-1 -> 0.17678961 | X38: =AB19/$X$23-1 -> 0.14316705 | Y38: =AB19/$Y$23-1 -> 0.11141241 | Z38: =AB19/$Z$23-1 -> 0.081374233
D39: AMZN | E39: {=_xll.PrecioBD(D39,24,"ASK","N")} -> 2046 | F39: {=_xll.PrecioBD(D39,24,"VOLUME AMOUNT","N")} -> 760295075 | G39: {=_xll.PrecioBD(D39,24,"IMBALANCE","N")} -> -0.0284 | J39: PAMP | K39: {=_xll.PrecioBD(J39,24,"ASK","N")} -> 4940 | L39: {=_xll.PrecioBD(J39,24,"VOLUME AMOUNT","N")} -> 1222518355 | M39: {=_xll.PrecioBD(J39,24,"IMBALANCE","N")} -> -0.0256
D40: GOOGL | E40: {=_xll.PrecioBD(D40,24,"ASK","N")} -> 7860 | F40: {=_xll.PrecioBD(D40,24,"VOLUME AMOUNT","N")} -> 751712840 | G40: {=_xll.PrecioBD(D40,24,"IMBALANCE","N")} -> -0.0094 | J40: COME | K40: {=_xll.PrecioBD(J40,24,"ASK","N")} -> 51.5 | L40: {=_xll.PrecioBD(J40,24,"VOLUME AMOUNT","N")} -> 2.0281591e+08 | M40: {=_xll.PrecioBD(J40,24,"IMBALANCE","N")} -> -0.0284
...

Sheet Hoja1
B3: ALUA | C3: 990,00 | D3: 1,12 | E3: -5,26 | F3: 1,02 | G3: 979,00 | H3: 990,00 | I3: 980,00 | J3: 1.030,00 | K3: 0.69513889 | L3: 729.547 | M3: 740.354.729,00
B4: BBAR | C4: 9.000,00 | D4: 1,60 | E4: -11,81 | F4: -2,74 | G4: 8.750,00 | H4: 8.920,00 | I4: 8.785,00 | J4: 9.125,00 | K4: 0.69513889 | L4: 234.589 | M4: 2.092.388.530,00
B5: BMA | C5: 13.750,00 | D5: 3,59 | E5: -9,35 | F5: 2,14 | G5: 13.380,00 | H5: 13.030,00 | I5: 13.030,00 | J5: 13.950,00 | K5: 0.69513889 | L5: 136.009 | M5: 1.861.423.320,00
B6: BYMA | C6: 329,75 | D6: -0,23 | E6: -1,79 | F6: 13,41 | G6: 330,50 | H6: 329,75 | I6: 329,25 | J6: 333,75 | K6: 0.69513889 | L6: 12.906.984 | M6: 4.282.852.453,00
B7: CEPU | C7: 2.343,00 | D7: 1,38 | E7: -9,46 | F7: -12,98 | G7: 2.322,00 | H7: 2.313,00 | I7: 2.300,00 | J7: 2.385,00 | K7: 0.69513889 | L7: 430.717 | M7: 1.015.226.332,00
B8: COME | C8: 51,60 | D8: 2,79 | E8: -15,13 | F8: -13,28 | G8: 50,20 | H8: 51,40 | I8: 50,50 | J8: 51,60 | K8: 0.69513889 | L8: 13.089.758 | M8: 671.076.788,00
B9: CRES | C9: 1.954,00 | D9: 0,84 | E9: -5,12 | F9: 0,42 | G9: 1.910,00 | H9: 1.980,00 | I9: 1.898,00 | J9: 2.000,00 | K9: 0.69513889 | L9: 312.668 | M9: 605.569.646,00
B10: EDN | C10: 2.057,00 | D10: 1,98 | E10: -12,02 | F10: -15,25 | G10: 2.017,00 | H10: 2.015,00 | I10: 2.015,00 | J10: 2.093,00 | K10: 0.68055556 | L10: 339.662 | M10: 699.986.421,00
B11: GGAL | C11: 7.515,00 | D11: 0,46 | E11: -10,65 | F11: -9,45 | G11: 7.480,43 | H11: 7.515,00 | I11: 7.350,00 | J11: 7.640,00 | K11: 0.69513889 | L11: 3.567.229 | M11: 26.616.044.485,00
B12: IRSA | C12: 2.375,00 | D12: - | E12: -9,87 | F12: -6,31 | G12: 2.375,00 | H12: 2.375,00 | I12: 2.355,00 | J12: 2.445,00 | K12: 0.69513889 | L12: 168.413 | M12: 404.590.690,00
B13: LOMA | C13: 3.330,00 | D13: 3,02 | E13: -7,38 | F13: -17,60 | G13: 3.227,50 | H13: 3.232,50 | I13: 3.232,50 | J13: 3.405,00 | K13: 0.69513889 | L13: 200.823 | M13: 666.762.465,00
B14: METR | C14: 2.280,00 | D14: 4,23 | E14: -2,34 | F14: -8,15 | G14: 2.245,00 | H14: 2.255,00 | I14: 2.255,00 | J14: 2.377,00 | K14: 0.69513889 | L14: 435.19 | M14: 1.012.517.298,00
B15: PAMP | C15: 4.920,00 | D15: 1,32 | E15: -4,41 | F15: -5,23 | G15: 4.920,00 | H15: 4.920,00 | I15: 4.900,00 | J15: 5.045,00 | K15: 0.69513889 | L15: 895.564 | M15: 4.465.168.188,00
B16: SUPV | C16: 3.245,00 | D16: 4,05 | E16: -11,01 | F16: -8,26 | G16: 3.147,50 | H16: 3.145,00 | I16: 3.145,00 | J16: 3.292,50 | K16: 0.69513889 | L16: 629.97 | M16: 2.039.917.058,00
B17: TECO2 | C17: 3.620,00 | D17: 3,95 | E17: -11,71 | F17: 2,62 | G17: 3.482,50 | H17: 3.605,00 | I17: 3.470,00 | J17: 3.670,00 | K17: 0.68055556 | L17: 71.928 | M17: 255.944.160,00
B18: TGNO4 | C18: 4.120,00 | D18: 3,65 | E18: -8,50 | F18: -15,92 | G18: 3.975,00 | H18: 4.090,00 | I18: 4.007,50 | J18: 4.182,50 | K18: 0.69513889 | L18: 211.601 | M18: 865.019.880,00
B19: TGSU2 | C19: 8.760,00 | D19: 2,00 | E19: -7,51 | F19: -3,46 | G19: 8.755,00 | H19: 8.760,00 | I19: 8.760,00 | J19: 9.130,00 | K19: 0.69513889 | L19: 159.019 | M19: 1.418.342.155,00
B20: TRAN | C20: 3.950,00 | D20: 3,56 | E20: 4,03 | F20: 11,81 | G20: 3.862,50 | H20: 3.865,00 | I20: 3.820,00 | J20: 4.000,00 | K20: 0.69513889 | L20: 379.215 | M20: 1.505.853.448,00
B21: TXAR | C21: 691,00 | D21: 1,10 | E21: -1,99 | F21: 2,83 | G21: 683,50 | H21: 691,00 | I21: 680,50 | J21: 701,50 | K21: 0.69513889 | L21: 684.823 | M21: 471.499.947,00
B22: VALO | C22: 585,00 | D22: 0,77 | E22: -5,08 | F22: 6,81 | G22: 583,50 | H22: 585,00 | I22: 585,00 | J22: 594,00 | K22: 0.69513889 | L22: 2.466.195 | M22: 1.449.781.104,00
B23: YPFD | C23: 56.500,00 | D23: 1,37 | E23: -4,19 | F23: 4,76 | G23: 56.425,00 | H23: 56.500,00 | I23: 56.500,00 | J23: 58.300,00 | K23: 0.69513889 | L23: 214.242 | M23: 12.369.784.400,00

Sheet Multi-mercado
A1: Ticker | B1: GD41D | C1: 24
B3: Cierre | C3: {=_xll.PrecioBD(B1,C1,"PREVIOUS","N")} -> 74.98 | D3: Último | E3: {=_xll.PrecioBD(B1,C1,"LAST","N")} -> 75.12 | F3: Var | G3: {=_xll.PrecioBD(B1,C1,"IMBALANCE","N")} -> 0.0018
B4: Vwap | C4: {=_xll.PrecioBD(B1,C1,"VWAP","N")} -> 75.037905 | D4: Nominales | E4: {=_xll.PrecioBD(B1,C1,"TRADE VOLUME","N")} -> 223225 | F4: Monto $ | G4: {=_xll.PrecioBD(B1,C1,"VOLUME AMOUNT","N")} -> 167503.41
B6: {=_xll.PrecioBD(B1,C1,"BID","N")} -> 75.11 | E6: {=_xll.PrecioBD(B1,C1,"ASK","N")} -> 75.15
A7: {=_xll.ProfundidadBD(B1,C1)} -> GD41D - 24hs | B7: ORD. | C7: CANT. | D7: PRECIO | E7: PRECIO | F7: CANT. | G7: ORD.
B8: 2 | C8: 763 | D8: 75.07 | E8: 75.15 | F8: 10 | G8: 1
B9: 1 | C9: 146 | D9: 75.02 | E9: 75.21 | F9: 559 | G9: 1
B10: 1 | C10: 632 | D10: 74.99 | E10: 75.22 | F10: 244 | G10: 1
B11: 1 | C11: 94 | D11: 74.95 | E11: 75.23 | F11: 960 | G11: 1
B12: 1 | C12: 8 | D12: 74.92 | E12: 75.24 | F12: 996 | G12: 1
I14: Pase
A15: Ticker | B15: =B1 -> GD41D | C15: CI | J15: Venta CI - Compra T1 | K15: Compra CI - Venta T1
I16: Arbitraje | J16: =D22/E8-1 -> -0.0011976048 | K16: =D8/E22-1 -> -0.0011974454
B17: Cierre | C17: {=_xll.PrecioBD(B15,C15,"PREVIOUS","N")} -> 74.95 | D17: Último | E17: {=_xll.PrecioBD(B15,C15,"LAST","N")} -> 75.16 | F17: Var | G17: {=_xll.PrecioBD(B15,C15,"IMBALANCE","N")} -> 0.0028 | I17: TNA | J17: =+J16*365 -> -0.43712575 | K17: =+K16*365 -> -0.43706759
B18: Vwap | C18: {=_xll.PrecioBD(B15,C15,"VWAP","N")} -> 75.070864 | D18: Nominales | E18: {=_xll.PrecioBD(B15,C15,"TRADE VOLUME","N")} -> 54350 | F18: Monto $ | G18: {=_xll.PrecioBD(B15,C15,"VOLUME AMOUNT","N")} -> 40801.02
B20: {=_xll.PrecioBD(B15,C15,"BID","N")} -> 75.1 | E20: {=_xll.PrecioBD(B15,C15,"ASK","N")} -> 75.16
A21: {=_xll.ProfundidadBD(B15,C15)} -> GD41D - CI | B21: ORD. | C21: CANT. | D21: PRECIO | E21: PRECIO | F21: CANT. | G21: ORD.
B22: 2 | C22: 1227 | D22: 75.06 | E22: 75.16 | F22: 10 | G22: 1
B23: 1 | C23: 10 | D23: 75.03 | E23: 75.21 | F23: 10 | G23: 1
B24: 1 | C24: 599 | D24: 74.95 | E24: 75.23 | F24: 5480 | G24: 1
B25: 1 | C25: 557 | D25: 74.93 | E25: 75.25 | F25: 159 | G25: 1
B26: 1 | C26: 2 | D26: 74.88 | E26: 75.26 | F26: 3720 | G26: 1

Sheet Indices BYMA
B3: {=_xll.IndicesBYMABD()} -> INDICES BYMA | C3: DESCRIPCION | D3: NOMBRE | E3: PRECIO | F3: MAXIMO | G3: MINIMO | H3: VARIACION | I3: CIERRE | J3: CIERRE ANTERIOR
C4: S&P BYMA Indice General | E4: 1.2083177e+08 | F4: 1.2476379e+08 | G4: 1.2079439e+08 | H4: -0.0207 | I4: 0 | J4: 1.2338569e+08
C5: S&P MERVAL | E5: 2949567.2 | F5: 3051946 | G5: 2948383.6 | H5: -0.0226 | I5: 0 | J5: 3017641.3
C6: S&P BYMA Construccion | E6: 43895.26 | F6: 45769.96 | G6: 43728.74 | H6: -0.0203 | I6: 0 | J6: 44806.34
C7: S&P BYMA CEDEAR Index | E7: 34712.41 | F7: 35283.66 | G7: 34710.36 | H7: -0.0149 | I7: 0 | J7: 35237.17
C8: S&P BYMA Ingenius Index | E8: 23678.1 | F8: 24173.33 | G8: 23654.2 | H8: -0.0205 | I8: 0 | J8: 24173.33
C9: S&P BYMA Energia | E9: 104946.17 | F9: 107722.98 | G9: 104439.2 | H9: -0.0185 | I9: 0 | J9: 106929.61
C10: S&P BYMA Bs Intermedios | E10: 50288.99 | F10: 51272.74 | G10: 50112.96 | H10: -0.0071 | I10: 0 | J10: 50646.76
C11: S&P BYMA Ind y Bs de Cap | E11: 46180.62 | F11: 47178.02 | G11: 46016.63 | H11: 0.0036 | I11: 0 | J11: 46016.63
C12: S&P BYMA Cons No Esencial | E12: 63004.83 | F12: 63999.08 | G12: 61451.65 | H12: -0.0109 | I12: 0 | J12: 63701.25
C13: S&P BYMA Consumo Masivo | E13: 86354.63 | F13: 88722.6 | G13: 86354.63 | H13: -0.0158 | I13: 0 | J13: 87737.9
