Workbook

Sheet Main
B1: Nombre | C1: Riesgo | D1: Theme | E1: Plazo
B2: Capital | C2: Alto | D2: Working capital | E2: Corto plazo
B4: Elite Income | C4: Medio | D4: Renta fija USD | E4: Largo plazo
B5: Premium Income | C5: Medio | D5: Flujo mensual | E5: Largo plazo
B7: Equilibrium | C7: Medio | D7: Diversificado | E7: Largo plazo
B9: Innova | C9: Extremo | D9: Innovación y teconología disruptiva | E9: Mediano plazo
B10: Future+ | C10: Alto | D10: Inicio de plan de retiro | E10: Largo plazo
B11: Factor alfa | C11: Extremo | D11: Equity cuantitativo | E11: Mediano plazo
B14: Tactical
B16: Value | C16: Alto | D16: Empresas baratas y de calidad | E16: Mediano
B17: Momentum | C17: Alto | D17: Empresas que han subido mucho | E17: Corto
B18: Skewness | C18: Alto | D18: Empresas que cayeron mucho | E18: Corto
B19: Low Volatility | C19: Alto | D19: Empresas con baja volatilidad | E19: Corto
B25: Todo en base a momentum
B26: Stop
B27: Target
B28: Google fianance que se de señal | C28: Tablero
B29: Todo lo que haya universo de activos
B30: Transicionar de a poco.
B54: EMB | C54: https://www,blackrock,com/cl/productos/239572/ishares-jp-morgan-usd-emerging-markets-bond-etf
B55: CEMB | C55: https://www,blackrock,com/cl/productos/239525/ishares-emerging-markets-corporate-bond-etf
B56: EMLC | C56: EMLC - J,P, Morgan EM Local Currency Bond ETF | Holdings & Performance | VanEck
B57: CME | C57: https://interactive,researchaffiliates,com/asset-allocation#!/?category=Multi-Country&currency=USD&model=ER&scale=Log&selected=60&tab=details&terms=Real&type=Government+T-Bills&vs=N4IgxgrgTlCmB2AXAygCwIYAdYGED2ANnlCAFzwQEEA0IqAlgCaMICCAzu7Iu2QNoBWAdQAcI6gEYA7ADZJU8dICckpcIBMABk3UtGzVN0SNEuevUaALCos6LE3QPXVLEh5YDMl3So9yPmgC6tAzMbJzcACoAnti8pHzBdEws8BxciDjoiLAA5sT0sPGJISkI%2BBBIUIXFIOhgILSMALYgSaGpFVXRMXH8SbAAHpjo8CyMvUX8IAAKAKKNIHMAiosASnMAkos4APIAsjtrOwBCiyvqiwBiABqLmwAyZwPDo%2BNZOfnVUwl8S6u0fYAVQekW2wT%2BG22tA2bWofz2h0BILBcL%2Bt0WABE5gA1NH-c6HQIvEZjWCMLqIKA9WI-P6Y2AAN1gRGwjHOzVgUFy9HguUW%2B0oiHoAFpKdS4SB2GAoBAAEZyrk49AECA-UBgLCwEVQbL0PAigi82BkUAEWAAM0QZB0IGquVQ1tImgAvrR8ozECL2KztUb4CbSGbLU7bfbHTa3eA4Ix6F6fXhsIbjaaQOarTbaOHQ1HMMREBbCPr2CLsFBC1BmqMwH6U0G0yHM3b6A6cy6XUA

Sheet Ons
I2: =IFERROR(__xludf.DUMMYFUNCTION("IMPORTRANGE(""https://docs.google.com/spreadsheets/d/1QFB2kh2cYM7XonEBR7QFtdA5P63irew36fgS54qRFHA/edit?pli=1&gid=720802488#gid=720802488"" , ""ONs NY!A:P"")"),45938.0) -> 45938 | AG2: =IFERROR(__xludf.DUMMYFUNCTION("IMPORTRANGE(""https://docs.google.com/spreadsheets/d/1Mr1-WgkgjeFEk5QNcL6PEK-ZeHJ0W4Ga3Q_OiCASfug/edit?gid=301422845#gid=301422845"" , ""ONs Argentina!A:L"")"),"") | AM2: =IFERROR(__xludf.DUMMYFUNCTION("""COMPUTED_VALUE"""),"Comision") -> Comision | AN2: =IFERROR(__xludf.DUMMYFUNCTION("""COMPUTED_VALUE"""),1.0) -> 1
J3: =IFERROR(__xludf.DUMMYFUNCTION("""COMPUTED_VALUE"""),"CORPORATIVOS LEY NY") -> CORPORATIVOS LEY NY | X3: =IFERROR(__xludf.DUMMYFUNCTION("""COMPUTED_VALUE"""),"Canje") -> Canje | AM3: =IFERROR(__xludf.DUMMYFUNCTION("""COMPUTED_VALUE"""),"Dia de liquidacion") -> Dia de liquidacion | AN3: =IFERROR(__xludf.DUMMYFUNCTION("""COMPUTED_VALUE"""),45939.0) -> 45939
B4: Conservador | J4: =IFERROR(__xludf.DUMMYFUNCTION("""COMPUTED_VALUE"""),"Ticker") -> Ticker | K4: =IFERROR(__xludf.DUMMYFUNCTION("""COMPUTED_VALUE"""),"Empresa") -> Empresa | L4: =IFERROR(__xludf.DUMMYFUNCTION("""COMPUTED_VALUE"""),"Vencimiento") -> Vencimiento | M4: =IFERROR(__xludf.DUMMYFUNCTION("""COMPUTED_VALUE"""),"Tasa") -> Tasa | N4: =IFERROR(__xludf.DUMMYFUNCTION("""COMPUTED_VALUE"""),"Precio") -> Precio | O4: =IFERROR(__xludf.DUMMYFUNCTION("""COMPUTED_VALUE"""),"TIR") -> TIR | P4: =IFERROR(__xludf.DUMMYFUNCTION("""COMPUTED_VALUE"""),"Var. Diaria%") -> Var. Diaria% | Q4: =IFERROR(__xludf.DUMMYFUNCTION("""COMPUTED_VALUE"""),"Duration") -> Duration | R4: =IFERROR(__xludf.DUMMYFUNCTION("""COMPUTED_VALUE"""),"Cupones") -> Cupones | S4: =IFERROR(__xludf.DUMMYFUNCTION("""COMPUTED_VALUE"""),"Tipo") -> Tipo | T4: =IFERROR(__xludf.DUMMYFUNCTION("""COMPUTED_VALUE"""),"Ley") -> Ley | U4: =IFERROR(__xludf.DUMMYFUNCTION("""COMPUTED_VALUE"""),"Lam Minima") -> Lam Minima | V4: =IFERROR(__xludf.DUMMYFUNCTION("""COMPUTED_VALUE"""),"Prox Cupón (días)") -> Prox Cupón (días) | W4: =IFERROR(__xludf.DUMMYFUNCTION("""COMPUTED_VALUE"""),"Paridad") -> Paridad
B5: =K5 -> Central Puerto | C5: TIR | D5: M,Duration | E5: Vto | F5: Inverse m,D | G5: Weight | H5: Lamina | J5: =IFERROR(__xludf.DUMMYFUNCTION("""COMPUTED_VALUE"""),"NPCBD") -> NPCBD | K5: =IFERROR(__xludf.DUMMYFUNCTION("""COMPUTED_VALUE"""),"Central Puerto") -> Central Puerto | L5: =IFERROR(__xludf.DUMMYFUNCTION("""COMPUTED_VALUE"""),45947.0) -> 45947 | M5: =IFERROR(__xludf.DUMMYFUNCTION("""COMPUTED_VALUE"""),0.1) -> 0.1 | N5: =IFERROR(__xludf.DUMMYFUNCTION("""COMPUTED_VALUE"""),106.2) -> 106.2 | O5: =IFERROR(__xludf.DUMMYFUNCTION("""COMPUTED_VALUE"""),-0.3692612611849655) -> -0.36926126 | P5: =IFERROR(__xludf.DUMMYFUNCTION("""COMPUTED_VALUE"""),0.0023) -> 0.0023 | Q5: =IFERROR(__xludf.DUMMYFUNCTION("""COMPUTED_VALUE"""),0.02500394606092653) -> 0.025003946 | R5: =IFERROR(__xludf.DUMMYFUNCTION("""COMPUTED_VALUE"""),"Semestral") -> Semestral | S5: =IFERROR(__xludf.DUMMYFUNCTION("""COMPUTED_VALUE"""),"Bullet") -> Bullet | T5: =IFERROR(__xludf.DUMMYFUNCTION("""COMPUTED_VALUE"""),"NY") -> NY | U5: =IFERROR(__xludf.DUMMYFUNCTION("""COMPUTED_VALUE"""),1000.0) -> 1000 | V5: =IFERROR(__xludf.DUMMYFUNCTION("""COMPUTED_VALUE"""),9.0) -> 9 | W5: =IFERROR(__xludf.DUMMYFUNCTION("""COMPUTED_VALUE"""),1.01276821192053) -> 1.0127682 | X5: =IFERROR(__xludf.DUMMYFUNCTION("""COMPUTED_VALUE"""),0.010267693436010417) -> 0.010267693 | AH5: =IFERROR(__xludf.DUMMYFUNCTION("""COMPUTED_VALUE"""),"Empresa") -> Empresa | AI5: =IFERROR(__xludf.DUMMYFUNCTION("""COMPUTED_VALUE"""),"Ticker") -> Ticker | AJ5: =IFERROR(__xludf.DUMMYFUNCTION("""COMPUTED_VALUE"""),"TIR") -> TIR | AK5: =IFERROR(__xludf.DUMMYFUNCTION("""COMPUTED_VALUE"""),"Precio") -> Precio | AL5: =IFERROR(__xludf.DUMMYFUNCTION("""COMPUTED_VALUE"""),"Sin comision") -> Sin comision | AM5: =IFERROR(__xludf.DUMMYFUNCTION("""COMPUTED_VALUE"""),"MD") -> MD | AN5: =IFERROR(__xludf.DUMMYFUNCTION("""COMPUTED_VALUE"""),"Vto") -> Vto | AO5: =IFERROR(__xludf.DUMMYFUNCTION("""COMPUTED_VALUE"""),"Ley") -> Ley | AP5: =IFERROR(__xludf.DUMMYFUNCTION("""COMPUTED_VALUE"""),"Periodicidad") -> Periodicidad | AQ5: =IFERROR(__xludf.DUMMYFUNCTION("""COMPUTED_VALUE"""),"Lamina minima") -> Lamina minima | AR5: =IFERROR(__xludf.DUMMYFUNCTION("""COMPUTED_VALUE"""),"Tipo") -> Tipo
B6: TLCPD | C6: =VLOOKUP(B6,$J$6:$W$36,6,0) -> 0.097477722 | D6: =VLOOKUP(B6,$J$6:$W$36,8,0) -> 5.213219 | E6: =VLOOKUP(B6,$J$6:$W$36,3,0) -> 48727 | F6: =1/D6 -> 0.19182006 | G6: =F6/$F$12 -> 0.17531045 | H6: =VLOOKUP(B6,$J$6:$W$36,12,0) -> 100 | J6: =IFERROR(__xludf.DUMMYFUNCTION("""COMPUTED_VALUE"""),"YMCHD") -> YMCHD | K6: =IFERROR(__xludf.DUMMYFUNCTION("""COMPUTED_VALUE"""),"YPF") -> YPF | L6: =IFERROR(__xludf.DUMMYFUNCTION("""COMPUTED_VALUE"""),46065.0) -> 46065 | M6: =IFERROR(__xludf.DUMMYFUNCTION("""COMPUTED_VALUE"""),0.04) -> 0.04 | N6: =IFERROR(__xludf.DUMMYFUNCTION("""COMPUTED_VALUE"""),16.36) -> 16.36 | O6: =IFERROR(__xludf.DUMMYFUNCTION("""COMPUTED_VALUE"""),-0.12221745916049007) -> -0.12221746 | P6: =IFERROR(__xludf.DUMMYFUNCTION("""COMPUTED_VALUE"""),0.0073) -> 0.0073 | Q6: =IFERROR(__xludf.DUMMYFUNCTION("""COMPUTED_VALUE"""),0.22299269945896666) -> 0.2229927 | R6: =IFERROR(__xludf.DUMMYFUNCTION("""COMPUTED_VALUE"""),"Trimestral") -> Trimestral | S6: =IFERROR(__xludf.DUMMYFUNCTION("""COMPUTED_VALUE"""),"Sinkable") -> Sinkable | T6: =IFERROR(__xludf.DUMMYFUNCTION("""COMPUTED_VALUE"""),"NY") -> NY | U6: =IFERROR(__xludf.DUMMYFUNCTION("""COMPUTED_VALUE"""),1.0) -> 1 | V6: =IFERROR(__xludf.DUMMYFUNCTION("""COMPUTED_VALUE"""),35.0) -> 35 | W6: =IFERROR(__xludf.DUMMYFUNCTION("""COMPUTED_VALUE"""),1.0485156389696602) -> 1.0485156
B7: BACGD | C7: =VLOOKUP(B7,$J$6:$W$36,6,0) -> 0.081859039 | D7: =VLOOKUP(B7,$J$6:$W$36,8,0) -> 3.2393086 | E7: =VLOOKUP(B7,$J$6:$W$36,3,0) -> 47292 | F7: =1/D7 -> 0.30870785 | G7: =F7/$F$12 -> 0.28213792 | H7: =VLOOKUP(B7,$J$6:$W$36,12,0) -> 1000 | J7: =IFERROR(__xludf.DUMMYFUNCTION("""COMPUTED_VALUE"""),"MTCGD") -> MTCGD | K7: =IFERROR(__xludf.DUMMYFUNCTION("""COMPUTED_VALUE"""),"Mastellone") -> Mastellone | L7: =IFERROR(__xludf.DUMMYFUNCTION("""COMPUTED_VALUE"""),46203.0) -> 46203 | M7: =IFERROR(__xludf.DUMMYFUNCTION("""COMPUTED_VALUE"""),0.1095) -> 0.1095 | N7: =IFERROR(__xludf.DUMMYFUNCTION("""COMPUTED_VALUE"""),101.5) -> 101.5 | O7: =IFERROR(__xludf.DUMMYFUNCTION("""COMPUTED_VALUE"""),0.09534594734110474) -> 0.095345947 | P7: =IFERROR(__xludf.DUMMYFUNCTION("""COMPUTED_VALUE"""),0.011899999999999999) -> 0.0119 | Q7: =IFERROR(__xludf.DUMMYFUNCTION("""COMPUTED_VALUE"""),0.7127086800293023) -> 0.71270868 | R7: =IFERROR(__xludf.DUMMYFUNCTION("""COMPUTED_VALUE"""),"Trimestral") -> Trimestral | S7: =IFERROR(__xludf.DUMMYFUNCTION("""COMPUTED_VALUE"""),"Bullet") -> Bullet | T7: =IFERROR(__xludf.DUMMYFUNCTION("""COMPUTED_VALUE"""),"NY") -> NY | U7: =IFERROR(__xludf.DUMMYFUNCTION("""COMPUTED_VALUE"""),1.0) -> 1 | V7: =IFERROR(__xludf.DUMMYFUNCTION("""COMPUTED_VALUE"""),83.0) -> 83 | W7: =IFERROR(__xludf.DUMMYFUNCTION("""COMPUTED_VALUE"""),1.0122290230494022) -> 1.012229 | AG7: =IFERROR(__xludf.DUMMYFUNCTION("""COMPUTED_VALUE"""),"Poco volumen") -> Poco volumen | AH7: =IFERROR(__xludf.DUMMYFUNCTION("""COMPUTED_VALUE"""),"Irsa") -> Irsa | AI7: =IFERROR(__xludf.DUMMYFUNCTION("""COMPUTED_VALUE"""),"IRCHD") -> IRCHD | AJ7: =IFERROR(__xludf.DUMMYFUNCTION("""COMPUTED_VALUE"""),"#NUM!") -> #NUM! | AK7: =IFERROR(__xludf.DUMMYFUNCTION("""COMPUTED_VALUE"""),104.5) -> 104.5 | AL7: =IFERROR(__xludf.DUMMYFUNCTION("""COMPUTED_VALUE"""),104.5) -> 104.5 | AM7: =IFERROR(__xludf.DUMMYFUNCTION("""COMPUTED_VALUE"""),"#NUM!") -> #NUM! | AN7: =IFERROR(__xludf.DUMMYFUNCTION("""COMPUTED_VALUE"""),"#N/A") -> #N/A | AO7: =IFERROR(__xludf.DUMMYFUNCTION("""COMPUTED_VALUE"""),"Argentina") -> Argentina | AP7: =IFERROR(__xludf.DUMMYFUNCTION("""COMPUTED_VALUE"""),"#N/A") -> #N/A | AQ7: =IFERROR(__xludf.DUMMYFUNCTION("""COMPUTED_VALUE"""),1.0) -> 1 | AR7: =IFERROR(__xludf.DUMMYFUNCTION("""COMPUTED_VALUE"""),"#N/A") -> #N/A
B8: IRCPD | C8: =VLOOKUP(B8,$J$6:$W$36,6,0) -> 0.080184559 | D8: =VLOOKUP(B8,$J$6:$W$36,8,0) -> 6.3420415 | E8: =VLOOKUP(B8,$J$6:$W$36,3,0) -> 49399 | F8: =1/D8 -> 0.15767793 | G8: =F8/$F$12 -> 0.14410687 | H8: =VLOOKUP(B8,$J$6:$W$36,12,0) -> 1 | J8: =IFERROR(__xludf.DUMMYFUNCTION("""COMPUTED_VALUE"""),"MGC9D") -> MGC9D | K8: =IFERROR(__xludf.DUMMYFUNCTION("""COMPUTED_VALUE"""),"Pampa Energia") -> Pampa Energia | L8: =IFERROR(__xludf.DUMMYFUNCTION("""COMPUTED_VALUE"""),46364.0) -> 46364 | M8: =IFERROR(__xludf.DUMMYFUNCTION("""COMPUTED_VALUE"""),0.095) -> 0.095 | N8: =IFERROR(__xludf.DUMMYFUNCTION("""COMPUTED_VALUE"""),71.2) -> 71.2 | O8: =IFERROR(__xludf.DUMMYFUNCTION("""COMPUTED_VALUE"""),0.04779948184699389) -> 0.047799482 | P8: =IFERROR(__xludf.DUMMYFUNCTION("""COMPUTED_VALUE"""),-0.0055000000000000005) -> -0.0055 | Q8: =IFERROR(__xludf.DUMMYFUNCTION("""COMPUTED_VALUE"""),0.6604825150010593) -> 0.66048251 | R8: =IFERROR(__xludf.DUMMYFUNCTION("""COMPUTED_VALUE"""),"Semestral") -> Semestral | S8: =IFERROR(__xludf.DUMMYFUNCTION("""COMPUTED_VALUE"""),"Sinkable") -> Sinkable | T8: =IFERROR(__xludf.DUMMYFUNCTION("""COMPUTED_VALUE"""),"NY") -> NY | U8: =IFERROR(__xludf.DUMMYFUNCTION("""COMPUTED_VALUE"""),1.0) -> 1 | V8: =IFERROR(__xludf.DUMMYFUNCTION("""COMPUTED_VALUE"""),61.0) -> 61 | W8: =IFERROR(__xludf.DUMMYFUNCTION("""COMPUTED_VALUE"""),1.029277921301921) -> 1.0292779 | X8: =IFERROR(__xludf.DUMMYFUNCTION("""COMPUTED_VALUE"""),"al30c") -> al30c | AG8: =IFERROR(__xludf.DUMMYFUNCTION("""COMPUTED_VALUE"""),"Poco volumen") -> Poco volumen | AH8: =IFERROR(__xludf.DUMMYFUNCTION("""COMPUTED_VALUE"""),"Pampa energia") -> Pampa energia | AI8: =IFERROR(__xludf.DUMMYFUNCTION("""COMPUTED_VALUE"""),"MGCJD") -> MGCJD | AJ8: =IFERROR(__xludf.DUMMYFUNCTION("""COMPUTED_VALUE"""),"#NUM!") -> #NUM! | AK8: =IFERROR(__xludf.DUMMYFUNCTION("""COMPUTED_VALUE"""),0.0) -> 0 | AL8: =IFERROR(__xludf.DUMMYFUNCTION("""COMPUTED_VALUE"""),0.0) -> 0 | AM8: =IFERROR(__xludf.DUMMYFUNCTION("""COMPUTED_VALUE"""),"#NUM!") -> #NUM! | AN8: =IFERROR(__xludf.DUMMYFUNCTION("""COMPUTED_VALUE"""),"#N/A") -> #N/A | AO8: =IFERROR(__xludf.DUMMYFUNCTION("""COMPUTED_VALUE"""),"Argentina") -> Argentina | AP8: =IFERROR(__xludf.DUMMYFUNCTION("""COMPUTED_VALUE"""),"#N/A") -> #N/A | AQ8: =IFERROR(__xludf.DUMMYFUNCTION("""COMPUTED_VALUE"""),1.0) -> 1 | AR8: =IFERROR(__xludf.DUMMYFUNCTION("""COMPUTED_VALUE"""),"#N/A") -> #N/A
B9: YM34D | C9: =VLOOKUP(B9,$J$6:$W$36,6,0) -> 0.086475232 | D9: =VLOOKUP(B9,$J$6:$W$36,8,0) -> 5.5734194 | E9: =VLOOKUP(B9,$J$6:$W$36,3,0) -> 48961 | F9: =1/D9 -> 0.17942307 | G9: =F9/$F$12 -> 0.16398044 | H9: =VLOOKUP(B9,$J$6:$W$36,12,0) -> 1 | J9: =IFERROR(__xludf.DUMMYFUNCTION("""COMPUTED_VALUE"""),"PNDCD") -> PNDCD | K9: =IFERROR(__xludf.DUMMYFUNCTION("""COMPUTED_VALUE"""),"Pan American Energy") -> Pan American Energy | L9: =IFERROR(__xludf.DUMMYFUNCTION("""COMPUTED_VALUE"""),46507.0) -> 46507 | M9: =IFERROR(__xludf.DUMMYFUNCTION("""COMPUTED_VALUE"""),0.0913) -> 0.0913 | N9: =IFERROR(__xludf.DUMMYFUNCTION("""COMPUTED_VALUE"""),86.5) -> 86.5 | O9: =IFERROR(__xludf.DUMMYFUNCTION("""COMPUTED_VALUE"""),0.03924871575088921) -> 0.039248716 | P9: =IFERROR(__xludf.DUMMYFUNCTION("""COMPUTED_VALUE"""),-0.017) -> -0.017 | Q9: =IFERROR(__xludf.DUMMYFUNCTION("""COMPUTED_VALUE"""),0.7822434263638092) -> 0.78224343 | R9: =IFERROR(__xludf.DUMMYFUNCTION("""COMPUTED_VALUE"""),"Semestral") -> Semestral | S9: =IFERROR(__xludf.DUMMYFUNCTION("""COMPUTED_VALUE"""),"Sinkable") -> Sinkable | T9: =IFERROR(__xludf.DUMMYFUNCTION("""COMPUTED_VALUE"""),"NY") -> NY | U9: =IFERROR(__xludf.DUMMYFUNCTION("""COMPUTED_VALUE"""),1000.0) -> 1000 | V9: =IFERROR(__xludf.DUMMYFUNCTION("""COMPUTED_VALUE"""),22.0) -> 22 | W9: =IFERROR(__xludf.DUMMYFUNCTION("""COMPUTED_VALUE"""),1.0386023893858438) -> 1.0386024 | X9: =IFERROR(__xludf.DUMMYFUNCTION("""COMPUTED_VALUE"""),"al30d") -> al30d | AH9: =IFERROR(__xludf.DUMMYFUNCTION("""COMPUTED_VALUE"""),"Pampa energia") -> Pampa energia | AI9: =IFERROR(__xludf.DUMMYFUNCTION("""COMPUTED_VALUE"""),"MGCHD") -> MGCHD | AJ9: =IFERROR(__xludf.DUMMYFUNCTION("""COMPUTED_VALUE"""),0.24190855575300954) -> 0.24190856 | AK9: =IFERROR(__xludf.DUMMYFUNCTION("""COMPUTED_VALUE"""),100.95) -> 100.95 | AL9: =IFERROR(__xludf.DUMMYFUNCTION("""COMPUTED_VALUE"""),100.95) -> 100.95 | AM9: =IFERROR(__xludf.DUMMYFUNCTION("""COMPUTED_VALUE"""),0.06391983923288115) -> 0.063919839 | AN9: =IFERROR(__xludf.DUMMYFUNCTION("""COMPUTED_VALUE"""),45965.0) -> 45965 | AO9: =IFERROR(__xludf.DUMMYFUNCTION("""COMPUTED_VALUE"""),"Argentina") -> Argentina | AP9: =IFERROR(__xludf.DUMMYFUNCTION("""COMPUTED_VALUE"""),"Semestral") -> Semestral | AQ9: =IFERROR(__xludf.DUMMYFUNCTION("""COMPUTED_VALUE"""),1.0) -> 1 | AR9: =IFERROR(__xludf.DUMMYFUNCTION("""COMPUTED_VALUE"""),"Bullet") -> Bullet
B10: TLCMD | C10: =VLOOKUP(B10,$J$6:$W$36,6,0) -> 0.092867481 | D10: =VLOOKUP(B10,$J$6:$W$36,8,0) -> 3.8979568 | E10: =VLOOKUP(B10,$J$6:$W$36,3,0) -> 48047 | F10: =1/D10 -> 0.25654466 | G10: =F10/$F$12 -> 0.23446432 | H10: =VLOOKUP(B10,$J$6:$W$36,12,0) -> 1000 | J10: =IFERROR(__xludf.DUMMYFUNCTION("""COMPUTED_VALUE"""),"YCAMD") -> YCAMD | K10: =IFERROR(__xludf.DUMMYFUNCTION("""COMPUTED_VALUE"""),"YPF") -> YPF | L10: =IFERROR(__xludf.DUMMYFUNCTION("""COMPUTED_VALUE"""),46589.0) -> 46589 | M10: =IFERROR(__xludf.DUMMYFUNCTION("""COMPUTED_VALUE"""),0.0695) -> 0.0695 | N10: =IFERROR(__xludf.DUMMYFUNCTION("""COMPUTED_VALUE"""),102.25) -> 102.25 | O10: =IFERROR(__xludf.DUMMYFUNCTION("""COMPUTED_VALUE"""),0.06619237840504184) -> 0.066192378 | P10: =IFERROR(__xludf.DUMMYFUNCTION("""COMPUTED_VALUE"""),0.0) -> 0 | Q10: =IFERROR(__xludf.DUMMYFUNCTION("""COMPUTED_VALUE"""),1.7036405613044903) -> 1.7036406 | R10: =IFERROR(__xludf.DUMMYFUNCTION("""COMPUTED_VALUE"""),"Semestral") -> Semestral | S10: =IFERROR(__xludf.DUMMYFUNCTION("""COMPUTED_VALUE"""),"Bullet") -> Bullet | T10: =IFERROR(__xludf.DUMMYFUNCTION("""COMPUTED_VALUE"""),"NY") -> NY | U10: =IFERROR(__xludf.DUMMYFUNCTION("""COMPUTED_VALUE"""),10000.0) -> 10000 | V10: =IFERROR(__xludf.DUMMYFUNCTION("""COMPUTED_VALUE"""),105.0) -> 105 | W10: =IFERROR(__xludf.DUMMYFUNCTION("""COMPUTED_VALUE"""),1.006948243790349) -> 1.0069482 | AG10: =IFERROR(__xludf.DUMMYFUNCTION("""COMPUTED_VALUE"""),"Poco volumen") -> Poco volumen | AH10: =IFERROR(__xludf.DUMMYFUNCTION("""COMPUTED_VALUE"""),"Arcor") -> Arcor | AI10: =IFERROR(__xludf.DUMMYFUNCTION("""COMPUTED_VALUE"""),"RCCMD") -> RCCMD | AJ10: =IFERROR(__xludf.DUMMYFUNCTION("""COMPUTED_VALUE"""),0.02144906447461636) -> 0.021449064 | AK10: =IFERROR(__xludf.DUMMYFUNCTION("""COMPUTED_VALUE"""),101.5) -> 101.5 | AL10: =IFERROR(__xludf.DUMMYFUNCTION("""COMPUTED_VALUE"""),101.5) -> 101.5 | AM10: =IFERROR(__xludf.DUMMYFUNCTION("""COMPUTED_VALUE"""),0.119275557329253) -> 0.11927556 | AN10: =IFERROR(__xludf.DUMMYFUNCTION("""COMPUTED_VALUE"""),45983.0) -> 45983 | AO10: =IFERROR(__xludf.DUMMYFUNCTION("""COMPUTED_VALUE"""),"Argentina") -> Argentina | AP10: =IFERROR(__xludf.DUMMYFUNCTION("""COMPUTED_VALUE"""),"Semestral") -> Semestral | AQ10: =IFERROR(__xludf.DUMMYFUNCTION("""COMPUTED_VALUE"""),1.0) -> 1 | AR10: =IFERROR(__xludf.DUMMYFUNCTION("""COMPUTED_VALUE"""),"Bullet") -> Bullet
J11: =IFERROR(__xludf.DUMMYFUNCTION("""COMPUTED_VALUE"""),"GNCXD") -> GNCXD | K11: =IFERROR(__xludf.DUMMYFUNCTION("""COMPUTED_VALUE"""),"Genneia") -> Genneia | L11: =IFERROR(__xludf.DUMMYFUNCTION("""COMPUTED_VALUE"""),46632.0) -> 46632 | M11: =IFERROR(__xludf.DUMMYFUNCTION("""COMPUTED_VALUE"""),0.0875) -> 0.0875 | N11: =IFERROR(__xludf.DUMMYFUNCTION("""COMPUTED_VALUE"""),40.89) -> 40.89 | O11: =IFERROR(__xludf.DUMMYFUNCTION("""COMPUTED_VALUE"""),0.07634798914958861) -> 0.076347989 | P11: =IFERROR(__xludf.DUMMYFUNCTION("""COMPUTED_VALUE"""),0.0070999999999999995) -> 0.0071 | Q11: =IFERROR(__xludf.DUMMYFUNCTION("""COMPUTED_VALUE"""),1.1154498500735563) -> 1.1154499 | R11: =IFERROR(__xludf.DUMMYFUNCTION("""COMPUTED_VALUE"""),"Semestral") -> Semestral | S11: =IFERROR(__xludf.DUMMYFUNCTION("""COMPUTED_VALUE"""),"Sinkable") -> Sinkable | T11: =IFERROR(__xludf.DUMMYFUNCTION("""COMPUTED_VALUE"""),"NY") -> NY | U11: =IFERROR(__xludf.DUMMYFUNCTION("""COMPUTED_VALUE"""),1000.0) -> 1000 | V11: =IFERROR(__xludf.DUMMYFUNCTION("""COMPUTED_VALUE"""),145.0) -> 145 | W11: =IFERROR(__xludf.DUMMYFUNCTION("""COMPUTED_VALUE"""),0.8105110292852472) -> 0.81051103 | AH11: =IFERROR(__xludf.DUMMYFUNCTION("""COMPUTED_VALUE"""),"Tarjeta Naranja") -> Tarjeta Naranja | AI11: =IFERROR(__xludf.DUMMYFUNCTION("""COMPUTED_VALUE"""),"TN63D") -> TN63D | AJ11: =IFERROR(__xludf.DUMMYFUNCTION("""COMPUTED_VALUE"""),"#NUM!") -> #NUM! | AK11: =IFERROR(__xludf.DUMMYFUNCTION("""COMPUTED_VALUE"""),101.25) -> 101.25 | AL11: =IFERROR(__xludf.DUMMYFUNCTION("""COMPUTED_VALUE"""),101.25) -> 101.25 | AM11: =IFERROR(__xludf.DUMMYFUNCTION("""COMPUTED_VALUE"""),"#NUM!") -> #NUM! | AN11: =IFERROR(__xludf.DUMMYFUNCTION("""COMPUTED_VALUE"""),45989.0) -> 45989 | AO11: =IFERROR(__xludf.DUMMYFUNCTION("""COMPUTED_VALUE"""),"Argentina") -> Argentina | AP11: =IFERROR(__xludf.DUMMYFUNCTION("""COMPUTED_VALUE"""),"Trimestral") -> Trimestral | AQ11: =IFERROR(__xludf.DUMMYFUNCTION("""COMPUTED_VALUE"""),1.0) -> 1 | AR11: =IFERROR(__xludf.DUMMYFUNCTION("""COMPUTED_VALUE"""),"Sinkable") -> Sinkable
F12: =SUM(F6:F11) -> 1.0941736 | J12: =IFERROR(__xludf.DUMMYFUNCTION("""COMPUTED_VALUE"""),"IRCFD") -> IRCFD | K12: =IFERROR(__xludf.DUMMYFUNCTION("""COMPUTED_VALUE"""),"Irsa") -> Irsa | L12: =IFERROR(__xludf.DUMMYFUNCTION("""COMPUTED_VALUE"""),46926.0) -> 46926 | M12: =IFERROR(__xludf.DUMMYFUNCTION("""COMPUTED_VALUE"""),0.0875) -> 0.0875 | N12: =IFERROR(__xludf.DUMMYFUNCTION("""COMPUTED_VALUE"""),69.79) -> 69.79 | O12: =IFERROR(__xludf.DUMMYFUNCTION("""COMPUTED_VALUE"""),0.060872134275639526) -> 0.060872134 | P12: =IFERROR(__xludf.DUMMYFUNCTION("""COMPUTED_VALUE"""),-0.0012) -> -0.0012 | Q12: =IFERROR(__xludf.DUMMYFUNCTION("""COMPUTED_VALUE"""),1.7631168587831665) -> 1.7631169 | R12: =IFERROR(__xludf.DUMMYFUNCTION("""COMPUTED_VALUE"""),"Semestral") -> Semestral | S12: =IFERROR(__xludf.DUMMYFUNCTION("""COMPUTED_VALUE"""),"Sinkable") -> Sinkable | T12: =IFERROR(__xludf.DUMMYFUNCTION("""COMPUTED_VALUE"""),"NY") -> NY | U12: =IFERROR(__xludf.DUMMYFUNCTION("""COMPUTED_VALUE"""),1.0) -> 1 | V12: =IFERROR(__xludf.DUMMYFUNCTION("""COMPUTED_VALUE"""),75.0) -> 75 | W12: =IFERROR(__xludf.DUMMYFUNCTION("""COMPUTED_VALUE"""),1.0459810730148655) -> 1.0459811 | AG12: =IFERROR(__xludf.DUMMYFUNCTION("""COMPUTED_VALUE"""),"Poco volumen") -> Poco volumen | AH12: =IFERROR(__xludf.DUMMYFUNCTION("""COMPUTED_VALUE"""),"Loma Negra") -> Loma Negra | AI12: =IFERROR(__xludf.DUMMYFUNCTION("""COMPUTED_VALUE"""),"LOC2D") -> LOC2D | AJ12: =IFERROR(__xludf.DUMMYFUNCTION("""COMPUTED_VALUE"""),0.16231005781614452) -> 0.16231006 | AK12: =IFERROR(__xludf.DUMMYFUNCTION("""COMPUTED_VALUE"""),100.2) -> 100.2 | AL12: =IFERROR(__xludf.DUMMYFUNCTION("""COMPUTED_VALUE"""),100.2) -> 100.2 | AM12: =IFERROR(__xludf.DUMMYFUNCTION("""COMPUTED_VALUE"""),0.18551071432542224) -> 0.18551071 | AN12: =IFERROR(__xludf.DUMMYFUNCTION("""COMPUTED_VALUE"""),"#N/A") -> #N/A | AO12: =IFERROR(__xludf.DUMMYFUNCTION("""COMPUTED_VALUE"""),"Argentina") -> Argentina | AP12: =IFERROR(__xludf.DUMMYFUNCTION("""COMPUTED_VALUE"""),"#N/A") -> #N/A | AQ12: =IFERROR(__xludf.DUMMYFUNCTION("""COMPUTED_VALUE"""),1.0) -> 1 | AR12: =IFERROR(__xludf.DUMMYFUNCTION("""COMPUTED_VALUE"""),"#N/A") -> #N/A
J13: =IFERROR(__xludf.DUMMYFUNCTION("""COMPUTED_VALUE"""),"CAC5D") -> CAC5D | K13: =IFERROR(__xludf.DUMMYFUNCTION("""COMPUTED_VALUE"""),"Capex") -> Capex | L13: =IFERROR(__xludf.DUMMYFUNCTION("""COMPUTED_VALUE"""),46990.0) -> 46990 | M13: =IFERROR(__xludf.DUMMYFUNCTION("""COMPUTED_VALUE"""),0.0925) -> 0.0925 | N13: =IFERROR(__xludf.DUMMYFUNCTION("""COMPUTED_VALUE"""),75.72) -> 75.72 | O13: =IFERROR(__xludf.DUMMYFUNCTION("""COMPUTED_VALUE"""),0.09544429307870247) -> 0.095444293 | P13: =IFERROR(__xludf.DUMMYFUNCTION("""COMPUTED_VALUE"""),-0.0076) -> -0.0076 | Q13: =IFERROR(__xludf.DUMMYFUNCTION("""COMPUTED_VALUE"""),1.5251915772927287) -> 1.5251916 | R13: =IFERROR(__xludf.DUMMYFUNCTION("""COMPUTED_VALUE"""),"Semestral") -> Semestral | S13: =IFERROR(__xludf.DUMMYFUNCTION("""COMPUTED_VALUE"""),"Sinkable") -> Sinkable | T13: =IFERROR(__xludf.DUMMYFUNCTION("""COMPUTED_VALUE"""),"NY") -> NY | U13: =IFERROR(__xludf.DUMMYFUNCTION("""COMPUTED_VALUE"""),1.0) -> 1 | V13: =IFERROR(__xludf.DUMMYFUNCTION("""COMPUTED_VALUE"""),140.0) -> 140 | W13: =IFERROR(__xludf.DUMMYFUNCTION("""COMPUTED_VALUE"""),0.855479941745002) -> 0.85547994 | AH13: =IFERROR(__xludf.DUMMYFUNCTION("""COMPUTED_VALUE"""),"YPF") -> YPF | AI13: =IFERROR(__xludf.DUMMYFUNCTION("""COMPUTED_VALUE"""),"YMCQD") -> YMCQD | AJ13: =IFERROR(__xludf.DUMMYFUNCTION("""COMPUTED_VALUE"""),0.0881540943546613) -> 0.088154094 | AK13: =IFERROR(__xludf.DUMMYFUNCTION("""COMPUTED_VALUE"""),100.4) -> 100.4 | AL13: =IFERROR(__xludf.DUMMYFUNCTION("""COMPUTED_VALUE"""),100.4) -> 100.4 | AM13: =IFERROR(__xludf.DUMMYFUNCTION("""COMPUTED_VALUE"""),0.32967463211111653) -> 0.32967463 | AN13: =IFERROR(__xludf.DUMMYFUNCTION("""COMPUTED_VALUE"""),46066.0) -> 46066 | AO13: =IFERROR(__xludf.DUMMYFUNCTION("""COMPUTED_VALUE"""),"Argentina") -> Argentina | AP13: =IFERROR(__xludf.DUMMYFUNCTION("""COMPUTED_VALUE"""),"Semestral") -> Semestral | AQ13: =IFERROR(__xludf.DUMMYFUNCTION("""COMPUTED_VALUE"""),1.0) -> 1 | AR13: =IFERROR(__xludf.DUMMYFUNCTION("""COMPUTED_VALUE"""),"Bullet") -> Bullet
J14: =IFERROR(__xludf.DUMMYFUNCTION("""COMPUTED_VALUE"""),"BYCHD") -> BYCHD | K14: =IFERROR(__xludf.DUMMYFUNCTION("""COMPUTED_VALUE"""),"Galicia") -> Galicia | L14: =IFERROR(__xludf.DUMMYFUNCTION("""COMPUTED_VALUE"""),47036.0) -> 47036 | M14: =IFERROR(__xludf.DUMMYFUNCTION("""COMPUTED_VALUE"""),0.0775) -> 0.0775 | N14: =IFERROR(__xludf.DUMMYFUNCTION("""COMPUTED_VALUE"""),105.8) -> 105.8 | O14: =IFERROR(__xludf.DUMMYFUNCTION("""COMPUTED_VALUE"""),0.07149077584364663) -> 0.071490776 | P14: =IFERROR(__xludf.DUMMYFUNCTION("""COMPUTED_VALUE"""),-0.0014000000000000002) -> -0.0014 | Q14: =IFERROR(__xludf.DUMMYFUNCTION("""COMPUTED_VALUE"""),2.6701754812302956) -> 2.6701755 | R14: =IFERROR(__xludf.DUMMYFUNCTION("""COMPUTED_VALUE"""),"Semestral") -> Semestral | S14: =IFERROR(__xludf.DUMMYFUNCTION("""COMPUTED_VALUE"""),"Bullet") -> Bullet | T14: =IFERROR(__xludf.DUMMYFUNCTION("""COMPUTED_VALUE"""),"NY") -> NY | U14: =IFERROR(__xludf.DUMMYFUNCTION("""COMPUTED_VALUE"""),2000.0) -> 2000 | V14: =IFERROR(__xludf.DUMMYFUNCTION("""COMPUTED_VALUE"""),2.0) -> 2 | W14: =IFERROR(__xludf.DUMMYFUNCTION("""COMPUTED_VALUE"""),1.0181098889349247) -> 1.0181099 | AG14: =IFERROR(__xludf.DUMMYFUNCTION("""COMPUTED_VALUE"""),"Poco volumen") -> Poco volumen | AH14: =IFERROR(__xludf.DUMMYFUNCTION("""COMPUTED_VALUE"""),"CGC") -> CGC | AI14: =IFERROR(__xludf.DUMMYFUNCTION("""COMPUTED_VALUE"""),"CP34D") -> CP34D | AJ14: =IFERROR(__xludf.DUMMYFUNCTION("""COMPUTED_VALUE"""),0.2934021780710768) -> 0.29340218 | AK14: =IFERROR(__xludf.DUMMYFUNCTION("""COMPUTED_VALUE"""),94.0) -> 94 | AL14: =IFERROR(__xludf.DUMMYFUNCTION("""COMPUTED_VALUE"""),94.0) -> 94 | AM14: =IFERROR(__xludf.DUMMYFUNCTION("""COMPUTED_VALUE"""),0.3300356913502398) -> 0.33003569 | AN14: =IFERROR(__xludf.DUMMYFUNCTION("""COMPUTED_VALUE"""),46076.0) -> 46076 | AO14: =IFERROR(__xludf.DUMMYFUNCTION("""COMPUTED_VALUE"""),"Argentina") -> Argentina | AP14: =IFERROR(__xludf.DUMMYFUNCTION("""COMPUTED_VALUE"""),"Semestral") -> Semestral | AQ14: =IFERROR(__xludf.DUMMYFUNCTION("""COMPUTED_VALUE"""),1.0) -> 1 | AR14: =IFERROR(__xludf.DUMMYFUNCTION("""COMPUTED_VALUE"""),"Bullet") -> Bullet
H15: =C8/D8 -> 0.012643336 | J15: =IFERROR(__xludf.DUMMYFUNCTION("""COMPUTED_VALUE"""),"BACGD") -> BACGD | K15: =IFERROR(__xludf.DUMMYFUNCTION("""COMPUTED_VALUE"""),"Banco Macro") -> Banco Macro | L15: =IFERROR(__xludf.DUMMYFUNCTION("""COMPUTED_VALUE"""),47292.0) -> 47292 | M15: =IFERROR(__xludf.DUMMYFUNCTION("""COMPUTED_VALUE"""),0.08) -> 0.08 | N15: =IFERROR(__xludf.DUMMYFUNCTION("""COMPUTED_VALUE"""),102.25) -> 102.25 | O15: =IFERROR(__xludf.DUMMYFUNCTION("""COMPUTED_VALUE"""),0.08185903892745386) -> 0.081859039 | P15: =IFERROR(__xludf.DUMMYFUNCTION("""COMPUTED_VALUE"""),0.0024) -> 0.0024 | Q15: =IFERROR(__xludf.DUMMYFUNCTION("""COMPUTED_VALUE"""),3.2393086080317754) -> 3.2393086 | R15: =IFERROR(__xludf.DUMMYFUNCTION("""COMPUTED_VALUE"""),"Semestral") -> Semestral | S15: =IFERROR(__xludf.DUMMYFUNCTION("""COMPUTED_VALUE"""),"Bullet") -> Bullet | T15: =IFERROR(__xludf.DUMMYFUNCTION("""COMPUTED_VALUE"""),"NY") -> NY | U15: =IFERROR(__xludf.DUMMYFUNCTION("""COMPUTED_VALUE"""),1000.0) -> 1000 | V15: =IFERROR(__xludf.DUMMYFUNCTION("""COMPUTED_VALUE"""),76.0) -> 76 | W15: =IFERROR(__xludf.DUMMYFUNCTION("""COMPUTED_VALUE"""),0.99853515625) -> 0.99853516 | AH15: =IFERROR(__xludf.DUMMYFUNCTION("""COMPUTED_VALUE"""),"Cresud") -> Cresud | AI15: =IFERROR(__xludf.DUMMYFUNCTION("""COMPUTED_VALUE"""),"CS38D") -> CS38D | AJ15: =IFERROR(__xludf.DUMMYFUNCTION("""COMPUTED_VALUE"""),0.09214149546043073) -> 0.092141495 | AK15: =IFERROR(__xludf.DUMMYFUNCTION("""COMPUTED_VALUE"""),101.75) -> 101.75 | AL15: =IFERROR(__xludf.DUMMYFUNCTION("""COMPUTED_VALUE"""),101.75) -> 101.75 | AM15: =IFERROR(__xludf.DUMMYFUNCTION("""COMPUTED_VALUE"""),0.37433901956556387) -> 0.37433902 | AN15: =IFERROR(__xludf.DUMMYFUNCTION("""COMPUTED_VALUE"""),"#N/A") -> #N/A | AO15: =IFERROR(__xludf.DUMMYFUNCTION("""COMPUTED_VALUE"""),"Argentina") -> Argentina | AP15: =IFERROR(__xludf.DUMMYFUNCTION("""COMPUTED_VALUE"""),"#N/A") -> #N/A | AQ15: =IFERROR(__xludf.DUMMYFUNCTION("""COMPUTED_VALUE"""),1.0) -> 1 | AR15: =IFERROR(__xludf.DUMMYFUNCTION("""COMPUTED_VALUE"""),"#N/A") -> #N/A
J16: =IFERROR(__xludf.DUMMYFUNCTION("""COMPUTED_VALUE"""),"YMCID") -> YMCID | K16: =IFERROR(__xludf.DUMMYFUNCTION("""COMPUTED_VALUE"""),"YPF") -> YPF | L16: =IFERROR(__xludf.DUMMYFUNCTION("""COMPUTED_VALUE"""),47299.0) -> 47299 | M16: =IFERROR(__xludf.DUMMYFUNCTION("""COMPUTED_VALUE"""),0.09) -> 0.09 | N16: =IFERROR(__xludf.DUMMYFUNCTION("""COMPUTED_VALUE"""),106.95) -> 106.95 | O16: =IFERROR(__xludf.DUMMYFUNCTION("""COMPUTED_VALUE"""),0.06887414421954087) -> 0.068874144 | P16: =IFERROR(__xludf.DUMMYFUNCTION("""COMPUTED_VALUE"""),0.0042) -> 0.0042 | Q16: =IFERROR(__xludf.DUMMYFUNCTION("""COMPUTED_VALUE"""),2.028662833438036) -> 2.0286628 | R16: =IFERROR(__xludf.DUMMYFUNCTION("""COMPUTED_VALUE"""),"Semestral") -> Semestral | S16: =IFERROR(__xludf.DUMMYFUNCTION("""COMPUTED_VALUE"""),"Sinkable") -> Sinkable | T16: =IFERROR(__xludf.DUMMYFUNCTION("""COMPUTED_VALUE"""),"NY") -> NY | U16: =IFERROR(__xludf.DUMMYFUNCTION("""COMPUTED_VALUE"""),1.0) -> 1 | V16: =IFERROR(__xludf.DUMMYFUNCTION("""COMPUTED_VALUE"""),83.0) -> 83 | W16: =IFERROR(__xludf.DUMMYFUNCTION("""COMPUTED_VALUE"""),1.0431602048280906) -> 1.0431602 | AG16: =IFERROR(__xludf.DUMMYFUNCTION("""COMPUTED_VALUE"""),"Poco volumen") -> Poco volumen | AH16: =IFERROR(__xludf.DUMMYFUNCTION("""COMPUTED_VALUE"""),"Loma Negra") -> Loma Negra | AI16: =IFERROR(__xludf.DUMMYFUNCTION("""COMPUTED_VALUE"""),"LOC3D") -> LOC3D | AJ16: =IFERROR(__xludf.DUMMYFUNCTION("""COMPUTED_VALUE"""),0.024811236223566707) -> 0.024811236 | AK16: =IFERROR(__xludf.DUMMYFUNCTION("""COMPUTED_VALUE"""),102.65) -> 102.65 | AL16: =IFERROR(__xludf.DUMMYFUNCTION("""COMPUTED_VALUE"""),102.65) -> 102.65 | AM16: =IFERROR(__xludf.DUMMYFUNCTION("""COMPUTED_VALUE"""),0.4140727275747961) -> 0.41407273 | AN16: =IFERROR(__xludf.DUMMYFUNCTION("""COMPUTED_VALUE"""),46092.0) -> 46092 | AO16: =IFERROR(__xludf.DUMMYFUNCTION("""COMPUTED_VALUE"""),"Argentina") -> Argentina | AP16: =IFERROR(__xludf.DUMMYFUNCTION("""COMPUTED_VALUE"""),"Semestral") -> Semestral | AQ16: =IFERROR(__xludf.DUMMYFUNCTION("""COMPUTED_VALUE"""),50.0) -> 50 | AR16: =IFERROR(__xludf.DUMMYFUNCTION("""COMPUTED_VALUE"""),"Bullet") -> Bullet
B17: Agresivo | J17: =IFERROR(__xludf.DUMMYFUNCTION("""COMPUTED_VALUE"""),"DNC7D") -> DNC7D | K17: =IFERROR(__xludf.DUMMYFUNCTION("""COMPUTED_VALUE"""),"Edenor") -> Edenor | L17: =IFERROR(__xludf.DUMMYFUNCTION("""COMPUTED_VALUE"""),47780.0) -> 47780 | M17: =IFERROR(__xludf.DUMMYFUNCTION("""COMPUTED_VALUE"""),0.0975) -> 0.0975 | N17: =IFERROR(__xludf.DUMMYFUNCTION("""COMPUTED_VALUE"""),100.45) -> 100.45 | O17: =IFERROR(__xludf.DUMMYFUNCTION("""COMPUTED_VALUE"""),0.11324817794294945) -> 0.11324818 | P17: =IFERROR(__xludf.DUMMYFUNCTION("""COMPUTED_VALUE"""),-0.0024) -> -0.0024 | Q17: =IFERROR(__xludf.DUMMYFUNCTION("""COMPUTED_VALUE"""),3.2704911426029253) -> 3.2704911 | R17: =IFERROR(__xludf.DUMMYFUNCTION("""COMPUTED_VALUE"""),"Semestral") -> Semestral | S17: =IFERROR(__xludf.DUMMYFUNCTION("""COMPUTED_VALUE"""),"Sinkable") -> Sinkable | T17: =IFERROR(__xludf.DUMMYFUNCTION("""COMPUTED_VALUE"""),"NY") -> NY | U17: =IFERROR(__xludf.DUMMYFUNCTION("""COMPUTED_VALUE"""),100.0) -> 100 | V17: =IFERROR(__xludf.DUMMYFUNCTION("""COMPUTED_VALUE"""),16.0) -> 16 | W17: =IFERROR(__xludf.DUMMYFUNCTION("""COMPUTED_VALUE"""),0.9607843137254902) -> 0.96078431 | AG17: =IFERROR(__xludf.DUMMYFUNCTION("""COMPUTED_VALUE"""),"Poco volumen") -> Poco volumen | AH17: =IFERROR(__xludf.DUMMYFUNCTION("""COMPUTED_VALUE"""),"Central Puerto") -> Central Puerto | AI17: =IFERROR(__xludf.DUMMYFUNCTION("""COMPUTED_VALUE"""),"NPCAD") -> NPCAD | AJ17: =IFERROR(__xludf.DUMMYFUNCTION("""COMPUTED_VALUE"""),0.01070915154750966) -> 0.010709152 | AK17: =IFERROR(__xludf.DUMMYFUNCTION("""COMPUTED_VALUE"""),103.0) -> 103 | AL17: =IFERROR(__xludf.DUMMYFUNCTION("""COMPUTED_VALUE"""),103.0) -> 103 | AM17: =IFERROR(__xludf.DUMMYFUNCTION("""COMPUTED_VALUE"""),0.42512694791096006) -> 0.42512695 | AN17: =IFERROR(__xludf.DUMMYFUNCTION("""COMPUTED_VALUE"""),46095.0) -> 46095 | AO17: =IFERROR(__xludf.DUMMYFUNCTION("""COMPUTED_VALUE"""),"Argentina") -> Argentina | AP17: =IFERROR(__xludf.DUMMYFUNCTION("""COMPUTED_VALUE"""),"Semestral") -> Semestral | AQ17: =IFERROR(__xludf.DUMMYFUNCTION("""COMPUTED_VALUE"""),1.0) -> 1 | AR17: =IFERROR(__xludf.DUMMYFUNCTION("""COMPUTED_VALUE"""),"Bullet") -> Bullet
B18: =B5 -> Central Puerto | C18: =C5 -> TIR | D18: M,Duration | E18: Vto | F18: M,Duration | G18: Weight | H18: Lamina | J18: =IFERROR(__xludf.DUMMYFUNCTION("""COMPUTED_VALUE"""),"RUCDD") -> RUCDD | K18: =IFERROR(__xludf.DUMMYFUNCTION("""COMPUTED_VALUE"""),"MSU Energy") -> MSU Energy | L18: =IFERROR(__xludf.DUMMYFUNCTION("""COMPUTED_VALUE"""),47822.0) -> 47822 | M18: =IFERROR(__xludf.DUMMYFUNCTION("""COMPUTED_VALUE"""),0.0975) -> 0.0975 | N18: =IFERROR(__xludf.DUMMYFUNCTION("""COMPUTED_VALUE"""),91.2) -> 91.2 | O18: =IFERROR(__xludf.DUMMYFUNCTION("""COMPUTED_VALUE"""),0.1381500807351918) -> 0.13815008 | P18: =IFERROR(__xludf.DUMMYFUNCTION("""COMPUTED_VALUE"""),-0.013999999999999999) -> -0.014 | Q18: =IFERROR(__xludf.DUMMYFUNCTION("""COMPUTED_VALUE"""),3.629989032153328) -> 3.629989 | R18: =IFERROR(__xludf.DUMMYFUNCTION("""COMPUTED_VALUE"""),"Semestral") -> Semestral | S18: =IFERROR(__xludf.DUMMYFUNCTION("""COMPUTED_VALUE"""),"Sinkable") -> Sinkable | T18: =IFERROR(__xludf.DUMMYFUNCTION("""COMPUTED_VALUE"""),"NY") -> NY | U18: =IFERROR(__xludf.DUMMYFUNCTION("""COMPUTED_VALUE"""),1.0) -> 1 | V18: =IFERROR(__xludf.DUMMYFUNCTION("""COMPUTED_VALUE"""),58.0) -> 58 | W18: =IFERROR(__xludf.DUMMYFUNCTION("""COMPUTED_VALUE"""),0.8819049921431162) -> 0.88190499 | AH18: =IFERROR(__xludf.DUMMYFUNCTION("""COMPUTED_VALUE"""),"Tecpetrol") -> Tecpetrol | AI18: =IFERROR(__xludf.DUMMYFUNCTION("""COMPUTED_VALUE"""),"TTC7D") -> TTC7D | AJ18: =IFERROR(__xludf.DUMMYFUNCTION("""COMPUTED_VALUE"""),0.07945945525153902) -> 0.079459455 | AK18: =IFERROR(__xludf.DUMMYFUNCTION("""COMPUTED_VALUE"""),101.85) -> 101.85 | AL18: =IFERROR(__xludf.DUMMYFUNCTION("""COMPUTED_VALUE"""),101.85) -> 101.85 | AM18: =IFERROR(__xludf.DUMMYFUNCTION("""COMPUTED_VALUE"""),0.50010985450224) -> 0.50010985 | AN18: =IFERROR(__xludf.DUMMYFUNCTION("""COMPUTED_VALUE"""),46134.0) -> 46134 | AO18: =IFERROR(__xludf.DUMMYFUNCTION("""COMPUTED_VALUE"""),"Argentina") -> Argentina | AP18: =IFERROR(__xludf.DUMMYFUNCTION("""COMPUTED_VALUE"""),"Semestral") -> Semestral | AQ18: =IFERROR(__xludf.DUMMYFUNCTION("""COMPUTED_VALUE"""),1.0) -> 1 | AR18: =IFERROR(__xludf.DUMMYFUNCTION("""COMPUTED_VALUE"""),"Bullet") -> Bullet
B19: DNC7D | C19: =VLOOKUP(B19,$K$6:$T$36,2,0) -> #N/A | D19: =VLOOKUP(B19,$K$6:$T$36,5,0) -> #N/A | E19: =VLOOKUP(B19,$K$6:$T$36,6,0) -> #N/A | F19: =D19 -> #N/A | G19: =F19/$G$23 -> #N/A | H19: =VLOOKUP(B19,$K$6:$T$36,9,0) -> #N/A | J19: =IFERROR(__xludf.DUMMYFUNCTION("""COMPUTED_VALUE"""),"TLCMD") -> TLCMD | K19: =IFERROR(__xludf.DUMMYFUNCTION("""COMPUTED_VALUE"""),"Telecom") -> Telecom | L19: =IFERROR(__xludf.DUMMYFUNCTION("""COMPUTED_VALUE"""),48047.0) -> 48047 | M19: =IFERROR(__xludf.DUMMYFUNCTION("""COMPUTED_VALUE"""),0.095) -> 0.095 | N19: =IFERROR(__xludf.DUMMYFUNCTION("""COMPUTED_VALUE"""),103.7) -> 103.7 | O19: =IFERROR(__xludf.DUMMYFUNCTION("""COMPUTED_VALUE"""),0.0928674814932401) -> 0.092867481 | P19: =IFERROR(__xludf.DUMMYFUNCTION("""COMPUTED_VALUE"""),-0.0028000000000000004) -> -0.0028 | Q19: =IFERROR(__xludf.DUMMYFUNCTION("""COMPUTED_VALUE"""),3.8979568160861335) -> 3.8979568 | R19: =IFERROR(__xludf.DUMMYFUNCTION("""COMPUTED_VALUE"""),"Semestral") -> Semestral | S19: =IFERROR(__xludf.DUMMYFUNCTION("""COMPUTED_VALUE"""),"Sinkable") -> Sinkable | T19: =IFERROR(__xludf.DUMMYFUNCTION("""COMPUTED_VALUE"""),"NY") -> NY | U19: =IFERROR(__xludf.DUMMYFUNCTION("""COMPUTED_VALUE"""),1000.0) -> 1000 | V19: =IFERROR(__xludf.DUMMYFUNCTION("""COMPUTED_VALUE"""),102.0) -> 102 | W19: =IFERROR(__xludf.DUMMYFUNCTION("""COMPUTED_VALUE"""),1.014773638501162) -> 1.0147736 | AH19: =IFERROR(__xludf.DUMMYFUNCTION("""COMPUTED_VALUE"""),"YPF") -> YPF | AI19: =IFERROR(__xludf.DUMMYFUNCTION("""COMPUTED_VALUE"""),"YMCVD") -> YMCVD | AJ19: =IFERROR(__xludf.DUMMYFUNCTION("""COMPUTED_VALUE"""),0.10739006387326) -> 0.10739006 | AK19: =IFERROR(__xludf.DUMMYFUNCTION("""COMPUTED_VALUE"""),101.1) -> 101.1 | AL19: =IFERROR(__xludf.DUMMYFUNCTION("""COMPUTED_VALUE"""),101.1) -> 101.1 | AM19: =IFERROR(__xludf.DUMMYFUNCTION("""COMPUTED_VALUE"""),0.580855070282137) -> 0.58085507 | AN19: =IFERROR(__xludf.DUMMYFUNCTION("""COMPUTED_VALUE"""),46168.0) -> 46168 | AO19: =IFERROR(__xludf.DUMMYFUNCTION("""COMPUTED_VALUE"""),"Argentina") -> Argentina | AP19: =IFERROR(__xludf.DUMMYFUNCTION("""COMPUTED_VALUE"""),"Trimestral") -> Trimestral | AQ19: =IFERROR(__xludf.DUMMYFUNCTION("""COMPUTED_VALUE"""),1.0) -> 1 | AR19: =IFERROR(__xludf.DUMMYFUNCTION("""COMPUTED_VALUE"""),"Bullet") -> Bullet
B20: TLCPD | C20: =VLOOKUP(B20,$K$6:$T$36,2,0) -> #N/A | D20: =VLOOKUP(B20,$K$6:$T$36,5,0) -> #N/A | E20: =VLOOKUP(B20,$K$6:$T$36,6,0) -> #N/A | F20: =D20 -> #N/A | G20: =F20/$G$23 -> #N/A | H20: =VLOOKUP(B20,$K$6:$T$36,9,0) -> #N/A | J20: =IFERROR(__xludf.DUMMYFUNCTION("""COMPUTED_VALUE"""),"TSC3D") -> TSC3D | K20: =IFERROR(__xludf.DUMMYFUNCTION("""COMPUTED_VALUE"""),"TGS") -> TGS | L20: =IFERROR(__xludf.DUMMYFUNCTION("""COMPUTED_VALUE"""),48053.0) -> 48053 | M20: =IFERROR(__xludf.DUMMYFUNCTION("""COMPUTED_VALUE"""),0.085) -> 0.085 | N20: =IFERROR(__xludf.DUMMYFUNCTION("""COMPUTED_VALUE"""),107.2) -> 107.2 | O20: =IFERROR(__xludf.DUMMYFUNCTION("""COMPUTED_VALUE"""),0.07462369421868527) -> 0.074623694 | P20: =IFERROR(__xludf.DUMMYFUNCTION("""COMPUTED_VALUE"""),-0.0046) -> -0.0046 | Q20: =IFERROR(__xludf.DUMMYFUNCTION("""COMPUTED_VALUE"""),4.690068652262308) -> 4.6900687 | R20: =IFERROR(__xludf.DUMMYFUNCTION("""COMPUTED_VALUE"""),"Semestral") -> Semestral | S20: =IFERROR(__xludf.DUMMYFUNCTION("""COMPUTED_VALUE"""),"Bullet") -> Bullet | T20: =IFERROR(__xludf.DUMMYFUNCTION("""COMPUTED_VALUE"""),"NY") -> NY | U20: =IFERROR(__xludf.DUMMYFUNCTION("""COMPUTED_VALUE"""),10000.0) -> 10000 | V20: =IFERROR(__xludf.DUMMYFUNCTION("""COMPUTED_VALUE"""),108.0) -> 108 | W20: =IFERROR(__xludf.DUMMYFUNCTION("""COMPUTED_VALUE"""),1.052858448485179) -> 1.0528584 | AH20: =IFERROR(__xludf.DUMMYFUNCTION("""COMPUTED_VALUE"""),"Balanz") -> Balanz | AI20: =IFERROR(__xludf.DUMMYFUNCTION("""COMPUTED_VALUE"""),"NBS1D") -> NBS1D | AJ20: =IFERROR(__xludf.DUMMYFUNCTION("""COMPUTED_VALUE"""),0.07488250269684493) -> 0.074882503 | AK20: =IFERROR(__xludf.DUMMYFUNCTION("""COMPUTED_VALUE"""),100.2) -> 100.2 | AL20: =IFERROR(__xludf.DUMMYFUNCTION("""COMPUTED_VALUE"""),100.2) -> 100.2 | AM20: =IFERROR(__xludf.DUMMYFUNCTION("""COMPUTED_VALUE"""),0.6311269643904209) -> 0.63112696 | AN20: =IFERROR(__xludf.DUMMYFUNCTION("""COMPUTED_VALUE"""),46179.0) -> 46179 | AO20: =IFERROR(__xludf.DUMMYFUNCTION("""COMPUTED_VALUE"""),"Argentina") -> Argentina | AP20: =IFERROR(__xludf.DUMMYFUNCTION("""COMPUTED_VALUE"""),"Cuatrimestral") -> Cuatrimestral | AQ20: =IFERROR(__xludf.DUMMYFUNCTION("""COMPUTED_VALUE"""),1.0) -> 1 | AR20: =IFERROR(__xludf.DUMMYFUNCTION("""COMPUTED_VALUE"""),"Bullet") -> Bullet
J21: =IFERROR(__xludf.DUMMYFUNCTION("""COMPUTED_VALUE"""),"ARC1D") -> ARC1D | K21: =IFERROR(__xludf.DUMMYFUNCTION("""COMPUTED_VALUE"""),"Aeropuertos 2000") -> Aeropuertos 2000 | L21: =IFERROR(__xludf.DUMMYFUNCTION("""COMPUTED_VALUE"""),48061.0) -> 48061 | M21: =IFERROR(__xludf.DUMMYFUNCTION("""COMPUTED_VALUE"""),0.085) -> 0.085 | N21: =IFERROR(__xludf.DUMMYFUNCTION("""COMPUTED_VALUE"""),106.75) -> 106.75 | O21: =IFERROR(__xludf.DUMMYFUNCTION("""COMPUTED_VALUE"""),0.0706169294415442) -> 0.070616929 | P21: =IFERROR(__xludf.DUMMYFUNCTION("""COMPUTED_VALUE"""),-0.0161) -> -0.0161 | Q21: =IFERROR(__xludf.DUMMYFUNCTION("""COMPUTED_VALUE"""),3.2122134385327046) -> 3.2122134 | R21: =IFERROR(__xludf.DUMMYFUNCTION("""COMPUTED_VALUE"""),"Trimestral") -> Trimestral | S21: =IFERROR(__xludf.DUMMYFUNCTION("""COMPUTED_VALUE"""),"Sinkable") -> Sinkable | T21: =IFERROR(__xludf.DUMMYFUNCTION("""COMPUTED_VALUE"""),"NY") -> NY | U21: =IFERROR(__xludf.DUMMYFUNCTION("""COMPUTED_VALUE"""),1000.0) -> 1000 | V21: =IFERROR(__xludf.DUMMYFUNCTION("""COMPUTED_VALUE"""),24.0) -> 24 | W21: =IFERROR(__xludf.DUMMYFUNCTION("""COMPUTED_VALUE"""),1.0503874379894225) -> 1.0503874 | AH21: =IFERROR(__xludf.DUMMYFUNCTION("""COMPUTED_VALUE"""),"Edenor") -> Edenor | AI21: =IFERROR(__xludf.DUMMYFUNCTION("""COMPUTED_VALUE"""),"DNC5D") -> DNC5D | AJ21: =IFERROR(__xludf.DUMMYFUNCTION("""COMPUTED_VALUE"""),0.08612137462589714) -> 0.086121375 | AK21: =IFERROR(__xludf.DUMMYFUNCTION("""COMPUTED_VALUE"""),104.3) -> 104.3 | AL21: =IFERROR(__xludf.DUMMYFUNCTION("""COMPUTED_VALUE"""),104.3) -> 104.3 | AM21: =IFERROR(__xludf.DUMMYFUNCTION("""COMPUTED_VALUE"""),2.441654856231381) -> 2.4416549 | AN21: =IFERROR(__xludf.DUMMYFUNCTION("""COMPUTED_VALUE"""),46970.0) -> 46970 | AO21: =IFERROR(__xludf.DUMMYFUNCTION("""COMPUTED_VALUE"""),"Argentina") -> Argentina | AP21: =IFERROR(__xludf.DUMMYFUNCTION("""COMPUTED_VALUE"""),"Semestral") -> Semestral | AQ21: =IFERROR(__xludf.DUMMYFUNCTION("""COMPUTED_VALUE"""),1.0) -> 1 | AR21: =IFERROR(__xludf.DUMMYFUNCTION("""COMPUTED_VALUE"""),"Bullet") -> Bullet
J22: =IFERROR(__xludf.DUMMYFUNCTION("""COMPUTED_VALUE"""),"MGCMD") -> MGCMD | K22: =IFERROR(__xludf.DUMMYFUNCTION("""COMPUTED_VALUE"""),"Pampa Energia") -> Pampa Energia | L22: =IFERROR(__xludf.DUMMYFUNCTION("""COMPUTED_VALUE"""),48101.0) -> 48101 | M22: =IFERROR(__xludf.DUMMYFUNCTION("""COMPUTED_VALUE"""),0.0795) -> 0.0795 | N22: =IFERROR(__xludf.DUMMYFUNCTION("""COMPUTED_VALUE"""),103.7) -> 103.7 | O22: =IFERROR(__xludf.DUMMYFUNCTION("""COMPUTED_VALUE"""),0.07441493850747857) -> 0.074414939 | P22: =IFERROR(__xludf.DUMMYFUNCTION("""COMPUTED_VALUE"""),0.0019) -> 0.0019 | Q22: =IFERROR(__xludf.DUMMYFUNCTION("""COMPUTED_VALUE"""),4.8671100069722595) -> 4.86711 | R22: =IFERROR(__xludf.DUMMYFUNCTION("""COMPUTED_VALUE"""),"Semestral") -> Semestral | S22: =IFERROR(__xludf.DUMMYFUNCTION("""COMPUTED_VALUE"""),"Bullet") -> Bullet | T22: =IFERROR(__xludf.DUMMYFUNCTION("""COMPUTED_VALUE"""),"NY") -> NY | U22: =IFERROR(__xludf.DUMMYFUNCTION("""COMPUTED_VALUE"""),10000.0) -> 10000 | V22: =IFERROR(__xludf.DUMMYFUNCTION("""COMPUTED_VALUE"""),153.0) -> 153 | W22: =IFERROR(__xludf.DUMMYFUNCTION("""COMPUTED_VALUE"""),0.9904134283633586) -> 0.99041343 | AH22: =IFERROR(__xludf.DUMMYFUNCTION("""COMPUTED_VALUE"""),"YPF") -> YPF | AI22: =IFERROR(__xludf.DUMMYFUNCTION("""COMPUTED_VALUE"""),"YM39D") -> YM39D | AJ22: =IFERROR(__xludf.DUMMYFUNCTION("""COMPUTED_VALUE"""),0.0877953320026665) -> 0.087795332 | AK22: =IFERROR(__xludf.DUMMYFUNCTION("""COMPUTED_VALUE"""),102.95) -> 102.95 | AL22: =IFERROR(__xludf.DUMMYFUNCTION("""COMPUTED_VALUE"""),102.95) -> 102.95 | AM22: =IFERROR(__xludf.DUMMYFUNCTION("""COMPUTED_VALUE"""),3.774346743823558) -> 3.7743467 | AN22: =IFERROR(__xludf.DUMMYFUNCTION("""COMPUTED_VALUE"""),47686.0) -> 47686 | AO22: =IFERROR(__xludf.DUMMYFUNCTION("""COMPUTED_VALUE"""),"Argentina") -> Argentina | AP22: =IFERROR(__xludf.DUMMYFUNCTION("""COMPUTED_VALUE"""),"Semestral") -> Semestral | AQ22: =IFERROR(__xludf.DUMMYFUNCTION("""COMPUTED_VALUE"""),100.0) -> 100 | AR22: =IFERROR(__xludf.DUMMYFUNCTION("""COMPUTED_VALUE"""),"Bullet") -> Bullet
G23: =SUM(F19:F22) -> #N/A | J23: =IFERROR(__xludf.DUMMYFUNCTION("""COMPUTED_VALUE"""),"YMCXD") -> YMCXD | K23: =IFERROR(__xludf.DUMMYFUNCTION("""COMPUTED_VALUE"""),"YPF") -> YPF | L23: =IFERROR(__xludf.DUMMYFUNCTION("""COMPUTED_VALUE"""),48102.0) -> 48102 | M23: =IFERROR(__xludf.DUMMYFUNCTION("""COMPUTED_VALUE"""),0.0875) -> 0.0875 | N23: =IFERROR(__xludf.DUMMYFUNCTION("""COMPUTED_VALUE"""),104.3) -> 104.3 | O23: =IFERROR(__xludf.DUMMYFUNCTION("""COMPUTED_VALUE"""),0.08058538599984179) -> 0.080585386 | P23: =IFERROR(__xludf.DUMMYFUNCTION("""COMPUTED_VALUE"""),0.0028000000000000004) -> 0.0028 | Q23: =IFERROR(__xludf.DUMMYFUNCTION("""COMPUTED_VALUE"""),4.382994151768527) -> 4.3829942 | R23: =IFERROR(__xludf.DUMMYFUNCTION("""COMPUTED_VALUE"""),"Semestral") -> Semestral | S23: =IFERROR(__xludf.DUMMYFUNCTION("""COMPUTED_VALUE"""),"Sinkable") -> Sinkable | T23: =IFERROR(__xludf.DUMMYFUNCTION("""COMPUTED_VALUE"""),"NY") -> NY | U23: =IFERROR(__xludf.DUMMYFUNCTION("""COMPUTED_VALUE"""),1.0) -> 1 | V23: =IFERROR(__xludf.DUMMYFUNCTION("""COMPUTED_VALUE"""),154.0) -> 154 | W23: =IFERROR(__xludf.DUMMYFUNCTION("""COMPUTED_VALUE"""),0.9918901069871879) -> 0.99189011
J24: =IFERROR(__xludf.DUMMYFUNCTION("""COMPUTED_VALUE"""),"PNXCD") -> PNXCD | K24: =IFERROR(__xludf.DUMMYFUNCTION("""COMPUTED_VALUE"""),"Pan American Energy") -> Pan American Energy | L24: =IFERROR(__xludf.DUMMYFUNCTION("""COMPUTED_VALUE"""),48334.0) -> 48334 | M24: =IFERROR(__xludf.DUMMYFUNCTION("""COMPUTED_VALUE"""),0.085) -> 0.085 | N24: =IFERROR(__xludf.DUMMYFUNCTION("""COMPUTED_VALUE"""),111.0) -> 111 | O24: =IFERROR(__xludf.DUMMYFUNCTION("""COMPUTED_VALUE"""),0.07017365195080114) -> 0.070173652 | P24: =IFERROR(__xludf.DUMMYFUNCTION("""COMPUTED_VALUE"""),-9.0E-4) -> -0.0009 | Q24: =IFERROR(__xludf.DUMMYFUNCTION("""COMPUTED_VALUE"""),4.458917181881186) -> 4.4589172 | R24: =IFERROR(__xludf.DUMMYFUNCTION("""COMPUTED_VALUE"""),"Semestral") -> Semestral | S24: =IFERROR(__xludf.DUMMYFUNCTION("""COMPUTED_VALUE"""),"Sinkable") -> Sinkable | T24: =IFERROR(__xludf.DUMMYFUNCTION("""COMPUTED_VALUE"""),"NY") -> NY | U24: =IFERROR(__xludf.DUMMYFUNCTION("""COMPUTED_VALUE"""),1000.0) -> 1000 | V24: =IFERROR(__xludf.DUMMYFUNCTION("""COMPUTED_VALUE"""),22.0) -> 22 | W24: =IFERROR(__xludf.DUMMYFUNCTION("""COMPUTED_VALUE"""),1.0691066698771972) -> 1.0691067
B25: 6-12 meses Conservador | J25: =IFERROR(__xludf.DUMMYFUNCTION("""COMPUTED_VALUE"""),"YFCJD") -> YFCJD | K25: =IFERROR(__xludf.DUMMYFUNCTION("""COMPUTED_VALUE"""),"YPF Luz") -> YPF Luz | L25: =IFERROR(__xludf.DUMMYFUNCTION("""COMPUTED_VALUE"""),48503.0) -> 48503 | M25: =IFERROR(__xludf.DUMMYFUNCTION("""COMPUTED_VALUE"""),0.0788) -> 0.0788 | N25: =IFERROR(__xludf.DUMMYFUNCTION("""COMPUTED_VALUE"""),102.8) -> 102.8 | O25: =IFERROR(__xludf.DUMMYFUNCTION("""COMPUTED_VALUE"""),0.08249727097335856) -> 0.082497271 | P25: =IFERROR(__xludf.DUMMYFUNCTION("""COMPUTED_VALUE"""),9.0E-4) -> 0.0009 | Q25: =IFERROR(__xludf.DUMMYFUNCTION("""COMPUTED_VALUE"""),4.74795016936165) -> 4.7479502 | R25: =IFERROR(__xludf.DUMMYFUNCTION("""COMPUTED_VALUE"""),"Semestral") -> Semestral | S25: =IFERROR(__xludf.DUMMYFUNCTION("""COMPUTED_VALUE"""),"Sinkable") -> Sinkable | T25: =IFERROR(__xludf.DUMMYFUNCTION("""COMPUTED_VALUE"""),"NY") -> NY | U25: =IFERROR(__xludf.DUMMYFUNCTION("""COMPUTED_VALUE"""),1000.0) -> 1000 | V25: =IFERROR(__xludf.DUMMYFUNCTION("""COMPUTED_VALUE"""),8.0) -> 8 | W25: =IFERROR(__xludf.DUMMYFUNCTION("""COMPUTED_VALUE"""),0.9898892633606163) -> 0.98988926
B26: =B13 | C26: TIR | D26: M,Duration | E26: Vto | F26: M,Duration | G26: Weight | H26: Lamina | J26: =IFERROR(__xludf.DUMMYFUNCTION("""COMPUTED_VALUE"""),"PLC4D") -> PLC4D | K26: =IFERROR(__xludf.DUMMYFUNCTION("""COMPUTED_VALUE"""),"Pluspetrol") -> Pluspetrol | L26: =IFERROR(__xludf.DUMMYFUNCTION("""COMPUTED_VALUE"""),48364.0) -> 48364 | M26: =IFERROR(__xludf.DUMMYFUNCTION("""COMPUTED_VALUE"""),0.085) -> 0.085 | N26: =IFERROR(__xludf.DUMMYFUNCTION("""COMPUTED_VALUE"""),104.75) -> 104.75 | O26: =IFERROR(__xludf.DUMMYFUNCTION("""COMPUTED_VALUE"""),0.08323104363093586) -> 0.083231044 | P26: =IFERROR(__xludf.DUMMYFUNCTION("""COMPUTED_VALUE"""),-0.004699999999999999) -> -0.0047 | Q26: =IFERROR(__xludf.DUMMYFUNCTION("""COMPUTED_VALUE"""),5.1114625564212) -> 5.1114626 | R26: =IFERROR(__xludf.DUMMYFUNCTION("""COMPUTED_VALUE"""),"Semestral") -> Semestral | S26: =IFERROR(__xludf.DUMMYFUNCTION("""COMPUTED_VALUE"""),"Bullet") -> Bullet | T26: =IFERROR(__xludf.DUMMYFUNCTION("""COMPUTED_VALUE"""),"NY") -> NY | U26: =IFERROR(__xludf.DUMMYFUNCTION("""COMPUTED_VALUE"""),1000.0) -> 1000 | V26: =IFERROR(__xludf.DUMMYFUNCTION("""COMPUTED_VALUE"""),53.0) -> 53 | W26: =IFERROR(__xludf.DUMMYFUNCTION("""COMPUTED_VALUE"""),1.015839663811217) -> 1.0158397
J27: =IFERROR(__xludf.DUMMYFUNCTION("""COMPUTED_VALUE"""),"TTCAD") -> TTCAD | K27: =IFERROR(__xludf.DUMMYFUNCTION("""COMPUTED_VALUE"""),"Tecpetrol") -> Tecpetrol | L27: =IFERROR(__xludf.DUMMYFUNCTION("""COMPUTED_VALUE"""),48601.0) -> 48601 | M27: =IFERROR(__xludf.DUMMYFUNCTION("""COMPUTED_VALUE"""),0.0763) -> 0.0763 | N27: =IFERROR(__xludf.DUMMYFUNCTION("""COMPUTED_VALUE"""),105.45) -> 105.45 | O27: =IFERROR(__xludf.DUMMYFUNCTION("""COMPUTED_VALUE"""),0.0697006756604922) -> 0.069700676 | P27: =IFERROR(__xludf.DUMMYFUNCTION("""COMPUTED_VALUE"""),0.0042) -> 0.0042 | Q27: =IFERROR(__xludf.DUMMYFUNCTION("""COMPUTED_VALUE"""),5.098153000107035) -> 5.098153 | R27: =IFERROR(__xludf.DUMMYFUNCTION("""COMPUTED_VALUE"""),"Semestral") -> Semestral | S27: =IFERROR(__xludf.DUMMYFUNCTION("""COMPUTED_VALUE"""),"Sinkable") -> Sinkable | T27: =IFERROR(__xludf.DUMMYFUNCTION("""COMPUTED_VALUE"""),"NY") -> NY | U27: =IFERROR(__xludf.DUMMYFUNCTION("""COMPUTED_VALUE"""),1000.0) -> 1000 | V27: =IFERROR(__xludf.DUMMYFUNCTION("""COMPUTED_VALUE"""),106.0) -> 106 | W27: =IFERROR(__xludf.DUMMYFUNCTION("""COMPUTED_VALUE"""),1.037145813625482) -> 1.0371458
J28: =IFERROR(__xludf.DUMMYFUNCTION("""COMPUTED_VALUE"""),"YMCJD") -> YMCJD | K28: =IFERROR(__xludf.DUMMYFUNCTION("""COMPUTED_VALUE"""),"YPF") -> YPF | L28: =IFERROR(__xludf.DUMMYFUNCTION("""COMPUTED_VALUE"""),48852.0) -> 48852 | M28: =IFERROR(__xludf.DUMMYFUNCTION("""COMPUTED_VALUE"""),0.07) -> 0.07 | N28: =IFERROR(__xludf.DUMMYFUNCTION("""COMPUTED_VALUE"""),95.21) -> 95.21 | O28: =IFERROR(__xludf.DUMMYFUNCTION("""COMPUTED_VALUE"""),0.08160710044950233) -> 0.0816071 | P28: =IFERROR(__xludf.DUMMYFUNCTION("""COMPUTED_VALUE"""),0.004699999999999999) -> 0.0047 | Q28: =IFERROR(__xludf.DUMMYFUNCTION("""COMPUTED_VALUE"""),5.275965287084322) -> 5.2759653 | R28: =IFERROR(__xludf.DUMMYFUNCTION("""COMPUTED_VALUE"""),"Semestral") -> Semestral | S28: =IFERROR(__xludf.DUMMYFUNCTION("""COMPUTED_VALUE"""),"Sinkable") -> Sinkable | T28: =IFERROR(__xludf.DUMMYFUNCTION("""COMPUTED_VALUE"""),"NY") -> NY | U28: =IFERROR(__xludf.DUMMYFUNCTION("""COMPUTED_VALUE"""),1.0) -> 1 | V28: =IFERROR(__xludf.DUMMYFUNCTION("""COMPUTED_VALUE"""),173.0) -> 173 | W28: =IFERROR(__xludf.DUMMYFUNCTION("""COMPUTED_VALUE"""),0.9504367357125031) -> 0.95043674
J29: =IFERROR(__xludf.DUMMYFUNCTION("""COMPUTED_VALUE"""),"TLCPD") -> TLCPD | K29: =IFERROR(__xludf.DUMMYFUNCTION("""COMPUTED_VALUE"""),"Telecom") -> Telecom | L29: =IFERROR(__xludf.DUMMYFUNCTION("""COMPUTED_VALUE"""),48727.0) -> 48727 | M29: =IFERROR(__xludf.DUMMYFUNCTION("""COMPUTED_VALUE"""),0.0925) -> 0.0925 | N29: =IFERROR(__xludf.DUMMYFUNCTION("""COMPUTED_VALUE"""),102.0) -> 102 | O29: =IFERROR(__xludf.DUMMYFUNCTION("""COMPUTED_VALUE"""),0.09747772156634352) -> 0.097477722 | P29: =IFERROR(__xludf.DUMMYFUNCTION("""COMPUTED_VALUE"""),-0.0048) -> -0.0048 | Q29: =IFERROR(__xludf.DUMMYFUNCTION("""COMPUTED_VALUE"""),5.213219007752955) -> 5.213219 | R29: =IFERROR(__xludf.DUMMYFUNCTION("""COMPUTED_VALUE"""),"Semestral") -> Semestral | S29: =IFERROR(__xludf.DUMMYFUNCTION("""COMPUTED_VALUE"""),"Sinkable") -> Sinkable | T29: =IFERROR(__xludf.DUMMYFUNCTION("""COMPUTED_VALUE"""),"NY") -> NY | U29: =IFERROR(__xludf.DUMMYFUNCTION("""COMPUTED_VALUE"""),100.0) -> 100 | V29: =IFERROR(__xludf.DUMMYFUNCTION("""COMPUTED_VALUE"""),51.0) -> 51 | W29: =IFERROR(__xludf.DUMMYFUNCTION("""COMPUTED_VALUE"""),0.9860497589924676) -> 0.98604976
J30: =IFERROR(__xludf.DUMMYFUNCTION("""COMPUTED_VALUE"""),"VSCVD") -> VSCVD | K30: =IFERROR(__xludf.DUMMYFUNCTION("""COMPUTED_VALUE"""),"Vista Energy") -> Vista Energy | L30: =IFERROR(__xludf.DUMMYFUNCTION("""COMPUTED_VALUE"""),48740.0) -> 48740 | M30: =IFERROR(__xludf.DUMMYFUNCTION("""COMPUTED_VALUE"""),0.085) -> 0.085 | N30: =IFERROR(__xludf.DUMMYFUNCTION("""COMPUTED_VALUE"""),106.0) -> 106 | O30: =IFERROR(__xludf.DUMMYFUNCTION("""COMPUTED_VALUE"""),0.08023538487148903) -> 0.080235385 | P30: =IFERROR(__xludf.DUMMYFUNCTION("""COMPUTED_VALUE"""),0.004699999999999999) -> 0.0047 | Q30: =IFERROR(__xludf.DUMMYFUNCTION("""COMPUTED_VALUE"""),5.14696178862725) -> 5.1469618 | R30: =IFERROR(__xludf.DUMMYFUNCTION("""COMPUTED_VALUE"""),"Semestral") -> Semestral | S30: =IFERROR(__xludf.DUMMYFUNCTION("""COMPUTED_VALUE"""),"Sinkable") -> Sinkable | T30: =IFERROR(__xludf.DUMMYFUNCTION("""COMPUTED_VALUE"""),"NY") -> NY | U30: =IFERROR(__xludf.DUMMYFUNCTION("""COMPUTED_VALUE"""),1000.0) -> 1000 | V30: =IFERROR(__xludf.DUMMYFUNCTION("""COMPUTED_VALUE"""),63.0) -> 63 | W30: =IFERROR(__xludf.DUMMYFUNCTION("""COMPUTED_VALUE"""),1.03055754351378) -> 1.0305575
F31: =SUM(F27:F30) -> 0 | J31: =IFERROR(__xludf.DUMMYFUNCTION("""COMPUTED_VALUE"""),"YM34D") -> YM34D | K31: =IFERROR(__xludf.DUMMYFUNCTION("""COMPUTED_VALUE"""),"YPF") -> YPF | L31: =IFERROR(__xludf.DUMMYFUNCTION("""COMPUTED_VALUE"""),48961.0) -> 48961 | M31: =IFERROR(__xludf.DUMMYFUNCTION("""COMPUTED_VALUE"""),0.0825) -> 0.0825 | N31: =IFERROR(__xludf.DUMMYFUNCTION("""COMPUTED_VALUE"""),100.7) -> 100.7 | O31: =IFERROR(__xludf.DUMMYFUNCTION("""COMPUTED_VALUE"""),0.08647523168979138) -> 0.086475232 | P31: =IFERROR(__xludf.DUMMYFUNCTION("""COMPUTED_VALUE"""),-0.0078000000000000005) -> -0.0078 | Q31: =IFERROR(__xludf.DUMMYFUNCTION("""COMPUTED_VALUE"""),5.573419365572477) -> 5.5734194 | R31: =IFERROR(__xludf.DUMMYFUNCTION("""COMPUTED_VALUE"""),"Semestral") -> Semestral | S31: =IFERROR(__xludf.DUMMYFUNCTION("""COMPUTED_VALUE"""),"Sinkable") -> Sinkable | T31: =IFERROR(__xludf.DUMMYFUNCTION("""COMPUTED_VALUE"""),"NY") -> NY | U31: =IFERROR(__xludf.DUMMYFUNCTION("""COMPUTED_VALUE"""),1.0) -> 1 | V31: =IFERROR(__xludf.DUMMYFUNCTION("""COMPUTED_VALUE"""),101.0) -> 101 | W31: =IFERROR(__xludf.DUMMYFUNCTION("""COMPUTED_VALUE"""),0.987981358842286) -> 0.98798136
B32: Simple | J32: =IFERROR(__xludf.DUMMYFUNCTION("""COMPUTED_VALUE"""),"MGCOD") -> MGCOD | K32: =IFERROR(__xludf.DUMMYFUNCTION("""COMPUTED_VALUE"""),"Pampa Energia") -> Pampa Energia | L32: =IFERROR(__xludf.DUMMYFUNCTION("""COMPUTED_VALUE"""),49294.0) -> 49294 | M32: =IFERROR(__xludf.DUMMYFUNCTION("""COMPUTED_VALUE"""),0.0788) -> 0.0788 | N32: =IFERROR(__xludf.DUMMYFUNCTION("""COMPUTED_VALUE"""),102.0) -> 102 | O32: =IFERROR(__xludf.DUMMYFUNCTION("""COMPUTED_VALUE"""),0.08104000521943708) -> 0.081040005 | P32: =IFERROR(__xludf.DUMMYFUNCTION("""COMPUTED_VALUE"""),-9.0E-4) -> -0.0009 | Q32: =IFERROR(__xludf.DUMMYFUNCTION("""COMPUTED_VALUE"""),6.576337094089589) -> 6.5763371 | R32: =IFERROR(__xludf.DUMMYFUNCTION("""COMPUTED_VALUE"""),"Semestral") -> Semestral | S32: =IFERROR(__xludf.DUMMYFUNCTION("""COMPUTED_VALUE"""),"Bullet") -> Bullet | T32: =IFERROR(__xludf.DUMMYFUNCTION("""COMPUTED_VALUE"""),"NY") -> NY | U32: =IFERROR(__xludf.DUMMYFUNCTION("""COMPUTED_VALUE"""),10000.0) -> 10000 | V32: =IFERROR(__xludf.DUMMYFUNCTION("""COMPUTED_VALUE"""),69.0) -> 69 | W32: =IFERROR(__xludf.DUMMYFUNCTION("""COMPUTED_VALUE"""),0.9577745825875172) -> 0.95777458
B33: Ticker | C33: =L33 -> 49399 | D33: M,Duration | E33: Vto | F33: Inverse m,D | G33: Weight | H33: Lamina | J33: =IFERROR(__xludf.DUMMYFUNCTION("""COMPUTED_VALUE"""),"IRCPD") -> IRCPD | K33: =IFERROR(__xludf.DUMMYFUNCTION("""COMPUTED_VALUE"""),"IRSA") -> IRSA | L33: =IFERROR(__xludf.DUMMYFUNCTION("""COMPUTED_VALUE"""),49399.0) -> 49399 | M33: =IFERROR(__xludf.DUMMYFUNCTION("""COMPUTED_VALUE"""),0.08) -> 0.08 | N33: =IFERROR(__xludf.DUMMYFUNCTION("""COMPUTED_VALUE"""),101.0) -> 101 | O33: =IFERROR(__xludf.DUMMYFUNCTION("""COMPUTED_VALUE"""),0.08018455933001999) -> 0.080184559 | P33: =IFERROR(__xludf.DUMMYFUNCTION("""COMPUTED_VALUE"""),-0.0044) -> -0.0044 | Q33: =IFERROR(__xludf.DUMMYFUNCTION("""COMPUTED_VALUE"""),6.342041482649829) -> 6.3420415 | R33: =IFERROR(__xludf.DUMMYFUNCTION("""COMPUTED_VALUE"""),"Semestral") -> Semestral | S33: =IFERROR(__xludf.DUMMYFUNCTION("""COMPUTED_VALUE"""),"Sinkable") -> Sinkable | T33: =IFERROR(__xludf.DUMMYFUNCTION("""COMPUTED_VALUE"""),"NY") -> NY | U33: =IFERROR(__xludf.DUMMYFUNCTION("""COMPUTED_VALUE"""),1.0) -> 1 | V33: =IFERROR(__xludf.DUMMYFUNCTION("""COMPUTED_VALUE"""),174.0) -> 174 | W33: =IFERROR(__xludf.DUMMYFUNCTION("""COMPUTED_VALUE"""),1.0079840319361277) -> 1.007984
B34: YM34D | C34: =VLOOKUP($B$34,$K$6:$T$36,2,0) -> #N/A | D34: =VLOOKUP($B$34,$K$6:$T$36,5,0) -> #N/A | E34: =VLOOKUP($B$34,$K$6:$T$36,6,0) -> #N/A | F34: =1/D34 -> #N/A | G34: =F34/$F$12 -> #N/A | H34: =VLOOKUP($B$34,$K$6:$T$36,9,0) -> #N/A | J34: =IFERROR(__xludf.DUMMYFUNCTION("""COMPUTED_VALUE"""),"VSCTD") -> VSCTD | K34: =IFERROR(__xludf.DUMMYFUNCTION("""COMPUTED_VALUE"""),"Vista Energy") -> Vista Energy | L34: =IFERROR(__xludf.DUMMYFUNCTION("""COMPUTED_VALUE"""),49653.0) -> 49653 | M34: =IFERROR(__xludf.DUMMYFUNCTION("""COMPUTED_VALUE"""),0.0763) -> 0.0763 | N34: =IFERROR(__xludf.DUMMYFUNCTION("""COMPUTED_VALUE"""),99.9) -> 99.9 | O34: =IFERROR(__xludf.DUMMYFUNCTION("""COMPUTED_VALUE"""),0.0818604390915039) -> 0.081860439 | P34: =IFERROR(__xludf.DUMMYFUNCTION("""COMPUTED_VALUE"""),-0.0044) -> -0.0044 | Q34: =IFERROR(__xludf.DUMMYFUNCTION("""COMPUTED_VALUE"""),6.5851280860201555) -> 6.5851281 | R34: =IFERROR(__xludf.DUMMYFUNCTION("""COMPUTED_VALUE"""),"Semestral") -> Semestral | S34: =IFERROR(__xludf.DUMMYFUNCTION("""COMPUTED_VALUE"""),"Sinkable") -> Sinkable | T34: =IFERROR(__xludf.DUMMYFUNCTION("""COMPUTED_VALUE"""),"NY") -> NY | U34: =IFERROR(__xludf.DUMMYFUNCTION("""COMPUTED_VALUE"""),10000.0) -> 10000 | V34: =IFERROR(__xludf.DUMMYFUNCTION("""COMPUTED_VALUE"""),63.0) -> 63 | W34: =IFERROR(__xludf.DUMMYFUNCTION("""COMPUTED_VALUE"""),0.9387535360851988) -> 0.93875354
F40: =SUM(F34:F39) -> #N/A

Sheet Soberanos
B2: Working Capital | C2: TIR | D2: M,D | E2: Inverse duration | F2: Weight
A3: Lecap | B3: S10N5 | C3: =VLOOKUP(B3,$J$11:$R$63,7,0) -> 0.64634307 | D3: =VLOOKUP(B3,$J$11:$R$63,9,0) -> 33 | F3: 0.333
A4: Lecap | B4: T15D5 | C4: =VLOOKUP(B4,$J$11:$R$63,7,0) -> 0.63515085 | D4: =VLOOKUP(B4,$J$11:$R$63,9,0) -> 68 | F4: 0.333
A5: Lecap | B5: S28N5 | C5: =VLOOKUP(B5,$J$11:$R$63,7,0) -> 0.66463931 | D5: =VLOOKUP(B5,$J$11:$R$63,9,0) -> 51 | F5: 0.333
I8: =IFERROR(__xludf.DUMMYFUNCTION("IMPORTRANGE(""https://docs.google.com/spreadsheets/d/1QFB2kh2cYM7XonEBR7QFtdA5P63irew36fgS54qRFHA/edit?gid=443985142#gid=443985142"" , ""Lecaps!A:L"")"),45938.0) -> 45938 | U8: =IFERROR(__xludf.DUMMYFUNCTION("IMPORTRANGE(""https://docs.google.com/spreadsheets/d/1QFB2kh2cYM7XonEBR7QFtdA5P63irew36fgS54qRFHA/edit?gid=443985142#gid=443985142"" , ""CER!A:L"")"),45938.0) -> 45938 | AG8: =IFERROR(__xludf.DUMMYFUNCTION("IMPORTRANGE(""https://docs.google.com/spreadsheets/d/1QFB2kh2cYM7XonEBR7QFtdA5P63irew36fgS54qRFHA/edit?gid=443985142#gid=443985142"" , ""Soberanos!A:L"")"),"") | AS8: =IFERROR(__xludf.DUMMYFUNCTION("IMPORTRANGE(""https://docs.google.com/spreadsheets/d/1QFB2kh2cYM7XonEBR7QFtdA5P63irew36fgS54qRFHA/edit?gid=443985142#gid=443985142"" , ""Bopreales!A:L"")"),45938.0) -> 45938
B9: Conservador | C9: TIR | D9: M,D | E9: Inverse duration | F9: Weight | J9: =IFERROR(__xludf.DUMMYFUNCTION("""COMPUTED_VALUE"""),"LECAPS") -> LECAPS | V9: =IFERROR(__xludf.DUMMYFUNCTION("""COMPUTED_VALUE"""),"BONOS CER") -> BONOS CER | AH9: =IFERROR(__xludf.DUMMYFUNCTION("""COMPUTED_VALUE"""),"SOBERANOS USD") -> SOBERANOS USD | AT9: =IFERROR(__xludf.DUMMYFUNCTION("""COMPUTED_VALUE"""),"BOPREALES") -> BOPREALES
