Workbook

Sheet Multi-mercado
A1: Ticker | B1: COPX | C1: 24
B3: Cierre | C3: {=_xll.PrecioBD(B1,C1,"PREVIOUS","N")} -> 9240 | D3: Último | E3: {=_xll.PrecioBD(B1,C1,"LAST","N")} -> 8855 | F3: Var | G3: {=_xll.PrecioBD(B1,C1,"IMBALANCE","N")} -> -0.0416
B4: Vwap | C4: {=_xll.PrecioBD(B1,C1,"VWAP","N")} -> 8892.4331 | D4: Nominales | E4: {=_xll.PrecioBD(B1,C1,"TRADE VOLUME","N")} -> 97948 | F4: Monto $ | G4: {=_xll.PrecioBD(B1,C1,"VOLUME AMOUNT","N")} -> 869723240
B6: {=_xll.PrecioBD(B1,C1,"BID","N")} -> 8815 | E6: {=_xll.PrecioBD(B1,C1,"ASK","N")} -> 9050
A7: {=_xll.ProfundidadBD(B1,C1)} -> COPX - 24hs | B7: ORD. | C7: CANT. | D7: PRECIO | E7: PRECIO | F7: CANT. | G7: ORD.
I14: Pase
A15: Ticker | B15: =B1 -> COPX | C15: CI | J15: Venta CI - Compra T1 | K15: Compra CI - Venta T1
I16: Arbitraje | J16: =D22/E8-1 -> #DIV/0! | K16: =D8/E22-1 -> #DIV/0!
B17: Cierre | C17: {=_xll.PrecioBD(B15,C15,"PREVIOUS","N")} -> 9240 | D17: Último | E17: {=_xll.PrecioBD(B15,C15,"LAST","N")} -> 8815 | F17: Var | G17: {=_xll.PrecioBD(B15,C15,"IMBALANCE","N")} -> -0.0459 | I17: TNA | J17: =+J16*365 -> #DIV/0! | K17: =+K16*365 -> #DIV/0!
B18: Vwap | C18: {=_xll.PrecioBD(B15,C15,"VWAP","N")} -> 8892.4331 | D18: Nominales | E18: {=_xll.PrecioBD(B15,C15,"TRADE VOLUME","N")} -> 7102 | F18: Monto $ | G18: {=_xll.PrecioBD(B15,C15,"VOLUME AMOUNT","N")} -> 63154060
B20: {=_xll.PrecioBD(B15,C15,"BID","N")} -> 8815 | E20: {=_xll.PrecioBD(B15,C15,"ASK","N")} -> 9170
A21: {=_xll.ProfundidadBD(B15,C15)} -> COPX - CI | B21: ORD. | C21: CANT. | D21: PRECIO | E21: PRECIO | F21: CANT. | G21: ORD.

Sheet Main
A1: Fecha de liq | B1: =TODAY()+1 -> 46060
A4: Caución | B4: Moneda | C4: Plazo | D4: Tasa | E4: Bid | F4: Ask | G4: VWAP | I4: Soberanos HD | J4: Ticker | K4: TIR | L4: Ask price | M4: MD | N4: Variación | P4: ARGY | Q4: Ticker | R4: Precio | S4: Total volume | T4: Variación
B5: USD | C5: 1 | D5: =VLOOKUP(C5,Caucho!$E$2:$N$65,3,FALSE) -> #N/A | E5: =VLOOKUP(C5,Caucho!$E$2:$N$65,7,FALSE) -> #N/A | F5: =VLOOKUP(C5,Caucho!$E$2:$N$65,8,FALSE) -> #N/A | G5: =VLOOKUP(C5,Caucho!$E$2:$N$65,10,FALSE) -> #N/A | J5: AE38D | K5: =VLOOKUP(Tabla9[[#This Row],[Ticker]],ONs_NY8[[Ticker]:[Variación]],2,FALSE) -> 0.096076125 | L5: {=_xll.PrecioBD(Tabla9[[#This Row],[Ticker]],24,"ASK","N")} -> 80.05 | M5: =VLOOKUP(Tabla9[[#This Row],[Ticker]],ONs_NY8[[Ticker]:[Variación]],5,FALSE) -> 4.9019119 | N5: {=_xll.PrecioBD(Tabla9[[#This Row],[Ticker]],24,"IMBALANCE","N")} -> -0.0007 | Q5: TRAN | R5: {=_xll.PrecioBD(Q5,24,"ASK","N")} -> 3870 | S5: {=_xll.PrecioBD(Q5,24,"VOLUME AMOUNT","N")} -> 2.969431e+09 | T5: {=_xll.PrecioBD(Q5,24,"IMBALANCE","N")} -> -0.019
B6: USD | C6: 7 | D6: =VLOOKUP(C6,Caucho!$E$2:$N$65,3,FALSE) -> 0.018 | E6: =VLOOKUP(C6,Caucho!$E$2:$N$65,7,FALSE) -> 0.005 | F6: =VLOOKUP(C6,Caucho!$E$2:$N$65,8,FALSE) -> 0.018 | G6: =VLOOKUP(C6,Caucho!$E$2:$N$65,10,FALSE) -> 0.018 | J6: AL29D | K6: =VLOOKUP(Tabla9[[#This Row],[Ticker]],ONs_NY8[[Ticker]:[Variación]],2,FALSE) -> 0.088069263 | L6: {=_xll.PrecioBD(Tabla9[[#This Row],[Ticker]],24,"ASK","N")} -> 60.97 | M6: =VLOOKUP(Tabla9[[#This Row],[Ticker]],ONs_NY8[[Ticker]:[Variación]],5,FALSE) -> 0.5 | N6: {=_xll.PrecioBD(Tabla9[[#This Row],[Ticker]],24,"IMBALANCE","N")} -> 0.0013 | Q6: YPFD | R6: {=_xll.PrecioBD(Q6,24,"ASK","N")} -> 56500 | S6: {=_xll.PrecioBD(Q6,24,"VOLUME AMOUNT","N")} -> 16604746650 | T6: {=_xll.PrecioBD(Q6,24,"IMBALANCE","N")} -> -0.0342
B7: USD | C7: 30 | D7: =VLOOKUP(C7,Caucho!$E$2:$N$65,3,FALSE) -> #N/A | E7: =VLOOKUP(C7,Caucho!$E$2:$N$65,7,FALSE) -> #N/A | F7: =VLOOKUP(C7,Caucho!$E$2:$N$65,8,FALSE) -> #N/A | G7: =VLOOKUP(C7,Caucho!$E$2:$N$65,10,FALSE) -> #N/A | J7: AL30D | K7: =VLOOKUP(Tabla9[[#This Row],[Ticker]],ONs_NY8[[Ticker]:[Variación]],2,FALSE) -> 0.09034898 | L7: {=_xll.PrecioBD(Tabla9[[#This Row],[Ticker]],24,"ASK","N")} -> 60.58 | M7: =VLOOKUP(Tabla9[[#This Row],[Ticker]],ONs_NY8[[Ticker]:[Variación]],5,FALSE) -> 2.1755694 | N7: {=_xll.PrecioBD(Tabla9[[#This Row],[Ticker]],24,"IMBALANCE","N")} -> 0.0048 | Q7: TXAR | R7: {=_xll.PrecioBD(Q7,24,"ASK","N")} -> 684.5 | S7: {=_xll.PrecioBD(Q7,24,"VOLUME AMOUNT","N")} -> 765643230 | T7: {=_xll.PrecioBD(Q7,24,"IMBALANCE","N")} -> -0.0228
B8: ARS | C8: 1 | D8: =VLOOKUP(C8,Caucho!$E$66:$N$141,3,FALSE) -> #N/A | E8: =VLOOKUP(C8,Caucho!$E$66:$N$141,7,FALSE) -> #N/A | F8: =VLOOKUP(C8,Caucho!$E$66:$N$141,8,FALSE) -> #N/A | G8: =VLOOKUP(C8,Caucho!$E$66:$N$141,10,FALSE) -> #N/A | J8: AL35D | K8: =VLOOKUP(Tabla9[[#This Row],[Ticker]],ONs_NY8[[Ticker]:[Variación]],2,FALSE) -> 0.091250238 | L8: {=_xll.PrecioBD(Tabla9[[#This Row],[Ticker]],24,"ASK","N")} -> 78.67 | M8: =VLOOKUP(Tabla9[[#This Row],[Ticker]],ONs_NY8[[Ticker]:[Variación]],5,FALSE) -> 5.6790308 | N8: {=_xll.PrecioBD(Tabla9[[#This Row],[Ticker]],24,"IMBALANCE","N")} -> -0.0005 | Q8: PAMP | R8: {=_xll.PrecioBD(Q8,24,"ASK","N")} -> 4922.5 | S8: {=_xll.PrecioBD(Q8,24,"VOLUME AMOUNT","N")} -> 3104521655 | T8: {=_xll.PrecioBD(Q8,24,"IMBALANCE","N")} -> -0.008
B9: ARS | C9: 7 | D9: =VLOOKUP(C9,Caucho!$E$66:$N$141,3,FALSE) -> 0.2 | E9: =VLOOKUP(C9,Caucho!$E$66:$N$141,7,FALSE) -> 0.21 | F9: =VLOOKUP(C9,Caucho!$E$66:$N$141,8,FALSE) -> 0.238 | G9: =VLOOKUP(C9,Caucho!$E$66:$N$141,10,FALSE) -> 0.27097955 | J9: AL41D | K9: =VLOOKUP(Tabla9[[#This Row],[Ticker]],ONs_NY8[[Ticker]:[Variación]],2,FALSE) -> 0.069507185 | L9: {=_xll.PrecioBD(Tabla9[[#This Row],[Ticker]],24,"ASK","N")} -> 73.35 | M9: =VLOOKUP(Tabla9[[#This Row],[Ticker]],ONs_NY8[[Ticker]:[Variación]],5,FALSE) -> 7.5551069 | N9: {=_xll.PrecioBD(Tabla9[[#This Row],[Ticker]],24,"IMBALANCE","N")} -> -0.0083 | Q9: TGNO4 | R9: {=_xll.PrecioBD(Q9,24,"ASK","N")} -> 4000 | S9: {=_xll.PrecioBD(Q9,24,"VOLUME AMOUNT","N")} -> 1.4425626e+09 | T9: {=_xll.PrecioBD(Q9,24,"IMBALANCE","N")} -> -0.0308
B10: ARS | C10: 30 | D10: =VLOOKUP(C10,Caucho!$E$66:$N$141,3,FALSE) -> #N/A | E10: =VLOOKUP(C10,Caucho!$E$66:$N$141,7,FALSE) -> #N/A | F10: =VLOOKUP(C10,Caucho!$E$66:$N$141,8,FALSE) -> #N/A | G10: =VLOOKUP(C10,Caucho!$E$66:$N$141,10,FALSE) -> #N/A | J10: GD29D | K10: =VLOOKUP(Tabla9[[#This Row],[Ticker]],ONs_NY8[[Ticker]:[Variación]],2,FALSE) -> 0.06248239 | L10: {=_xll.PrecioBD(Tabla9[[#This Row],[Ticker]],24,"ASK","N")} -> 63.7 | M10: =VLOOKUP(Tabla9[[#This Row],[Ticker]],ONs_NY8[[Ticker]:[Variación]],5,FALSE) -> 1.7972543 | N10: {=_xll.PrecioBD(Tabla9[[#This Row],[Ticker]],24,"IMBALANCE","N")} -> 0 | Q10: BYMA | R10: {=_xll.PrecioBD(Q10,24,"ASK","N")} -> 329.75 | S10: {=_xll.PrecioBD(Q10,24,"VOLUME AMOUNT","N")} -> 1.8223637e+09 | T10: {=_xll.PrecioBD(Q10,24,"IMBALANCE","N")} -> -0.0119
J11: GD30D | K11: =VLOOKUP(Tabla9[[#This Row],[Ticker]],ONs_NY8[[Ticker]:[Variación]],2,FALSE) -> 0.070274821 | L11: {=_xll.PrecioBD(Tabla9[[#This Row],[Ticker]],24,"ASK","N")} -> 63.21 | M11: =VLOOKUP(Tabla9[[#This Row],[Ticker]],ONs_NY8[[Ticker]:[Variación]],5,FALSE) -> 2.2254087 | N11: {=_xll.PrecioBD(Tabla9[[#This Row],[Ticker]],24,"IMBALANCE","N")} -> 0.0017 | Q11: VALO | R11: {=_xll.PrecioBD(Q11,24,"ASK","N")} -> 584 | S11: {=_xll.PrecioBD(Q11,24,"VOLUME AMOUNT","N")} -> 1418758887 | T11: {=_xll.PrecioBD(Q11,24,"IMBALANCE","N")} -> -0.0143
A12: {=_xll.TiposCambioBD()} -> TIPO CAMBIO | B12: VENCIMIENTO | C12: ESPECIE | D12: SIMBOLO | E12: COMPRA | F12: VENTA | G12: ULTIMO | J12: GD35D | K12: =VLOOKUP(Tabla9[[#This Row],[Ticker]],ONs_NY8[[Ticker]:[Variación]],2,FALSE) -> 0.088632891 | L12: {=_xll.PrecioBD(Tabla9[[#This Row],[Ticker]],24,"ASK","N")} -> 79.8 | M12: =VLOOKUP(Tabla9[[#This Row],[Ticker]],ONs_NY8[[Ticker]:[Variación]],5,FALSE) -> 5.6982618 | N12: {=_xll.PrecioBD(Tabla9[[#This Row],[Ticker]],24,"IMBALANCE","N")} -> -0.0023 | Q12: CRES | R12: {=_xll.PrecioBD(Q12,24,"ASK","N")} -> 1911 | S12: {=_xll.PrecioBD(Q12,24,"VOLUME AMOUNT","N")} -> 328995806 | T12: {=_xll.PrecioBD(Q12,24,"IMBALANCE","N")} -> -0.0204
J13: GD38D | K13: =VLOOKUP(Tabla9[[#This Row],[Ticker]],ONs_NY8[[Ticker]:[Variación]],2,FALSE) -> 0.088778743 | L13: {=_xll.PrecioBD(Tabla9[[#This Row],[Ticker]],24,"ASK","N")} -> 82.86 | M13: =VLOOKUP(Tabla9[[#This Row],[Ticker]],ONs_NY8[[Ticker]:[Variación]],5,FALSE) -> 4.9813448 | N13: {=_xll.PrecioBD(Tabla9[[#This Row],[Ticker]],24,"IMBALANCE","N")} -> -0.0016 | Q13: ALUA | R13: {=_xll.PrecioBD(Q13,24,"ASK","N")} -> 980 | S13: {=_xll.PrecioBD(Q13,24,"VOLUME AMOUNT","N")} -> 1054451303 | T13: {=_xll.PrecioBD(Q13,24,"IMBALANCE","N")} -> 0.0046
B14: 2026-02-04 | C14: GD30/GD30C | D14: GD30/GD30C (CI) | E14: 1494 | F14: 1495.8 | G14: 1493.3 | J14: GD41D | K14: =VLOOKUP(Tabla9[[#This Row],[Ticker]],ONs_NY8[[Ticker]:[Variación]],2,FALSE) -> 0.067179868 | L14: {=_xll.PrecioBD(Tabla9[[#This Row],[Ticker]],24,"ASK","N")} -> 74.28 | M14: =VLOOKUP(Tabla9[[#This Row],[Ticker]],ONs_NY8[[Ticker]:[Variación]],5,FALSE) -> 7.6189885 | N14: {=_xll.PrecioBD(Tabla9[[#This Row],[Ticker]],24,"IMBALANCE","N")} -> -0.0022 | Q14: GGAL | R14: {=_xll.PrecioBD(Q14,24,"ASK","N")} -> 7525 | S14: {=_xll.PrecioBD(Q14,24,"VOLUME AMOUNT","N")} -> 38345100540 | T14: {=_xll.PrecioBD(Q14,24,"IMBALANCE","N")} -> -0.0334
B15: 2026-02-04 | C15: GD30/GD30D | D15: GD30/GD30D (CI) | E15: 1455.7 | F15: 1457.3 | G15: 1456.9 | Q15: COME | R15: {=_xll.PrecioBD(Q15,24,"ASK","N")} -> 50.4 | S15: {=_xll.PrecioBD(Q15,24,"VOLUME AMOUNT","N")} -> 9.4522398e+08 | T15: {=_xll.PrecioBD(Q15,24,"IMBALANCE","N")} -> -0.0472
B16: 2026-02-04 | C16: MAE | D16: Dolar Mayorista Bancos - Argentina | E16: 1437 | F16: 1446 | G16: 1446 | J16: Spread | K16: Delta | Q16: TGSU2 | R16: {=_xll.PrecioBD(Q16,24,"ASK","N")} -> 8790 | S16: {=_xll.PrecioBD(Q16,24,"VOLUME AMOUNT","N")} -> 1388241715 | T16: {=_xll.PrecioBD(Q16,24,"IMBALANCE","N")} -> -0.0184
B17: 2026-02-04 | C17: USB | D17: Dolar Banco Nacion Billete - Argentina | E17: 1415 | F17: 1465 | G17: 1465 | J17: AL29/GD29 | K17: {=_xll.PrecioBD("GD29D",24,"ASK","N")/_xll.PrecioBD("AL29D",24,"ASK","N")-1} -> 0.044776119 | Q17: METR | R17: {=_xll.PrecioBD(Q17,24,"ASK","N")} -> 2250 | S17: {=_xll.PrecioBD(Q17,24,"VOLUME AMOUNT","N")} -> 1826416388 | T17: {=_xll.PrecioBD(Q17,24,"IMBALANCE","N")} -> 0.0363
B18: 2026-02-04 | C18: USD | D18: Dolar x Peso Argentino BNA | E18: 1437 | F18: 1446 | G18: 1446 | J18: AL30/GD30 | K18: {=_xll.PrecioBD("GD30D",24,"ASK","N")/_xll.PrecioBD("AL30D",24,"ASK","N")-1} -> 0.043413668 | Q18: LOMA | R18: {=_xll.PrecioBD(Q18,24,"ASK","N")} -> 3230 | S18: {=_xll.PrecioBD(Q18,24,"VOLUME AMOUNT","N")} -> 1480430810 | T18: {=_xll.PrecioBD(Q18,24,"IMBALANCE","N")} -> 0.0189
J19: AL35/GD35 | K19: {=_xll.PrecioBD("GD35D",24,"ASK","N")/_xll.PrecioBD("AL35D",24,"ASK","N")-1} -> 0.014363798 | Q19: BMA | R19: {=_xll.PrecioBD(Q19,24,"ASK","N")} -> 13390 | S19: {=_xll.PrecioBD(Q19,24,"VOLUME AMOUNT","N")} -> 4901909650 | T19: {=_xll.PrecioBD(Q19,24,"IMBALANCE","N")} -> -0.0471
B20: Plazo fijo | C20: PF - Caucho | D20: PF - Lecap | F20: MEP | G20: CCL | J20: AE38/GD38 | K20: {=_xll.PrecioBD("GD38D",24,"ASK","N")/_xll.PrecioBD("AE38D",24,"ASK","N")-1} -> 0.035103061 | Q20: SUPV | R20: {=_xll.PrecioBD(Q20,24,"ASK","N")} -> 3160 | S20: {=_xll.PrecioBD(Q20,24,"VOLUME AMOUNT","N")} -> 3276570805 | T20: {=_xll.PrecioBD(Q20,24,"IMBALANCE","N")} -> -0.0474
B21: 0.26 | C21: =E8-B21 -> #N/A | F21: {=(1+_xll.PrecioBD("AL30","CI","IMBALANCE","N"))/(1+_xll.PrecioBD("AL30D","CI","IMBALANCE","N"))-1} -> 0.0023906764 | G21: {=(1+_xll.PrecioBD("AL30","CI","IMBALANCE","N"))/(1+_xll.PrecioBD("AL30C","CI","IMBALANCE","N"))-1} -> 0.0071056845 | J21: AL41/GD41 | K21: {=_xll.PrecioBD("GD41D",24,"ASK","N")/_xll.PrecioBD("AL41D",24,"ASK","N")-1} -> 0.012678937 | Q21: CEPU | R21: {=_xll.PrecioBD(Q21,24,"ASK","N")} -> 2330 | S21: {=_xll.PrecioBD(Q21,24,"VOLUME AMOUNT","N")} -> 1204640889 | T21: {=_xll.PrecioBD(Q21,24,"IMBALANCE","N")} -> -0.0197
Q22: EDN | R22: {=_xll.PrecioBD(Q22,24,"ASK","N")} -> 2018 | S22: {=_xll.PrecioBD(Q22,24,"VOLUME AMOUNT","N")} -> 1027865902 | T22: {=_xll.PrecioBD(Q22,24,"IMBALANCE","N")} -> -0.0208
Q23: TECO2 | R23: {=_xll.PrecioBD(Q23,24,"ASK","N")} -> 3490 | S23: {=_xll.PrecioBD(Q23,24,"VOLUME AMOUNT","N")} -> 531370580 | T23: {=_xll.PrecioBD(Q23,24,"IMBALANCE","N")} -> -0.0398
Q24: BBAR | R24: {=_xll.PrecioBD(Q24,24,"ASK","N")} -> 8820 | S24: {=_xll.PrecioBD(Q24,24,"VOLUME AMOUNT","N")} -> 2162042740 | T24: {=_xll.PrecioBD(Q24,24,"IMBALANCE","N")} -> -0.0564
A26: CEDEARs | B26: Ticker | C26: Precio | D26: Total volume | E26: Variación | I26: Indices | J26: Ticker | K26: Precio | L26: Total volume | M26: Variación
B27: LLY | C27: {=_xll.PrecioBD(B27,24,"ASK","N")} -> 27680 | D27: {=_xll.PrecioBD(B27,24,"VOLUME AMOUNT","N")} -> 605226780 | E27: {=_xll.PrecioBD(B27,24,"IMBALANCE","N")} -> -0.0683 | J27: SLV | K27: {=_xll.PrecioBD(J27,24,"ASK","N")} -> 17080 | L27: {=_xll.PrecioBD(J27,24,"VOLUME AMOUNT","N")} -> 9368501220 | M27: {=_xll.PrecioBD(J27,24,"IMBALANCE","N")} -> -0.1353
B28: GSK | C28: {=_xll.PrecioBD(B28,24,"ASK","N")} -> 22420 | D28: {=_xll.PrecioBD(B28,24,"VOLUME AMOUNT","N")} -> 32991220 | E28: {=_xll.PrecioBD(B28,24,"IMBALANCE","N")} -> 0.0401 | J28: USO | K28: {=_xll.PrecioBD(J28,24,"ASK","N")} -> 7750 | L28: {=_xll.PrecioBD(J28,24,"VOLUME AMOUNT","N")} -> 10757595 | M28: {=_xll.PrecioBD(J28,24,"IMBALANCE","N")} -> -0.0083
B29: AMGN | C29: {=_xll.PrecioBD(B29,24,"ASK","N")} -> 18450 | D29: {=_xll.PrecioBD(B29,24,"VOLUME AMOUNT","N")} -> 50834290 | E29: {=_xll.PrecioBD(B29,24,"IMBALANCE","N")} -> 0.0027 | J29: XLE | K29: {=_xll.PrecioBD(J29,24,"ASK","N")} -> 39500 | L29: {=_xll.PrecioBD(J29,24,"VOLUME AMOUNT","N")} -> 596468420 | M29: {=_xll.PrecioBD(J29,24,"IMBALANCE","N")} -> 0.003
B30: ARCO | C30: {=_xll.PrecioBD(B30,24,"ASK","N")} -> 25880 | D30: {=_xll.PrecioBD(B30,24,"VOLUME AMOUNT","N")} -> 345206600 | E30: {=_xll.PrecioBD(B30,24,"IMBALANCE","N")} -> -0.0271 | J30: IJH | K30: {=_xll.PrecioBD(J30,24,"ASK","N")} -> 8800 | L30: {=_xll.PrecioBD(J30,24,"VOLUME AMOUNT","N")} -> 6035760 | M30: {=_xll.PrecioBD(J30,24,"IMBALANCE","N")} -> -0.0034
B31: DOW | C31: {=_xll.PrecioBD(B31,24,"ASK","N")} -> 7690 | D31: {=_xll.PrecioBD(B31,24,"VOLUME AMOUNT","N")} -> 114358905 | E31: {=_xll.PrecioBD(B31,24,"IMBALANCE","N")} -> -0.057 | J31: GLD | K31: {=_xll.PrecioBD(J31,24,"ASK","N")} -> 13370 | L31: {=_xll.PrecioBD(J31,24,"VOLUME AMOUNT","N")} -> 2767549920 | M31: {=_xll.PrecioBD(J31,24,"IMBALANCE","N")} -> -0.0161
B32: IP | C32: {=_xll.PrecioBD(B32,24,"ASK","N")} -> 17000 | D32: {=_xll.PrecioBD(B32,24,"VOLUME AMOUNT","N")} -> 224784100 | E32: {=_xll.PrecioBD(B32,24,"IMBALANCE","N")} -> -0.0112 | J32: DIA | K32: {=_xll.PrecioBD(J32,24,"ASK","N")} -> 36960 | L32: {=_xll.PrecioBD(J32,24,"VOLUME AMOUNT","N")} -> 868964960 | M32: {=_xll.PrecioBD(J32,24,"IMBALANCE","N")} -> -0.0064
B33: PSX | C33: {=_xll.PrecioBD(B33,24,"ASK","N")} -> 39260 | D33: {=_xll.PrecioBD(B33,24,"VOLUME AMOUNT","N")} -> 7041540 | E33: {=_xll.PrecioBD(B33,24,"IMBALANCE","N")} -> 0.0041 | J33: VEA | K33: {=_xll.PrecioBD(J33,24,"ASK","N")} -> 0 | L33: {=_xll.PrecioBD(J33,24,"VOLUME AMOUNT","N")} -> 92175345 | M33: {=_xll.PrecioBD(J33,24,"IMBALANCE","N")} -> -0.0104
B34: AAP | C34: {=_xll.PrecioBD(B34,24,"ASK","N")} -> 5720 | D34: {=_xll.PrecioBD(B34,24,"VOLUME AMOUNT","N")} -> 96757585 | E34: {=_xll.PrecioBD(B34,24,"IMBALANCE","N")} -> -0.0181 | J34: IEUR | K34: {=_xll.PrecioBD(J34,24,"ASK","N")} -> 10140 | L34: {=_xll.PrecioBD(J34,24,"VOLUME AMOUNT","N")} -> 36890210 | M34: {=_xll.PrecioBD(J34,24,"IMBALANCE","N")} -> -0.0078
B35: XROX | C35: {=_xll.PrecioBD(B35,24,"ASK","N")} -> 3395 | D35: {=_xll.PrecioBD(B35,24,"VOLUME AMOUNT","N")} -> 404035740 | E35: {=_xll.PrecioBD(B35,24,"IMBALANCE","N")} -> -0.0548 | J35: VXX | K35: {=_xll.PrecioBD(J35,24,"ASK","N")} -> 8665 | L35: {=_xll.PrecioBD(J35,24,"VOLUME AMOUNT","N")} -> 673293070 | M35: {=_xll.PrecioBD(J35,24,"IMBALANCE","N")} -> 0.0523
B36: BKR | C36: {=_xll.PrecioBD(B36,24,"ASK","N")} -> 12300 | D36: {=_xll.PrecioBD(B36,24,"VOLUME AMOUNT","N")} -> 451800 | E36: {=_xll.PrecioBD(B36,24,"IMBALANCE","N")} -> -0.0144 | J36: SPY | K36: {=_xll.PrecioBD(J36,24,"ASK","N")} -> 51100 | L36: {=_xll.PrecioBD(J36,24,"VOLUME AMOUNT","N")} -> 6013950575 | M36: {=_xll.PrecioBD(J36,24,"IMBALANCE","N")} -> -0.0082
B37: HPQ | C37: {=_xll.PrecioBD(B37,24,"ASK","N")} -> 30000 | D37: {=_xll.PrecioBD(B37,24,"VOLUME AMOUNT","N")} -> 177274720 | E37: {=_xll.PrecioBD(B37,24,"IMBALANCE","N")} -> -0.0407 | J37: IEMG | K37: {=_xll.PrecioBD(J37,24,"ASK","N")} -> 0 | L37: {=_xll.PrecioBD(J37,24,"VOLUME AMOUNT","N")} -> 30049325 | M37: {=_xll.PrecioBD(J37,24,"IMBALANCE","N")} -> 0.0005
B38: CAR | C38: {=_xll.PrecioBD(B38,24,"ASK","N")} -> 7340 | D38: {=_xll.PrecioBD(B38,24,"VOLUME AMOUNT","N")} -> 6055140 | E38: {=_xll.PrecioBD(B38,24,"IMBALANCE","N")} -> -0.0901 | J38: IWM | K38: {=_xll.PrecioBD(J38,24,"ASK","N")} -> 39140 | L38: {=_xll.PrecioBD(J38,24,"VOLUME AMOUNT","N")} -> 328708760 | M38: {=_xll.PrecioBD(J38,24,"IMBALANCE","N")} -> -0.0123
... B45: HMC | C45: {=_xll.PrecioBD(B45,24,"ASK","N")} -> 56000 | D45: {=_xll.PrecioBD(B45,24,"VOLUME AMOUNT","N")} -> 15724700 | E45: {=_xll.PrecioBD(B45,24,"IMBALANCE","N")} -> -0.005 | J45: URA | K45: {=_xll.PrecioBD(J45,24,"ASK","N")} -> 15100 | L45: {=_xll.PrecioBD(J45,24,"VOLUME AMOUNT","N")} -> 562502000 | M45: {=_xll.PrecioBD(J45,24,"IMBALANCE","N")} -> -0.0396
B46: GLOB | C46: {=_xll.PrecioBD(B46,24,"ASK","N")} -> 4725 | D46: {=_xll.PrecioBD(B46,24,"VOLUME AMOUNT","N")} -> 5.8005604e+08 | E46: {=_xll.PrecioBD(B46,24,"IMBALANCE","N")} -> -0.0566
B47: AVY | C47: {=_xll.PrecioBD(B47,24,"ASK","N")} -> 16360 | D47: {=_xll.PrecioBD(B47,24,"VOLUME AMOUNT","N")} -> 1971020 | E47: {=_xll.PrecioBD(B47,24,"IMBALANCE","N")} -> 0.0155
B48: MFG | C48: {=_xll.PrecioBD(B48,24,"ASK","N")} -> 13800 | D48: {=_xll.PrecioBD(B48,24,"VOLUME AMOUNT","N")} -> 5248160 | E48: {=_xll.PrecioBD(B48,24,"IMBALANCE","N")} -> -0.0195
B49: ARM | C49: {=_xll.PrecioBD(B49,24,"ASK","N")} -> 6490 | D49: {=_xll.PrecioBD(B49,24,"VOLUME AMOUNT","N")} -> 176602010 | E49: {=_xll.PrecioBD(B49,24,"IMBALANCE","N")} -> 0.0823
...

Sheet Opciones
A1: =_xll.PanelOpcionesBD() -> OPCIONES | B1: SIMBOLO | C1: VTO. | D1: MONEDA | E1: C.CPRA. | F1: P.CPRA. | G1: P.VTA. | H1: C.VTA. | I1: APERTURA | J1: MINIMO | K1: MAXIMO | L1: ULTIMO | M1: CIERRE ANT. | N1: VAR. | O1: VOLUMEN | P1: VOL.MONTO | Q1: VWAP | R1: CIERRE | S1: HORA
B2: A30C90000A | C2: 24hs | D2: ARS | E2: 0 | F2: 0 | G2: 0 | H2: 0 | I2: 0 | J2: 0 | K2: 0 | L2: 0 | M2: 0 | N2: 0 | O2: 0 | P2: 0 | Q2: 0 | R2: 0
B3: A30C90000F | C3: 24hs | D3: ARS | E3: 0 | F3: 0 | G3: 0 | H3: 0 | I3: 0 | J3: 0 | K3: 0 | L3: 0 | M3: 0 | N3: 0 | O3: 0 | P3: 0 | Q3: 0 | R3: 0
B4: A30C90000M | C4: 24hs | D4: ARS | E4: 0 | F4: 0 | G4: 0 | H4: 0 | I4: 0 | J4: 0 | K4: 0 | L4: 0 | M4: 0 | N4: 0 | O4: 0 | P4: 0 | Q4: 0 | R4: 0
B5: A30C92000A | C5: 24hs | D5: ARS | E5: 0 | F5: 0 | G5: 0 | H5: 0 | I5: 0 | J5: 0 | K5: 0 | L5: 0 | M5: 0 | N5: 0 | O5: 0 | P5: 0 | Q5: 0 | R5: 0
B6: A30C92000F | C6: 24hs | D6: ARS | E6: 0 | F6: 0 | G6: 0 | H6: 0 | I6: 0 | J6: 0 | K6: 0 | L6: 0 | M6: 0 | N6: 0 | O6: 0 | P6: 0 | Q6: 0 | R6: 0
B7: A30C92000M | C7: 24hs | D7: ARS | E7: 0 | F7: 0 | G7: 0 | H7: 0 | I7: 0 | J7: 0 | K7: 0 | L7: 0 | M7: 0 | N7: 0 | O7: 0 | P7: 0 | Q7: 0 | R7: 0
B8: A30V90000A | C8: 24hs | D8: ARS | E8: 0 | F8: 0 | G8: 0 | H8: 0 | I8: 0 | J8: 0 | K8: 0 | L8: 0 | M8: 0 | N8: 0 | O8: 0 | P8: 0 | Q8: 0 | R8: 0
B9: A30V90000F | C9: 24hs | D9: ARS | E9: 0 | F9: 0 | G9: 0 | H9: 0 | I9: 0 | J9: 0 | K9: 0 | L9: 0 | M9: 0 | N9: 0 | O9: 0 | P9: 0 | Q9: 0 | R9: 0
B10: A30V90000M | C10: 24hs | D10: ARS | E10: 0 | F10: 0 | G10: 0 | H10: 0 | I10: 0 | J10: 0 | K10: 0 | L10: 0 | M10: 0 | N10: 0 | O10: 0 | P10: 0 | Q10: 0 | R10: 0
B11: A30V92000A | C11: 24hs | D11: ARS | E11: 0 | F11: 0 | G11: 0 | H11: 0 | I11: 0 | J11: 0 | K11: 0 | L11: 0 | M11: 0 | N11: 0 | O11: 0 | P11: 0 | Q11: 0 | R11: 0
B12: A30V92000F | C12: 24hs | D12: ARS | E12: 0 | F12: 0 | G12: 0 | H12: 0 | I12: 0 | J12: 0 | K12: 0 | L12: 0 | M12: 0 | N12: 0 | O12: 0 | P12: 0 | Q12: 0 | R12: 0
B13: A30V92000M | C13: 24hs | D13: ARS | E13: 0 | F13: 0 | G13: 0 | H13: 0 | I13: 0 | J13: 0 | K13: 0 | L13: 0 | M13: 0 | N13: 0 | O13: 0 | P13: 0 | Q13: 0 | R13: 0
... B4206: TRAC4000AB | C4206: 24hs | D4206: ARS | E4206: 0 | F4206: 0 | G4206: 0 | H4206: 0 | I4206: 0 | J4206: 0 | K4206: 0 | L4206: 0 | M4206: 950 | N4206: 0 | O4206: 0 | P4206: 0 | Q4206: 0 | R4206: 950
B4207: TRAC4000FE | C4207: 24hs | D4207: ARS | E4207: 0 | F4207: 0 | G4207: 185 | H4207: 7 | I4207: 130 | J4207: 130 | K4207: 130 | L4207: 130 | M4207: 120 | N4207: 0.0833 | O4207: 5 | P4207: 65000 | Q4207: 130 | R4207: 130 | S4207: 13:06:14
B4208: TRAC4000JU | C4208: 24hs | D4208: ARS | E4208: 1 | F4208: 422.1 | G4208: 718.8 | H4208: 10 | I4208: 0 | J4208: 0 | K4208: 0 | L4208: 0 | M4208: 400 | N4208: 0 | O4208: 0 | P4208: 0 | Q4208: 0 | R4208: 400
B4209: TRAC4000MA | C4209: 24hs | D4209: ARS | E4209: 0 | F4209: 0 | G4209: 0 | H4209: 0 | I4209: 0 | J4209: 0 | K4209: 0 | L4209: 0 | M4209: 0 | N4209: 0 | O4209: 0 | P4209: 0 | Q4209: 0 | R4209: 0
B4210: TRAC4200AB | C4210: 24hs | D4210: ARS | E4210: 0 | F4210: 0 | G4210: 0 | H4210: 0 | I4210: 0 | J4210: 0 | K4210: 0 | L4210: 0 | M4210: 0 | N4210: 0 | O4210: 0 | P4210: 0 | Q4210: 0 | R4210: 0
B4211: TRAC4200FE | C4211: 24hs | D4211: ARS | E4211: 0 | F4211: 0 | G4211: 0 | H4211: 0 | I4211: 0 | J4211: 0 | K4211: 0 | L4211: 0 | M4211: 0 | N4211: 0 | O4211: 0 | P4211: 0 | Q4211: 0 | R4211: 0
B4212: TRAC4200JU | C4212: 24hs | D4212: ARS | E4212: 1 | F4212: 343.6 | G4212: 0 | H4212: 0 | I4212: 0 | J4212: 0 | K4212: 0 | L4212: 0 | M4212: 0 | N4212: 0 | O4212: 0 | P4212: 0 | Q4212: 0 | R4212: 0
B4213: TRAC4200MA | C4213: 24hs | D4213: ARS | E4213: 0 | F4213: 0 | G4213: 0 | H4213: 0 | I4213: 0 | J4213: 0 | K4213: 0 | L4213: 0 | M4213: 0 | N4213: 0 | O4213: 0 | P4213: 0 | Q4213: 0 | R4213: 0
B4214: TRAC4400AB | C4214: 24hs | D4214: ARS | E4214: 0 | F4214: 0 | G4214: 0 | H4214: 0 | I4214: 0 | J4214: 0 | K4214: 0 | L4214: 0 | M4214: 0 | N4214: 0 | O4214: 0 | P4214: 0 | Q4214: 0 | R4214: 0
B4215: TRAC4400FE | C4215: 24hs | D4215: ARS | E4215: 0 | F4215: 0 | G4215: 0 | H4215: 0 | I4215: 0 | J4215: 0 | K4215: 0 | L4215: 0 | M4215: 0 | N4215: 0 | O4215: 0 | P4215: 0 | Q4215: 0 | R4215: 0
B4216: TRAC4400JU | C4216: 24hs | D4216: ARS | E4216: 0 | F4216: 0 | G4216: 0 | H4216: 0 | I4216: 0 | J4216: 0 | K4216: 0 | L4216: 0 | M4216: 0 | N4216: 0 | O4216: 0 | P4216: 0 | Q4216: 0 | R4216: 0
B4217: TRAC4400MA | C4217: 24hs | D4217: ARS | E4217: 0 | F4217: 0 | G4217: 0 | H4217: 0 | I4217: 0 | J4217: 0 | K4217: 0 | L4217: 0 | M4217: 0 | N4217: 0 | O4217: 0 | P4217: 0 | Q4217: 0 | R4217: 0
B4218: TRAC4600AB | C4218: 24hs | D4218: ARS | E4218: 0 | F4218: 0 | G4218: 0 | H4218: 0 | I4218: 0 | J4218: 0 | K4218: 0 | L4218: 0 | M4218: 0 | N4218: 0 | O4218: 0 | P4218: 0 | Q4218: 0 | R4218: 0
B4219: TRAC4600FE | C4219: 24hs | D4219: ARS | E4219: 0 | F4219: 0 | G4219: 0 | H4219: 0 | I4219: 0 | J4219: 0 | K4219: 0 | L4219: 0 | M4219: 0 | N4219: 0 | O4219: 0 | P4219: 0 | Q4219: 0 | R4219: 0
... B4333: TXAC54.0JU | C4333: 24hs | D4333: ARS | E4333: 0 | F4333: 0 | G4333: 0 | H4333: 0 | I4333: 0 | J4333: 0 | K4333: 0 | L4333: 0 | M4333: 0 | N4333: 0 | O4333: 0 | P4333: 0 | Q4333: 0 | R4333: 0
B4334: TXAC54807F | C4334: 24hs | D4334: ARS | E4334: 0 | F4334: 0 | G4334: 202 | H4334: 10 | I4334: 163 | J4334: 160 | K4334: 163 | L4334: 160 | M4334: 164.5 | N4334: -0.0273 | O4334: 20 | P4334: 323000 | Q4334: 161.5 | R4334: 161.5 | S4334: 15:16:51
B4335: TXAC550.FE | C4335: 24hs | D4335: ARS | E4335: 0 | F4335: 0 | G4335: 0 | H4335: 0 | I4335: 0 | J4335: 0 | K4335: 0 | L4335: 0 | M4335: 0 | N4335: 0 | O4335: 0 | P4335: 0 | Q4335: 0 | R4335: 0
B4336: TXAC56.0AB | C4336: 24hs | D4336: ARS | E4336: 0 | F4336: 0 | G4336: 0 | H4336: 0 | I4336: 0 | J4336: 0 | K4336: 0 | L4336: 0 | M4336: 0 | N4336: 0 | O4336: 0 | P4336: 0 | Q4336: 0 | R4336: 0
B4337: TXAC56.0AG | C4337: 24hs | D4337: ARS | E4337: 0 | F4337: 0 | G4337: 0 | H4337: 0 | I4337: 0 | J4337: 0 | K4337: 0 | L4337: 0 | M4337: 0 | N4337: 0 | O4337: 0 | P4337: 0 | Q4337: 0 | R4337: 0
B4338: TXAC56.0FE | C4338: 24hs | D4338: ARS | E4338: 0 | F4338: 0 | G4338: 0 | H4338: 0 | I4338: 0 | J4338: 0 | K4338: 0 | L4338: 0 | M4338: 0 | N4338: 0 | O4338: 0 | P4338: 0 | Q4338: 0 | R4338: 0
B4339: TXAC56.0JU | C4339: 24hs | D4339: ARS | E4339: 0 | F4339: 0 | G4339: 0 | H4339: 0 | I4339: 0 | J4339: 0 | K4339: 0 | L4339: 0 | M4339: 0 | N4339: 0 | O4339: 0 | P4339: 0 | Q4339: 0 | R4339: 0
B4340: TXAC56.0OC | C4340: 24hs | D4340: ARS | E4340: 0 | F4340: 0 | G4340: 0 | H4340: 0 | I4340: 0 | J4340: 0 | K4340: 0 | L4340: 0 | M4340: 0 | N4340: 0 | O4340: 0 | P4340: 0 | Q4340: 0 | R4340: 0
B4341: TXAC58.0AB | C4341: 24hs | D4341: ARS | E4341: 0 | F4341: 0 | G4341: 0 | H4341: 0 | I4341: 0 | J4341: 0 | K4341: 0 | L4341: 0 | M4341: 0 | N4341: 0 | O4341: 0 | P4341: 0 | Q4341: 0 | R4341: 0
B4342: TXAC58.0AG | C4342: 24hs | D4342: ARS | E4342: 0 | F4342: 0 | G4342: 0 | H4342: 0 | I4342: 0 | J4342: 0 | K4342: 0 | L4342: 0 | M4342: 0 | N4342: 0 | O4342: 0 | P4342: 0 | Q4342: 0 | R4342: 0
B4343: TXAC59807F | C4343: 24hs | D4343: ARS | E4343: 0 | F4343: 0 | G4343: 0 | H4343: 0 | I4343: 0 | J4343: 0 | K4343: 0 | L4343: 0 | M4343: 130.27 | N4343: 0 | O4343: 0 | P4343: 0 | Q4343: 0 | R4343: 130.27
B4344: TXAC60.0AB | C4344: 24hs | D4344: ARS | E4344: 0 | F4344: 0 | G4344: 0 | H4344: 0 | I4344: 0 | J4344: 0 | K4344: 0 | L4344: 0 | M4344: 0 | N4344: 0 | O4344: 0 | P4344: 0 | Q4344: 0 | R4344: 0
B4345: TXAC60.0AG | C4345: 24hs | D4345: ARS | E4345: 0 | F4345: 0 | G4345: 0 | H4345: 0 | I4345: 0 | J4345: 0 | K4345: 0 | L4345: 0 | M4345: 0 | N4345: 0 | O4345: 0 | P4345: 0 | Q4345: 0 | R4345: 0
...

Sheet Caucho
A1: {=_xll.PanelCaucionesBD("S")} -> CAUCIONES | B1: SIMBOLO | C1: ESPECIE | D1: MONEDA | E1: PLAZO | F1: VTO. | G1: TASA | H1: CANT.OPER | I1: MONTO | J1: M.TOM | K1: T.TOM | L1: T.COL | M1: M.COL | N1: VWAP
B2: DOLAR-0203-U-CT-USD | D2: USD | E2: 24 | F2: 2026-03-02 | G2: 0 | H2: 0 | I2: 0 | J2: 50000 | K2: 0.0063 | L2: 0.03 | M2: 800 | N2: 0
B3: DOLAR-0206-U-CT-USD | D3: USD | E3: 116 | F3: 2026-06-02 | G3: 0 | H3: 0 | I3: 0 | J3: 0 | K3: 0 | L3: 0 | M3: 0 | N3: 0
B4: DOLAR-0303-U-CT-USD | D4: USD | E4: 25 | F4: 2026-03-03 | G4: 0 | H4: 0 | I4: 0 | J4: 25000 | K4: 0.0073 | L4: 0.03 | M4: 800 | N4: 0
B5: DOLAR-0403-U-CT-USD | D5: USD | E5: 26 | F5: 2026-03-04 | G5: 0.0075 | H5: 0 | I5: 588.33 | J5: 49412 | K5: 0.0075 | L5: 0.0299 | M5: 18312 | N5: 0.0075
B6: DOLAR-0405-U-CT-USD | D6: USD | E6: 87 | F6: 2026-05-04 | G6: 0 | H6: 0 | I6: 0 | J6: 50000 | K6: 0.007 | L6: 0 | M6: 0 | N6: 0
B7: DOLAR-0406-U-CT-USD | D7: USD | E7: 118 | F7: 2026-06-04 | G7: 0 | H7: 0 | I7: 0 | J7: 0 | K7: 0 | L7: 0 | M7: 0 | N7: 0
B8: DOLAR-0503-U-CT-USD | D8: USD | E8: 27 | F8: 2026-03-05 | G8: 0 | H8: 0 | I8: 0 | J8: 25000 | K8: 0.0068 | L8: 0.0295 | M8: 317 | N8: 0
B9: DOLAR-0505-U-CT-USD | D9: USD | E9: 88 | F9: 2026-05-05 | G9: 0 | H9: 0 | I9: 0 | J9: 0 | K9: 0 | L9: 0 | M9: 0 | N9: 0
B10: DOLAR-0506-U-CT-USD | D10: USD | E10: 119 | F10: 2026-06-05 | G10: 0.03 | H10: 0 | I10: 93845.07 | J10: 0 | K10: 0 | L10: 0.035 | M10: 60567 | N10: 0.03021523
B11: DOLAR-0602-U-CT-USD | D11: USD | E11: 0 | F11: 2026-02-06 | G11: 0.005 | H11: 0 | I11: 7.9885928e+08 | J11: 122529 | K11: 0.005 | L11: 0.008 | M11: 12212 | N11: 0.01079838
B12: DOLAR-0603-U-CT-USD | D12: USD | E12: 28 | F12: 2026-03-06 | G12: 0.026 | H12: 0 | I12: 15503.94 | J12: 18168 | K12: 0.011 | L12: 0.026 | M12: 51306 | N12: 0.02680447
B13: DOLAR-0604-U-CT-USD | D13: USD | E13: 59 | F13: 2026-04-06 | G13: 0.025 | H13: 0 | I13: 440804.11 | J13: 0 | K13: 0 | L13: 0 | M13: 0 | N13: 0.025
... B144: PESOS-3103-U-CT-ARS | D144: ARS | E144: 53 | F144: 2026-03-31 | G144: 0.211 | H144: 0 | I144: 207171.38 | J144: 299100 | K144: 0.211 | L144: 0 | M144: 0 | N144: 0.211
B145: PESOS-3103-U-CT-ARS | C145: PESOS | D145: ARS | E145: 55 | F145: 2026-03-31 | G145: 0 | H145: 0 | I145: 0 | J145: 0 | K145: 0 | L145: 0 | M145: 0 | N145: 0

Sheet Soberanos HD
F1: Comisión | G1: 1
F2: Fecha de liquidación | G2: =Main!B1 -> 46060
B4: Ticker | C4: TIR | D4: Precio con comisión | E4: Precio sin comisión | F4: MD | G4: Variación | H4: Bid | I4: Ask | J4: Bid Volume | K4: Ask volume | L4: Total volume | M4: Vto | N4: Ley | O4: Periodicidad | P4: Lamina minima | Q4: Tipo
B5: AL29D | C5: =AL29D!K4 -> 0.088069263 | D5: =E5*$G$1 -> 60.97 | E5: {=_xll.PrecioBD(ONs_NY8[[#This Row],[Ticker]],24,"ASK","N")} -> 60.97 | F5: =AL30D!K2 -> 0.5 | G5: {=_xll.PrecioBD(ONs_NY8[[#This Row],[Ticker]],24,"IMBALANCE","N")} -> 0.0013 | H5: {=_xll.PrecioBD(ONs_NY8[[#This Row],[Ticker]],"24","BID","N")} -> 60.88 | I5: {=_xll.PrecioBD(ONs_NY8[[#This Row],[Ticker]],"24","ASK","N")} -> 60.97 | J5: {=_xll.PrecioBD(ONs_NY8[[#This Row],[Ticker]],24,"QUANTITY BID","N")} -> 1732 | K5: {=_xll.PrecioBD(ONs_NY8[[#This Row],[Ticker]],24,"QUANTITY ASK","N")} -> 3095 | L5: {=_xll.PrecioBD(ONs_NY8[[#This Row],[Ticker]],24,"VOLUME AMOUNT","N")} -> 915582.46 | N5: ARG
B6: AL30D | C6: =AL30D!K4 -> 0.09034898 | D6: =E6*$G$1 -> 60.58 | E6: {=_xll.PrecioBD(ONs_NY8[[#This Row],[Ticker]],24,"ASK","N")} -> 60.58 | F6: =AL30D!K3 -> 2.1755694 | G6: {=_xll.PrecioBD(ONs_NY8[[#This Row],[Ticker]],24,"IMBALANCE","N")} -> 0.0048 | H6: {=_xll.PrecioBD(ONs_NY8[[#This Row],[Ticker]],"24","BID","N")} -> 60.54 | I6: {=_xll.PrecioBD(ONs_NY8[[#This Row],[Ticker]],"24","ASK","N")} -> 60.58 | J6: {=_xll.PrecioBD(ONs_NY8[[#This Row],[Ticker]],24,"QUANTITY BID","N")} -> 4723 | K6: {=_xll.PrecioBD(ONs_NY8[[#This Row],[Ticker]],24,"QUANTITY ASK","N")} -> 16351 | L6: {=_xll.PrecioBD(ONs_NY8[[#This Row],[Ticker]],24,"VOLUME AMOUNT","N")} -> 62804134 | N6: ARG
B7: AL35D | C7: =AL35D!K4 -> 0.091250238 | D7: =E7*$G$1 -> 78.67 | E7: {=_xll.PrecioBD(ONs_NY8[[#This Row],[Ticker]],24,"ASK","N")} -> 78.67 | F7: =AL35D!K3 -> 5.6790308 | G7: {=_xll.PrecioBD(ONs_NY8[[#This Row],[Ticker]],24,"IMBALANCE","N")} -> -0.0005 | H7: {=_xll.PrecioBD(ONs_NY8[[#This Row],[Ticker]],"24","BID","N")} -> 78.45 | I7: {=_xll.PrecioBD(ONs_NY8[[#This Row],[Ticker]],"24","ASK","N")} -> 78.67 | J7: {=_xll.PrecioBD(ONs_NY8[[#This Row],[Ticker]],24,"QUANTITY BID","N")} -> 2003 | K7: {=_xll.PrecioBD(ONs_NY8[[#This Row],[Ticker]],24,"QUANTITY ASK","N")} -> 500 | L7: {=_xll.PrecioBD(ONs_NY8[[#This Row],[Ticker]],24,"VOLUME AMOUNT","N")} -> 3641468.5 | N7: ARG
B8: AE38D | C8: =AE38D!K4 -> 0.096076125 | D8: =E8*$G$1 -> 80.05 | E8: {=_xll.PrecioBD(ONs_NY8[[#This Row],[Ticker]],24,"ASK","N")} -> 80.05 | F8: =AE38D!K3 -> 4.9019119 | G8: {=_xll.PrecioBD(ONs_NY8[[#This Row],[Ticker]],24,"IMBALANCE","N")} -> -0.0007 | H8: {=_xll.PrecioBD(ONs_NY8[[#This Row],[Ticker]],"24","BID","N")} -> 79.9 | I8: {=_xll.PrecioBD(ONs_NY8[[#This Row],[Ticker]],"24","ASK","N")} -> 80.05 | J8: {=_xll.PrecioBD(ONs_NY8[[#This Row],[Ticker]],24,"QUANTITY BID","N")} -> 8 | K8: {=_xll.PrecioBD(ONs_NY8[[#This Row],[Ticker]],24,"QUANTITY ASK","N")} -> 10000 | L8: {=_xll.PrecioBD(ONs_NY8[[#This Row],[Ticker]],24,"VOLUME AMOUNT","N")} -> 3809578.6 | N8: ARG
B9: AL41D | C9: =AL41D!K4 -> 0.069507185 | D9: =E9*$G$1 -> 73.35 | E9: {=_xll.PrecioBD(ONs_NY8[[#This Row],[Ticker]],24,"ASK","N")} -> 73.35 | F9: =AL41D!K3 -> 7.5551069 | G9: {=_xll.PrecioBD(ONs_NY8[[#This Row],[Ticker]],24,"IMBALANCE","N")} -> -0.0083 | H9: {=_xll.PrecioBD(ONs_NY8[[#This Row],[Ticker]],"24","BID","N")} -> 73.14 | I9: {=_xll.PrecioBD(ONs_NY8[[#This Row],[Ticker]],"24","ASK","N")} -> 73.35 | J9: {=_xll.PrecioBD(ONs_NY8[[#This Row],[Ticker]],24,"QUANTITY BID","N")} -> 1367 | K9: {=_xll.PrecioBD(ONs_NY8[[#This Row],[Ticker]],24,"QUANTITY ASK","N")} -> 114 | L9: {=_xll.PrecioBD(ONs_NY8[[#This Row],[Ticker]],24,"VOLUME AMOUNT","N")} -> 747448.48 | N9: ARG
B10: GD29D | C10: =GD29D!K4 -> 0.06248239 | D10: =E10*$G$1 -> 63.7 | E10: {=_xll.PrecioBD(ONs_NY8[[#This Row],[Ticker]],24,"ASK","N")} -> 63.7 | F10: =GD29D!K3 -> 1.7972543 | G10: {=_xll.PrecioBD(ONs_NY8[[#This Row],[Ticker]],24,"IMBALANCE","N")} -> 0 | H10: {=_xll.PrecioBD(ONs_NY8[[#This Row],[Ticker]],"24","BID","N")} -> 63.35 | I10: {=_xll.PrecioBD(ONs_NY8[[#This Row],[Ticker]],"24","ASK","N")} -> 63.7 | J10: {=_xll.PrecioBD(ONs_NY8[[#This Row],[Ticker]],24,"QUANTITY BID","N")} -> 7023 | K10: {=_xll.PrecioBD(ONs_NY8[[#This Row],[Ticker]],24,"QUANTITY ASK","N")} -> 12163 | L10: {=_xll.PrecioBD(ONs_NY8[[#This Row],[Ticker]],24,"VOLUME AMOUNT","N")} -> 267963.14 | N10: NY
B11: GD30D | C11: =GD30D!K4 -> 0.070274821 | D11: =E11*$G$1 -> 63.21 | E11: {=_xll.PrecioBD(ONs_NY8[[#This Row],[Ticker]],24,"ASK","N")} -> 63.21 | F11: =GD30D!K3 -> 2.2254087 | G11: {=_xll.PrecioBD(ONs_NY8[[#This Row],[Ticker]],24,"IMBALANCE","N")} -> 0.0017 | H11: {=_xll.PrecioBD(ONs_NY8[[#This Row],[Ticker]],"24","BID","N")} -> 62.25 | I11: {=_xll.PrecioBD(ONs_NY8[[#This Row],[Ticker]],"24","ASK","N")} -> 63.21 | J11: {=_xll.PrecioBD(ONs_NY8[[#This Row],[Ticker]],24,"QUANTITY BID","N")} -> 7891 | K11: {=_xll.PrecioBD(ONs_NY8[[#This Row],[Ticker]],24,"QUANTITY ASK","N")} -> 4 | L11: {=_xll.PrecioBD(ONs_NY8[[#This Row],[Ticker]],24,"VOLUME AMOUNT","N")} -> 2590984.1 | N11: NY
B12: GD35D | C12: =GD35D!K4 -> 0.088632891 | D12: =E12*$G$1 -> 79.8 | E12: {=_xll.PrecioBD(ONs_NY8[[#This Row],[Ticker]],24,"ASK","N")} -> 79.8 | F12: =GD35D!K3 -> 5.6982618 | G12: {=_xll.PrecioBD(ONs_NY8[[#This Row],[Ticker]],24,"IMBALANCE","N")} -> -0.0023 | H12: {=_xll.PrecioBD(ONs_NY8[[#This Row],[Ticker]],"24","BID","N")} -> 79.2 | I12: {=_xll.PrecioBD(ONs_NY8[[#This Row],[Ticker]],"24","ASK","N")} -> 79.8 | J12: {=_xll.PrecioBD(ONs_NY8[[#This Row],[Ticker]],24,"QUANTITY BID","N")} -> 3672 | K12: {=_xll.PrecioBD(ONs_NY8[[#This Row],[Ticker]],24,"QUANTITY ASK","N")} -> 11000 | L12: {=_xll.PrecioBD(ONs_NY8[[#This Row],[Ticker]],24,"VOLUME AMOUNT","N")} -> 3080649 | N12: NY
B13: GD38D | C13: =GD38D!K4 -> 0.088778743 | D13: =E13*$G$1 -> 82.86 | E13: {=_xll.PrecioBD(ONs_NY8[[#This Row],[Ticker]],24,"ASK","N")} -> 82.86 | F13: =GD38D!K3 -> 4.9813448 | G13: {=_xll.PrecioBD(ONs_NY8[[#This Row],[Ticker]],24,"IMBALANCE","N")} -> -0.0016 | H13: {=_xll.PrecioBD(ONs_NY8[[#This Row],[Ticker]],"24","BID","N")} -> 82.7 | I13: {=_xll.PrecioBD(ONs_NY8[[#This Row],[Ticker]],"24","ASK","N")} -> 82.86 | J13: {=_xll.PrecioBD(ONs_NY8[[#This Row],[Ticker]],24,"QUANTITY BID","N")} -> 2856 | K13: {=_xll.PrecioBD(ONs_NY8[[#This Row],[Ticker]],24,"QUANTITY ASK","N")} -> 44241 | L13: {=_xll.PrecioBD(ONs_NY8[[#This Row],[Ticker]],24,"VOLUME AMOUNT","N")} -> 222622 | N13: NY
B14: GD41D | C14: =GD41D!K4 -> 0.067179868 | D14: =E14*$G$1 -> 74.28 | E14: {=_xll.PrecioBD(ONs_NY8[[#This Row],[Ticker]],24,"ASK","N")} -> 74.28 | F14: =GD41D!K3 -> 7.6189885 | G14: {=_xll.PrecioBD(ONs_NY8[[#This Row],[Ticker]],24,"IMBALANCE","N")} -> -0.0022 | H14: {=_xll.PrecioBD(ONs_NY8[[#This Row],[Ticker]],"24","BID","N")} -> 74.08 | I14: {=_xll.PrecioBD(ONs_NY8[[#This Row],[Ticker]],"24","ASK","N")} -> 74.28 | J14: {=_xll.PrecioBD(ONs_NY8[[#This Row],[Ticker]],24,"QUANTITY BID","N")} -> 200 | K14: {=_xll.PrecioBD(ONs_NY8[[#This Row],[Ticker]],24,"QUANTITY ASK","N")} -> 5000 | L14: {=_xll.PrecioBD(ONs_NY8[[#This Row],[Ticker]],24,"VOLUME AMOUNT","N")} -> 1153333.2 | N14: NY

Sheet ONS NY
G1: Comisión | H1: 1
G2: Fecha de liquidación | H2: =Main!B1 -> 46060
B4: Empresa | C4: Ticker | D4: TIR | E4: Precio con comisión | F4: Precio sin comisión | G4: MD | H4: Vto | I4: Bid | J4: Ask | K4: Bid Volume | L4: Ask volume | M4: Total volume | N4: Variación | O4: Ley | P4: Periodicidad | Q4: Lamina minima | R4: Tipo
B5: YPF | C5: YMCHD | D5: =YMCHO!K4 -> #NUM! | E5: =F5*$H$1 -> 0 | F5: {=_xll.PrecioBD(ONs_NY[[#This Row],[Ticker]],24,"ASK","N")} -> 0 | G5: =YMCHO!K3 -> #NUM! | H5: 46065 | I5: {=_xll.PrecioBD(ONs_NY[[#This Row],[Ticker]],"24","BID","N")} -> 0 | J5: {=_xll.PrecioBD(ONs_NY[[#This Row],[Ticker]],"24","ASK","N")} -> 0 | K5: {=_xll.PrecioBD(ONs_NY[[#This Row],[Ticker]],24,"QUANTITY BID","N")} -> 0 | L5: {=_xll.PrecioBD(ONs_NY[[#This Row],[Ticker]],24,"QUANTITY ASK","N")} -> 0 | M5: {=_xll.PrecioBD(ONs_NY[[#This Row],[Ticker]],24,"VOLUME AMOUNT","N")} -> 0 | N5: {=_xll.PrecioBD(ONs_NY[[#This Row],[Ticker]],24,"IMBALANCE","N")} -> 0 | O5: NY | P5: Trimestral | Q5: 1 | R5: Sinkable
B6: Genneia | C6: GNCXD | D6: =GNCXD!K4 -> #NUM! | E6: =F6*$H$1 -> 0 | F6: {=_xll.PrecioBD(ONs_NY[[#This Row],[Ticker]],24,"ASK","N")} -> 0 | G6: =GNCXD!K3 -> #NUM! | H6: 46632 | I6: {=_xll.PrecioBD(ONs_NY[[#This Row],[Ticker]],"24","BID","N")} -> 0 | J6: {=_xll.PrecioBD(ONs_NY[[#This Row],[Ticker]],"24","ASK","N")} -> 0 | K6: {=_xll.PrecioBD(ONs_NY[[#This Row],[Ticker]],24,"QUANTITY BID","N")} -> 0 | L6: {=_xll.PrecioBD(ONs_NY[[#This Row],[Ticker]],24,"QUANTITY ASK","N")} -> 0 | M6: {=_xll.PrecioBD(ONs_NY[[#This Row],[Ticker]],24,"VOLUME AMOUNT","N")} -> 0 | N6: {=_xll.PrecioBD(ONs_NY[[#This Row],[Ticker]],24,"IMBALANCE","N")} -> 0 | O6: NY | P6: Semestral | Q6: 1000 | R6: Sinkable
B7: Arcor | C7: RCCJD | D7: =RCCJD!K4 -> #NUM! | E7: =F7*$H$1 -> 0 | F7: {=_xll.PrecioBD(ONs_NY[[#This Row],[Ticker]],24,"ASK","N")} -> 0 | G7: =RCCJD!K3 -> #NUM! | H7: 46669 | I7: {=_xll.PrecioBD(ONs_NY[[#This Row],[Ticker]],"24","BID","N")} -> 0 | J7: {=_xll.PrecioBD(ONs_NY[[#This Row],[Ticker]],"24","ASK","N")} -> 0 | K7: {=_xll.PrecioBD(ONs_NY[[#This Row],[Ticker]],24,"QUANTITY BID","N")} -> 0 | L7: {=_xll.PrecioBD(ONs_NY[[#This Row],[Ticker]],24,"QUANTITY ASK","N")} -> 0 | M7: {=_xll.PrecioBD(ONs_NY[[#This Row],[Ticker]],24,"VOLUME AMOUNT","N")} -> 0 | N7: {=_xll.PrecioBD(ONs_NY[[#This Row],[Ticker]],24,"IMBALANCE","N")} -> 0 | O7: NY
B8: Pampa energia | C8: MGC9D | D8: =MGC9D!K4 -> #NUM! | E8: =F8*$H$1 -> 0 | F8: {=_xll.PrecioBD(ONs_NY[[#This Row],[Ticker]],24,"ASK","N")} -> 0 | G8: =MGC9D!K3 -> #NUM! | H8: 46364 | I8: {=_xll.PrecioBD(ONs_NY[[#This Row],[Ticker]],"24","BID","N")} -> 0 | J8: {=_xll.PrecioBD(ONs_NY[[#This Row],[Ticker]],"24","ASK","N")} -> 0 | K8: {=_xll.PrecioBD(ONs_NY[[#This Row],[Ticker]],24,"QUANTITY BID","N")} -> 0 | L8: {=_xll.PrecioBD(ONs_NY[[#This Row],[Ticker]],24,"QUANTITY ASK","N")} -> 0 | M8: {=_xll.PrecioBD(ONs_NY[[#This Row],[Ticker]],24,"VOLUME AMOUNT","N")} -> 0 | N8: {=_xll.PrecioBD(ONs_NY[[#This Row],[Ticker]],24,"IMBALANCE","N")} -> 0 | O8: NY | P8: Semestral | Q8: 1 | R8: Sinkable
B9: MSU Energy | C9: RUCDD | D9: =RUCDO!K4 -> 0.09084594 | E9: =F9*$H$1 -> 104.7 | F9: {=_xll.PrecioBD(ONs_NY[[#This Row],[Ticker]],24,"ASK","N")} -> 104.7 | G9: =RUCDO!K3 -> 3.4036364 | H9: 47822 | I9: {=_xll.PrecioBD(ONs_NY[[#This Row],[Ticker]],"24","BID","N")} -> 104.35 | J9: {=_xll.PrecioBD(ONs_NY[[#This Row],[Ticker]],"24","ASK","N")} -> 104.7 | K9: {=_xll.PrecioBD(ONs_NY[[#This Row],[Ticker]],24,"QUANTITY BID","N")} -> 514 | L9: {=_xll.PrecioBD(ONs_NY[[#This Row],[Ticker]],24,"QUANTITY ASK","N")} -> 2596 | M9: {=_xll.PrecioBD(ONs_NY[[#This Row],[Ticker]],24,"VOLUME AMOUNT","N")} -> 140759.64 | N9: {=_xll.PrecioBD(ONs_NY[[#This Row],[Ticker]],24,"IMBALANCE","N")} -> 0.0004 | O9: NY | P9: Semestral | Q9: 1 | R9: Sinkable
B10: Edenor | C10: DNC7D | D10: =DNC7D!K4 -> 0.088900277 | E10: =F10*$H$1 -> 106.05 | F10: {=_xll.PrecioBD(ONs_NY[[#This Row],[Ticker]],24,"ASK","N")} -> 106.05 | G10: =DNC7D!K3 -> 2.9828026 | H10: 47780 | I10: {=_xll.PrecioBD(ONs_NY[[#This Row],[Ticker]],"24","BID","N")} -> 105.85 | J10: {=_xll.PrecioBD(ONs_NY[[#This Row],[Ticker]],"24","ASK","N")} -> 106.05 | K10: {=_xll.PrecioBD(ONs_NY[[#This Row],[Ticker]],24,"QUANTITY BID","N")} -> 1000 | L10: {=_xll.PrecioBD(ONs_NY[[#This Row],[Ticker]],24,"QUANTITY ASK","N")} -> 2900 | M10: {=_xll.PrecioBD(ONs_NY[[#This Row],[Ticker]],24,"VOLUME AMOUNT","N")} -> 314361.7 | N10: {=_xll.PrecioBD(ONs_NY[[#This Row],[Ticker]],24,"IMBALANCE","N")} -> 0.0014 | O10: NY | P10: Semestral | Q10: 100 | R10: Sinkable
B11: Telecom | C11: TLCTD | D11: =TLCTD!K4 -> 0.078768 | E11: =F11*$H$1 -> 105.5 | F11: {=_xll.PrecioBD(ONs_NY[[#This Row],[Ticker]],24,"ASK","N")} -> 105.5 | G11: =TLCTD!K3 -> 6.4810689 | H11: 49695 | I11: {=_xll.PrecioBD(ONs_NY[[#This Row],[Ticker]],"24","BID","N")} -> 105.4 | J11: {=_xll.PrecioBD(ONs_NY[[#This Row],[Ticker]],"24","ASK","N")} -> 105.5 | K11: {=_xll.PrecioBD(ONs_NY[[#This Row],[Ticker]],24,"QUANTITY BID","N")} -> 2918 | L11: {=_xll.PrecioBD(ONs_NY[[#This Row],[Ticker]],24,"QUANTITY ASK","N")} -> 1650 | M11: {=_xll.PrecioBD(ONs_NY[[#This Row],[Ticker]],24,"VOLUME AMOUNT","N")} -> 556489.95 | N11: {=_xll.PrecioBD(ONs_NY[[#This Row],[Ticker]],24,"IMBALANCE","N")} -> 0.0004 | O11: NY
B12: Telecom | C12: TLCPD | D12: =TLCPD!K4 -> 0.078323558 | E12: =F12*$H$1 -> 110.65 | F12: {=_xll.PrecioBD(ONs_NY[[#This Row],[Ticker]],24,"ASK","N")} -> 110.65 | G12: =TLCPD!K3 -> 4.9773841 | H12: 48726 | I12: {=_xll.PrecioBD(ONs_NY[[#This Row],[Ticker]],"24","BID","N")} -> 110.3 | J12: {=_xll.PrecioBD(ONs_NY[[#This Row],[Ticker]],"24","ASK","N")} -> 110.65 | K12: {=_xll.PrecioBD(ONs_NY[[#This Row],[Ticker]],24,"QUANTITY BID","N")} -> 1500 | L12: {=_xll.PrecioBD(ONs_NY[[#This Row],[Ticker]],24,"QUANTITY ASK","N")} -> 9401 | M12: {=_xll.PrecioBD(ONs_NY[[#This Row],[Ticker]],24,"VOLUME AMOUNT","N")} -> 289294.74 | N12: {=_xll.PrecioBD(ONs_NY[[#This Row],[Ticker]],24,"IMBALANCE","N")} -> -0.0018 | O12: NY | P12: Semestral | Q12: 100 | R12: Sinkable
B13: Pampa energia | C13: MGCRD | D13: =MGCRD!K4 -> 0.074627194 | E13: =F13*$H$1 -> 105.1 | F13: {=_xll.PrecioBD(ONs_NY[[#This Row],[Ticker]],24,"ASK","N")} -> 105.1 | G13: =MGCRD!K3 -> 7.5846465 | H13: 50360 | I13: {=_xll.PrecioBD(ONs_NY[[#This Row],[Ticker]],"24","BID","N")} -> 104.8 | J13: {=_xll.PrecioBD(ONs_NY[[#This Row],[Ticker]],"24","ASK","N")} -> 105.1 | K13: {=_xll.PrecioBD(ONs_NY[[#This Row],[Ticker]],24,"QUANTITY BID","N")} -> 10000 | L13: {=_xll.PrecioBD(ONs_NY[[#This Row],[Ticker]],24,"QUANTITY ASK","N")} -> 10000 | M13: {=_xll.PrecioBD(ONs_NY[[#This Row],[Ticker]],24,"VOLUME AMOUNT","N")} -> 146740 | N13: {=_xll.PrecioBD(ONs_NY[[#This Row],[Ticker]],24,"IMBALANCE","N")} -> -0.0019 | O13: NY | P13: Semestral | Q13: 10000 | R13: Bullet
B14: YPF | C14: YM34D | D14: =YM34D!K4 -> 0.072824374 | E14: =F14*$H$1 -> 106.45 | F14: {=_xll.PrecioBD(ONs_NY[[#This Row],[Ticker]],24,"ASK","N")} -> 106.45 | G14: =YM34D!K3 -> 5.3076418 | H14: 48961 | I14: {=_xll.PrecioBD(ONs_NY[[#This Row],[Ticker]],"24","BID","N")} -> 106.15 | J14: {=_xll.PrecioBD(ONs_NY[[#This Row],[Ticker]],"24","ASK","N")} -> 106.45 | K14: {=_xll.PrecioBD(ONs_NY[[#This Row],[Ticker]],24,"QUANTITY BID","N")} -> 35 | L14: {=_xll.PrecioBD(ONs_NY[[#This Row],[Ticker]],24,"QUANTITY ASK","N")} -> 1999 | M14: {=_xll.PrecioBD(ONs_NY[[#This Row],[Ticker]],24,"VOLUME AMOUNT","N")} -> 920344.59 | N14: {=_xll.PrecioBD(ONs_NY[[#This Row],[Ticker]],24,"IMBALANCE","N")} -> 0.0033 | O14: NY | P14: Semestral | Q14: 1 | R14: Sinkable
B15: Pluspetrol | C15: PLC4D | D15: =PCL4D!K4 -> 0.073033872 | E15: =F15*$H$1 -> 108.2 | F15: {=_xll.PrecioBD(ONs_NY[[#This Row],[Ticker]],24,"ASK","N")} -> 108.2 | G15: =PCL4D!K3 -> 4.8172422 | H15: 48364 | I15: {=_xll.PrecioBD(ONs_NY[[#This Row],[Ticker]],"24","BID","N")} -> 107.8 | J15: {=_xll.PrecioBD(ONs_NY[[#This Row],[Ticker]],"24","ASK","N")} -> 108.2 | K15: {=_xll.PrecioBD(ONs_NY[[#This Row],[Ticker]],24,"QUANTITY BID","N")} -> 1000 | L15: {=_xll.PrecioBD(ONs_NY[[#This Row],[Ticker]],24,"QUANTITY ASK","N")} -> 2000 | M15: {=_xll.PrecioBD(ONs_NY[[#This Row],[Ticker]],24,"VOLUME AMOUNT","N")} -> 405314.5 | N15: {=_xll.PrecioBD(ONs_NY[[#This Row],[Ticker]],24,"IMBALANCE","N")} -> 0.0027 | O15: NY | P15: Semestral | Q15: 1000 | R15: Bullet
B16: TGS | C16: TSC4D | D16: =TSC4D!K4 -> 0.073101494 | E16: =F16*$H$1 -> 105.65 | F16: {=_xll.PrecioBD(ONs_NY[[#This Row],[Ticker]],24,"ASK","N")} -> 105.65 | G16: =TSC4D!K3 -> 2.0859148 | H16: 49633 | I16: {=_xll.PrecioBD(ONs_NY[[#This Row],[Ticker]],"24","BID","N")} -> 105.4 | J16: {=_xll.PrecioBD(ONs_NY[[#This Row],[Ticker]],"24","ASK","N")} -> 105.65 | K16: {=_xll.PrecioBD(ONs_NY[[#This Row],[Ticker]],24,"QUANTITY BID","N")} -> 4000 | L16: {=_xll.PrecioBD(ONs_NY[[#This Row],[Ticker]],24,"QUANTITY ASK","N")} -> 39000 | M16: {=_xll.PrecioBD(ONs_NY[[#This Row],[Ticker]],24,"VOLUME AMOUNT","N")} -> 462528 | N16: {=_xll.PrecioBD(ONs_NY[[#This Row],[Ticker]],24,"IMBALANCE","N")} -> 0.0023 | O16: NY | P16: Semestral | Q16: 1000 | R16: Bullet
B17: IRSA | C17: IRCPD | D17: =IRCPD!K4 -> 0.072899458 | E17: =F17*$H$1 -> 107.9 | F17: {=_xll.PrecioBD(ONs_NY[[#This Row],[Ticker]],24,"ASK","N")} -> 107.9 | G17: =IRCPD!K3 -> 5.8223554 | H17: 49399 | I17: {=_xll.PrecioBD(ONs_NY[[#This Row],[Ticker]],"24","BID","N")} -> 107.85 | J17: {=_xll.PrecioBD(ONs_NY[[#This Row],[Ticker]],"24","ASK","N")} -> 107.9 | K17: {=_xll.PrecioBD(ONs_NY[[#This Row],[Ticker]],24,"QUANTITY BID","N")} -> 277 | L17: {=_xll.PrecioBD(ONs_NY[[#This Row],[Ticker]],24,"QUANTITY ASK","N")} -> 15927 | M17: {=_xll.PrecioBD(ONs_NY[[#This Row],[Ticker]],24,"VOLUME AMOUNT","N")} -> 897177.97 | N17: {=_xll.PrecioBD(ONs_NY[[#This Row],[Ticker]],24,"IMBALANCE","N")} -> -0.0027 | O17: NY | P17: Semestral | Q17: 1 | R17: Sinkable
B18: Pluspetrol | C18: PLC5D | D18: =PLC5D!K4 -> 0.071448514 | E18: =F18*$H$1 -> 106.55 | F18: {=_xll.PrecioBD(ONs_NY[[#This Row],[Ticker]],24,"ASK","N")} -> 106.55 | G18: =PLC5D!K3 -> 4.2018316 | H18: 47987 | I18: {=_xll.PrecioBD(ONs_NY[[#This Row],[Ticker]],"24","BID","N")} -> 106.25 | J18: {=_xll.PrecioBD(ONs_NY[[#This Row],[Ticker]],"24","ASK","N")} -> 106.55 | K18: {=_xll.PrecioBD(ONs_NY[[#This Row],[Ticker]],24,"QUANTITY BID","N")} -> 11000 | L18: {=_xll.PrecioBD(ONs_NY[[#This Row],[Ticker]],24,"QUANTITY ASK","N")} -> 4000 | M18: {=_xll.PrecioBD(ONs_NY[[#This Row],[Ticker]],24,"VOLUME AMOUNT","N")} -> 451908.5 | N18: {=_xll.PrecioBD(ONs_NY[[#This Row],[Ticker]],24,"IMBALANCE","N")} -> 0.0037 | O18: NY | P18: Semestral | Q18: 1000 | R18: Bullet
B19: Pampa energia | C19: MGCOD | D19: =MGCOD!K4 -> 0.072397116 | E19: =F19*$H$1 -> 106.05 | F19: {=_xll.PrecioBD(ONs_NY[[#This Row],[Ticker]],24,"ASK","N")} -> 106.05 | G19: =MGCOD!K3 -> 6.3137661 | H19: 49294 | I19: {=_xll.PrecioBD(ONs_NY[[#This Row],[Ticker]],"24","BID","N")} -> 105.8 | J19: {=_xll.PrecioBD(ONs_NY[[#This Row],[Ticker]],"24","ASK","N")} -> 106.05 | K19: {=_xll.PrecioBD(ONs_NY[[#This Row],[Ticker]],24,"QUANTITY BID","N")} -> 12000 | L19: {=_xll.PrecioBD(ONs_NY[[#This Row],[Ticker]],24,"QUANTITY ASK","N")} -> 10000 | M19: {=_xll.PrecioBD(ONs_NY[[#This Row],[Ticker]],24,"VOLUME AMOUNT","N")} -> 258626.5 | N19: {=_xll.PrecioBD(ONs_NY[[#This Row],[Ticker]],24,"IMBALANCE","N")} -> 0.0004 | O19: NY | P19: Semestral | Q19: 10000 | R19: Bullet
B20: Vista Energy | C20: VSCVD | D20: =VSCVD!K4 -> 0.07252064 | E20: =F20*$H$1 -> 108.25 | F20: {=_xll.PrecioBD(ONs_NY[[#This Row],[Ticker]],24,"ASK","N")} -> 108.25 | G20: =VSCVD!K3 -> 4.8412903 | H20: 48740 | I20: {=_xll.PrecioBD(ONs_NY[[#This Row],[Ticker]],"24","BID","N")} -> 108.2 | J20: {=_xll.PrecioBD(ONs_NY[[#This Row],[Ticker]],"24","ASK","N")} -> 108.25 | K20: {=_xll.PrecioBD(ONs_NY[[#This Row],[Ticker]],24,"QUANTITY BID","N")} -> 6000 | L20: {=_xll.PrecioBD(ONs_NY[[#This Row],[Ticker]],24,"QUANTITY ASK","N")} -> 3000 | M20: {=_xll.PrecioBD(ONs_NY[[#This Row],[Ticker]],24,"VOLUME AMOUNT","N")} -> 646774 | N20: {=_xll.PrecioBD(ONs_NY[[#This Row],[Ticker]],24,"IMBALANCE","N")} -> -0.0009 | O20: NY | P20: Semestral | Q20: 1000 | R20: Sinkable
B21: YPF | C21: YMCXD | D21: =YMCXO!K4 -> 0.070930883 | E21: =F21*$H$1 -> 110.95 | F21: {=_xll.PrecioBD(ONs_NY[[#This Row],[Ticker]],24,"ASK","N")} -> 110.95 | G21: =YMCXO!K3 -> 3.9050166 | H21: 48102 | I21: {=_xll.PrecioBD(ONs_NY[[#This Row],[Ticker]],"24","BID","N")} -> 110.65 | J21: {=_xll.PrecioBD(ONs_NY[[#This Row],[Ticker]],"24","ASK","N")} -> 110.95 | K21: {=_xll.PrecioBD(ONs_NY[[#This Row],[Ticker]],24,"QUANTITY BID","N")} -> 12826 | L21: {=_xll.PrecioBD(ONs_NY[[#This Row],[Ticker]],24,"QUANTITY ASK","N")} -> 1000 | M21: {=_xll.PrecioBD(ONs_NY[[#This Row],[Ticker]],24,"VOLUME AMOUNT","N")} -> 678005.9 | N21: {=_xll.PrecioBD(ONs_NY[[#This Row],[Ticker]],24,"IMBALANCE","N")} -> 0.0031 | O21: NY | P21: Semestral | Q21: 1 | R21: Sinkable
B22: Genneia | C22: GN49D | D22: =GN49D!K4 -> 0.071020624 | E22: =F22*$H$1 -> 105.55 | F22: {=_xll.PrecioBD(ONs_NY[[#This Row],[Ticker]],24,"ASK","N")} -> 105.55 | G22: =GN49D!K3 -> 5.1975468 | H22: 48915 | I22: {=_xll.PrecioBD(ONs_NY[[#This Row],[Ticker]],"24","BID","N")} -> 104.75 | J22: {=_xll.PrecioBD(ONs_NY[[#This Row],[Ticker]],"24","ASK","N")} -> 105.55 | K22: {=_xll.PrecioBD(ONs_NY[[#This Row],[Ticker]],24,"QUANTITY BID","N")} -> 5000 | L22: {=_xll.PrecioBD(ONs_NY[[#This Row],[Ticker]],24,"QUANTITY ASK","N")} -> 1000 | M22: {=_xll.PrecioBD(ONs_NY[[#This Row],[Ticker]],24,"VOLUME AMOUNT","N")} -> 12566 | N22: {=_xll.PrecioBD(ONs_NY[[#This Row],[Ticker]],24,"IMBALANCE","N")} -> 0.0014 | O22: NY | P22: Semestral | Q22: 1000 | R22: Sinkable
B23: Vista Energy | C23: VSCTD | D23: =VSCTD!K4 -> 0.071004906 | E23: =F23*$H$1 -> 105.35 | F23: {=_xll.PrecioBD(ONs_NY[[#This Row],[Ticker]],24,"ASK","N")} -> 105.35 | G23: =VSCTD!K3 -> 6.3443598 | H23: 49653 | I23: {=_xll.PrecioBD(ONs_NY[[#This Row],[Ticker]],"24","BID","N")} -> 105 | J23: {=_xll.PrecioBD(ONs_NY[[#This Row],[Ticker]],"24","ASK","N")} -> 105.35 | K23: {=_xll.PrecioBD(ONs_NY[[#This Row],[Ticker]],24,"QUANTITY BID","N")} -> 10000 | L23: {=_xll.PrecioBD(ONs_NY[[#This Row],[Ticker]],24,"QUANTITY ASK","N")} -> 10000 | M23: {=_xll.PrecioBD(ONs_NY[[#This Row],[Ticker]],24,"VOLUME AMOUNT","N")} -> 31545 | N23: {=_xll.PrecioBD(ONs_NY[[#This Row],[Ticker]],24,"IMBALANCE","N")} -> -0.0056 | O23: NY | P23: Semestral | Q23: 10000 | R23: Bullet
B24: Telecom | C24: TLCMD | D24: =TLCMO!K4 -> 0.07096636 | E24: =F24*$H$1 -> 110 | F24: {=_xll.PrecioBD(ONs_NY[[#This Row],[Ticker]],24,"ASK","N")} -> 110 | G24: =TLCMO!K3 -> 3.6176546 | H24: 48047 | I24: {=_xll.PrecioBD(ONs_NY[[#This Row],[Ticker]],"24","BID","N")} -> 109.65 | J24: {=_xll.PrecioBD(ONs_NY[[#This Row],[Ticker]],"24","ASK","N")} -> 110 | K24: {=_xll.PrecioBD(ONs_NY[[#This Row],[Ticker]],24,"QUANTITY BID","N")} -> 2000 | L24: {=_xll.PrecioBD(ONs_NY[[#This Row],[Ticker]],24,"QUANTITY ASK","N")} -> 3000 | M24: {=_xll.PrecioBD(ONs_NY[[#This Row],[Ticker]],24,"VOLUME AMOUNT","N")} -> 418537.5 | N24: {=_xll.PrecioBD(ONs_NY[[#This Row],[Ticker]],24,"IMBALANCE","N")} -> -0.0095 | O24: NY | P24: Semestral | Q24: 1000 | R24: Sinkable
B25: Tecpetrol | C25: TTCDD | D25: =TTCDD!K4 -> 0.067098203 | E25: =F25*$H$1 -> 106.05 | F25: {=_xll.PrecioBD(ONs_NY[[#This Row],[Ticker]],24,"ASK","N")} -> 106.05 | G25: =TTCDD!K3 -> 3.8809856 | H25: 47791 | I25: {=_xll.PrecioBD(ONs_NY[[#This Row],[Ticker]],"24","BID","N")} -> 105.5 | J25: {=_xll.PrecioBD(ONs_NY[[#This Row],[Ticker]],"24","ASK","N")} -> 106.05 | K25: {=_xll.PrecioBD(ONs_NY[[#This Row],[Ticker]],24,"QUANTITY BID","N")} -> 5000 | L25: {=_xll.PrecioBD(ONs_NY[[#This Row],[Ticker]],24,"QUANTITY ASK","N")} -> 8000 | M25: {=_xll.PrecioBD(ONs_NY[[#This Row],[Ticker]],24,"VOLUME AMOUNT","N")} -> 420302 | N25: {=_xll.PrecioBD(ONs_NY[[#This Row],[Ticker]],24,"IMBALANCE","N")} -> 0.0042 | O25: NY | P25: Semestral | Q25: 1000 | R25: Bullet
B26: YPF Luz | C26: YFCJD | D26: =YFCJD!K4 -> 0.070742473 | E26: =F26*$H$1 -> 106.7 | F26: {=_xll.PrecioBD(ONs_NY[[#This Row],[Ticker]],24,"ASK","N")} -> 106.7 | G26: =YFCJD!K3 -> 4.4526979 | H26: 48503 | I26: {=_xll.PrecioBD(ONs_NY[[#This Row],[Ticker]],"24","BID","N")} -> 106.35 | J26: {=_xll.PrecioBD(ONs_NY[[#This Row],[Ticker]],"24","ASK","N")} -> 106.7 | K26: {=_xll.PrecioBD(ONs_NY[[#This Row],[Ticker]],24,"QUANTITY BID","N")} -> 1000 | L26: {=_xll.PrecioBD(ONs_NY[[#This Row],[Ticker]],24,"QUANTITY ASK","N")} -> 30000 | M26: {=_xll.PrecioBD(ONs_NY[[#This Row],[Ticker]],24,"VOLUME AMOUNT","N")} -> 60720.5 | N26: {=_xll.PrecioBD(ONs_NY[[#This Row],[Ticker]],24,"IMBALANCE","N")} -> -0.0009 | O26: NY | P26: Semestral | Q26: 1000 | R26: Sinkable
B27: YPF | C27: YMCJD | D27: =YMCJO!K4 -> 0.06732305 | E27: =F27*$H$1 -> 104.4 | F27: {=_xll.PrecioBD(ONs_NY[[#This Row],[Ticker]],24,"ASK","N")} -> 104.4 | G27: =YMCJO!K3 -> 4.9493416 | H27: 48852 | I27: {=_xll.PrecioBD(ONs_NY[[#This Row],[Ticker]],"24","BID","N")} -> 103.8 | J27: {=_xll.PrecioBD(ONs_NY[[#This Row],[Ticker]],"24","ASK","N")} -> 104.4 | K27: {=_xll.PrecioBD(ONs_NY[[#This Row],[Ticker]],24,"QUANTITY BID","N")} -> 751 | L27: {=_xll.PrecioBD(ONs_NY[[#This Row],[Ticker]],24,"QUANTITY ASK","N")} -> 17187 | M27: {=_xll.PrecioBD(ONs_NY[[#This Row],[Ticker]],24,"VOLUME AMOUNT","N")} -> 287778.93 | N27: {=_xll.PrecioBD(ONs_NY[[#This Row],[Ticker]],24,"IMBALANCE","N")} -> -0.0019 | O27: NY | P27: Semestral | Q27: 1 | R27: Sinkable
B28: Tecpetrol | C28: TTCAD | D28: =TTCAD!K4 -> 0.065453872 | E28: =F28*$H$1 -> 106.05 | F28: {=_xll.PrecioBD(ONs_NY[[#This Row],[Ticker]],24,"ASK","N")} -> 106.05 | G28: =TTCAD!K3 -> 4.7617205 | H28: 48601 | I28: {=_xll.PrecioBD(ONs_NY[[#This Row],[Ticker]],"24","BID","N")} -> 105.5 | J28: {=_xll.PrecioBD(ONs_NY[[#This Row],[Ticker]],"24","ASK","N")} -> 106.05 | K28: {=_xll.PrecioBD(ONs_NY[[#This Row],[Ticker]],24,"QUANTITY BID","N")} -> 15000 | L28: {=_xll.PrecioBD(ONs_NY[[#This Row],[Ticker]],24,"QUANTITY ASK","N")} -> 100000 | M28: {=_xll.PrecioBD(ONs_NY[[#This Row],[Ticker]],24,"VOLUME AMOUNT","N")} -> 9576 | N28: {=_xll.PrecioBD(ONs_NY[[#This Row],[Ticker]],24,"IMBALANCE","N")} -> 0.0033 | O28: NY | P28: Semestral | Q28: 1000 | R28: Sinkable
B29: TGS | C29: TSC3D | D29: =TSC3D!K4 -> 0.066055217 | E29: =F29*$H$1 -> 109.4 | F29: {=_xll.PrecioBD(ONs_NY[[#This Row],[Ticker]],24,"ASK","N")} -> 109.4 | G29: =TSC3D!K3 -> 4.3735015 | H29: 48053 | I29: {=_xll.PrecioBD(ONs_NY[[#This Row],[Ticker]],"24","BID","N")} -> 108 | J29: {=_xll.PrecioBD(ONs_NY[[#This Row],[Ticker]],"24","ASK","N")} -> 109.4 | K29: {=_xll.PrecioBD(ONs_NY[[#This Row],[Ticker]],24,"QUANTITY BID","N")} -> 10000 | L29: {=_xll.PrecioBD(ONs_NY[[#This Row],[Ticker]],24,"QUANTITY ASK","N")} -> 12000 | M29: {=_xll.PrecioBD(ONs_NY[[#This Row],[Ticker]],24,"VOLUME AMOUNT","N")} -> 229980 | N29: {=_xll.PrecioBD(ONs_NY[[#This Row],[Ticker]],24,"IMBALANCE","N")} -> -0.0004 | O29: NY | P29: Semestral | Q29: 10000 | R29: Bullet
B30: Pampa energia | C30: MGCMD | D30: =MGCMD!K4 -> 0.064987287 | E30: =F30*$H$1 -> 110.5 | F30: {=_xll.PrecioBD(ONs_NY[[#This Row],[Ticker]],24,"ASK","N")} -> 110.5 | G30: =MGCMD!K3 -> 4.3828069 | H30: 48101 | I30: {=_xll.PrecioBD(ONs_NY[[#This Row],[Ticker]],"24","BID","N")} -> 109.5 | J30: {=_xll.PrecioBD(ONs_NY[[#This Row],[Ticker]],"24","ASK","N")} -> 110.5 | K30: {=_xll.PrecioBD(ONs_NY[[#This Row],[Ticker]],24,"QUANTITY BID","N")} -> 50000 | L30: {=_xll.PrecioBD(ONs_NY[[#This Row],[Ticker]],24,"QUANTITY ASK","N")} -> 15000 | M30: {=_xll.PrecioBD(ONs_NY[[#This Row],[Ticker]],24,"VOLUME AMOUNT","N")} -> 298755.5 | N30: {=_xll.PrecioBD(ONs_NY[[#This Row],[Ticker]],24,"IMBALANCE","N")} -> 0.0027 | O30: NY | P30: Semestral | Q30: 10000 | R30: Bullet
B31: Pan American Energy | C31: PNXCD | D31: =PNXCD!K4 -> 0.064733049 | E31: =F31*$H$1 -> 111.6 | F31: {=_xll.PrecioBD(ONs_NY[[#This Row],[Ticker]],24,"ASK","N")} -> 111.6 | G31: =PNXCD!K3 -> 4.14447 | H31: 48334 | I31: {=_xll.PrecioBD(ONs_NY[[#This Row],[Ticker]],"24","BID","N")} -> 111.5 | J31: {=_xll.PrecioBD(ONs_NY[[#This Row],[Ticker]],"24","ASK","N")} -> 111.6 | K31: {=_xll.PrecioBD(ONs_NY[[#This Row],[Ticker]],24,"QUANTITY BID","N")} -> 8000 | L31: {=_xll.PrecioBD(ONs_NY[[#This Row],[Ticker]],24,"QUANTITY ASK","N")} -> 2000 | M31: {=_xll.PrecioBD(ONs_NY[[#This Row],[Ticker]],24,"VOLUME AMOUNT","N")} -> 91545.5 | N31: {=_xll.PrecioBD(ONs_NY[[#This Row],[Ticker]],24,"IMBALANCE","N")} -> 0.0008 | O31: NY | P31: Semestral | Q31: 1000 | R31: Sinkable
B32: Arcor | C32: ARC1D | D32: =ARC1D!K4 -> 0.061897132 | E32: =F32*$H$1 -> 106 | F32: {=_xll.PrecioBD(ONs_NY[[#This Row],[Ticker]],24,"ASK","N")} -> 106 | G32: =ARC1D!K3 -> 2.9888579 | H32: 48061 | I32: {=_xll.PrecioBD(ONs_NY[[#This Row],[Ticker]],"24","BID","N")} -> 105.5 | J32: {=_xll.PrecioBD(ONs_NY[[#This Row],[Ticker]],"24","ASK","N")} -> 106 | K32: {=_xll.PrecioBD(ONs_NY[[#This Row],[Ticker]],24,"QUANTITY BID","N")} -> 8000 | L32: {=_xll.PrecioBD(ONs_NY[[#This Row],[Ticker]],24,"QUANTITY ASK","N")} -> 1000 | M32: {=_xll.PrecioBD(ONs_NY[[#This Row],[Ticker]],24,"VOLUME AMOUNT","N")} -> 50772 | N32: {=_xll.PrecioBD(ONs_NY[[#This Row],[Ticker]],24,"IMBALANCE","N")} -> 0.0061 | O32: NY | P32: Trimestral | Q32: 1000 | R32: Sinkable
B33: Banco Macro | C33: BACGD | D33: =BACGD!K4 -> 0.06251196 | E33: =F33*$H$1 -> 106.5 | F33: {=_xll.PrecioBD(ONs_NY[[#This Row],[Ticker]],24,"ASK","N")} -> 106.5 | G33: =BACGD!K3 -> 2.9228418 | H33: 47292 | I33: {=_xll.PrecioBD(ONs_NY[[#This Row],[Ticker]],"24","BID","N")} -> 106.1 | J33: {=_xll.PrecioBD(ONs_NY[[#This Row],[Ticker]],"24","ASK","N")} -> 106.5 | K33: {=_xll.PrecioBD(ONs_NY[[#This Row],[Ticker]],24,"QUANTITY BID","N")} -> 3000 | L33: {=_xll.PrecioBD(ONs_NY[[#This Row],[Ticker]],24,"QUANTITY ASK","N")} -> 1000 | M33: {=_xll.PrecioBD(ONs_NY[[#This Row],[Ticker]],24,"VOLUME AMOUNT","N")} -> 135035 | N33: {=_xll.PrecioBD(ONs_NY[[#This Row],[Ticker]],24,"IMBALANCE","N")} -> -0.0028 | O33: NY | P33: Semestral | Q33: 1000 | R33: Bullet
B34: Galicia | C34: BYCHD | D34: =BYCHD!K4 -> 0.054009077 | E34: =F34*$H$1 -> 108.5 | F34: {=_xll.PrecioBD(ONs_NY[[#This Row],[Ticker]],24,"ASK","N")} -> 108.5 | G34: =BYCHD!K3 -> 2.3546277 | H34: 47036 | I34: {=_xll.PrecioBD(ONs_NY[[#This Row],[Ticker]],"24","BID","N")} -> 107.9 | J34: {=_xll.PrecioBD(ONs_NY[[#This Row],[Ticker]],"24","ASK","N")} -> 108.5 | K34: {=_xll.PrecioBD(ONs_NY[[#This Row],[Ticker]],24,"QUANTITY BID","N")} -> 10000 | L34: {=_xll.PrecioBD(ONs_NY[[#This Row],[Ticker]],24,"QUANTITY ASK","N")} -> 900 | M34: {=_xll.PrecioBD(ONs_NY[[#This Row],[Ticker]],24,"VOLUME AMOUNT","N")} -> 32981.08 | N34: {=_xll.PrecioBD(ONs_NY[[#This Row],[Ticker]],24,"IMBALANCE","N")} -> -0.0046 | O34: NY | P34: Semestral | Q34: 2000 | R34: Bullet
B35: YPF | C35: YMCID | D35: =YMCID!K4 -> 0.054492775 | E35: =F35*$H$1 -> 107.3 | F35: {=_xll.PrecioBD(ONs_NY[[#This Row],[Ticker]],24,"ASK","N")} -> 107.3 | G35: =YMCID!K3 -> 1.7203707 | H35: 47299 | I35: {=_xll.PrecioBD(ONs_NY[[#This Row],[Ticker]],"24","BID","N")} -> 107.05 | J35: {=_xll.PrecioBD(ONs_NY[[#This Row],[Ticker]],"24","ASK","N")} -> 107.3 | K35: {=_xll.PrecioBD(ONs_NY[[#This Row],[Ticker]],24,"QUANTITY BID","N")} -> 795 | L35: {=_xll.PrecioBD(ONs_NY[[#This Row],[Ticker]],24,"QUANTITY ASK","N")} -> 455 | M35: {=_xll.PrecioBD(ONs_NY[[#This Row],[Ticker]],24,"VOLUME AMOUNT","N")} -> 192851.62 | N35: {=_xll.PrecioBD(ONs_NY[[#This Row],[Ticker]],24,"IMBALANCE","N")} -> 0.0023 | O35: NY | P35: Semestral | Q35: 1 | R35: Sinkable
B36: Capex | C36: CAC5D | D36: =CAC5D!K4 -> 0.055308428 | E36: =F36*$H$1 -> 81.6 | F36: {=_xll.PrecioBD(ONs_NY[[#This Row],[Ticker]],24,"ASK","N")} -> 81.6 | G36: =CAC5D!K3 -> 1.1688311 | H36: 46990 | I36: {=_xll.PrecioBD(ONs_NY[[#This Row],[Ticker]],"24","BID","N")} -> 81.01 | J36: {=_xll.PrecioBD(ONs_NY[[#This Row],[Ticker]],"24","ASK","N")} -> 81.6 | K36: {=_xll.PrecioBD(ONs_NY[[#This Row],[Ticker]],24,"QUANTITY BID","N")} -> 857 | L36: {=_xll.PrecioBD(ONs_NY[[#This Row],[Ticker]],24,"QUANTITY ASK","N")} -> 2606 | M36: {=_xll.PrecioBD(ONs_NY[[#This Row],[Ticker]],24,"VOLUME AMOUNT","N")} -> 14501.94 | N36: {=_xll.PrecioBD(ONs_NY[[#This Row],[Ticker]],24,"IMBALANCE","N")} -> -0.007 | O36: NY | P36: Semestral | Q36: 1 | R36: Sinkable
B37: Irsa | C37: IRCFD | D37: =IRCFO!K4 -> 0.052728108 | E37: =F37*$H$1 -> 69.11 | F37: {=_xll.PrecioBD(ONs_NY[[#This Row],[Ticker]],24,"ASK","N")} -> 69.11 | G37: =IRCFO!K3 -> 1.4402295 | H37: 46926 | I37: {=_xll.PrecioBD(ONs_NY[[#This Row],[Ticker]],"24","BID","N")} -> 68.92 | J37: {=_xll.PrecioBD(ONs_NY[[#This Row],[Ticker]],"24","ASK","N")} -> 69.11 | K37: {=_xll.PrecioBD(ONs_NY[[#This Row],[Ticker]],24,"QUANTITY BID","N")} -> 3084 | L37: {=_xll.PrecioBD(ONs_NY[[#This Row],[Ticker]],24,"QUANTITY ASK","N")} -> 198 | M37: {=_xll.PrecioBD(ONs_NY[[#This Row],[Ticker]],24,"VOLUME AMOUNT","N")} -> 40033.42 | N37: {=_xll.PrecioBD(ONs_NY[[#This Row],[Ticker]],24,"IMBALANCE","N")} -> -0.0018 | O37: NY | P37: Semestral | Q37: 1 | R37: Sinkable
